Workbook

Sheet ĐIỀU KHOẢN
A1: BẢNG TỔNG HỢP THÔNG TIN
A2: GÓI THẦU: CUNG CẤP VTTB VÀ THI CÔNG LẮP ĐẶT HỆ THỐNG CƠ ĐIỆN
A3: DỰ ÁN: TÒA NHÀ HỖN HỢP HACOM MALL
A5: I | B5: ĐIỀU KIỆN THƯƠNG MẠI | C5: ĐỀ XUẤT CÁC ĐIỀU KHOẢN THƯƠNG MẠI CỦA NHÀ THẦU
A6: 1 | B6: Tiến độ thi công | C6: 540 ngày ~ 18 tháng
A7: 2 | B7: Hình thức Hợp đồng | C7: Đơn giá cố định, khối lượng nghiệm thu theo thực tế
A8: 3 | B8: Bảo lãnh thực hiện HĐ | C8: 2% GTHĐ
A9: 4 | B9: Tạm ứng | C9: 20% GTHĐ trước thuế
A10: 5 | B10: Bảo lãnh tạm ứng | C10: 540 ngày ~ 18 tháng
C11: Thư Bão Lãnh Tạm Ứng có giá trị hiệu lực cho đến khi Bên A thu hồi hết khoản tiền tạm ứng đạt 80% giá trị Hợp Đồng đã ký. Trước ngày Thư bảo lãnh hết hạn tối đa 10 ngày mà Bên A vẫn chưa thu hồi hết khoản tiền tạm ứng nêu trên thì Bên B có trách nhiệm gia hạn Thư Bão Lãnh Tạm Ứng.
A12: 6 | B12: Thanh toán vật tư | C12: Đến 70% Giá trị vật tư (Được nghiệm thu)
A13: 7 | B13: Thanh toán Khối lượng hoàn thành | C13: Đến 90% KLHT
A14: 8 | B14: Quyết toán | C14: Đến 100% KLHT
A15: 9 | B15: Thời gian bảo hành (≥ 24 tháng) | C15: 24 tháng
C16: Bằng chứng thư bảo lãnh vô điều kiện, không hủy ngang, thanh toán ngay lập tức của ngân hàng uy tín có giá trị bằng 5% giá trị quyết toán.

Sheet Tổng hợp
E1: Mẫu số 03.1
A3: BẢNG CHÀO GIÁ TỔNG HỢP
A5: Stt | B5: Mô tả công việc mời thầu | C5: Thành tiền | E5: Ghi chú
C6: Theo KLMT | D6: Nhà thầu chào
A7: A | B7: ĐẦU MỤC CÔNG VIỆC THEO KLMT | C7: =C8+C9+C10+C11+C15 -> 1.519293e+11 | D7: =D8+D9+D10+D11+D15 -> 1.519293e+11
A8: I | B8: HẠNG MỤC: ĐIỆN | C8: ='1. HT điện'!Q9 -> 7.6346265e+10 | D8: ='1. HT điện'!R9 -> 7.6346265e+10
A9: II | B9: HẠNG MỤC: ĐIỆN NHẸ | C9: ='2. HT điện nhẹ'!Q9 -> 2.4590214e+09 | D9: ='2. HT điện nhẹ'!R9 -> 2.4590214e+09
A10: III | B10: HẠNG MỤC: CẤP THOÁT NƯỚC | C10: ='3. HT CTN'!Q9 -> 2.8952308e+10 | D10: ='3. HT CTN'!R9 -> 2.8952308e+10
A11: IV | B11: HẠNG MỤC: HVAC | C11: =SUM(C12:C14) -> 4.3107063e+10 | D11: =SUM(D12:D14) -> 4.3107063e+10
A12: IV.1 | B12: HVAC - ĐH VRV | C12: ='4.1 ĐH VRV'!AF9 -> 7.3670039e+08 | D12: ='4.1 ĐH VRV'!AG9 -> 7.3670039e+08
A13: IV.2 | B13: HVAC - QUẠT | C13: ='4.2 Quạt'!AC9 -> 3.2077763e+09 | D13: ='4.2 Quạt'!AD9 -> 3.2077763e+09
A14: IV.3 | B14: HVAC - ĐHKK & TG | C14: ='4.3 DHKK & TG'!Q9 -> 3.9162587e+10 | D14: ='4.3 DHKK & TG'!R9 -> 3.9162587e+10
A15: V | B15: HẠNG MỤC: NGĂN CHÁY LAN | C15: ='5. Ngăn cháy lan'!Q9 -> 1.0646398e+09 | D15: ='5. Ngăn cháy lan'!R9 -> 1.0646398e+09
A16: B | B16: ĐẦU MỤC CÔNG VIỆC PHÁT SINH NGOÀI KLMT | C16: =C17+C18+C19+C20+C24 -> 0 | D16: =D17+D18+D19+D20+D24 -> 3.712733e+09
A17: I | B17: HẠNG MỤC: ĐIỆN | C17: ='1. HT điện'!Q2682 -> 0 | D17: ='1. HT điện'!R2682 -> 42725530
A18: II | B18: HẠNG MỤC: ĐIỆN NHẸ | C18: ='2. HT điện nhẹ'!Q50 -> 0 | D18: ='2. HT điện nhẹ'!R50 -> 0
A19: III | B19: HẠNG MỤC: CẤP THOÁT NƯỚC | C19: ='3. HT CTN'!Q814 -> 0 | D19: ='3. HT CTN'!R814 -> 55735678
A20: IV | B20: HẠNG MỤC: HVAC | C20: =SUM(C21:C23) -> 0 | D20: =SUM(D21:D23) -> 3.6142717e+09
A21: IV.1 | B21: HVAC - ĐH VRV | C21: ='4.1 ĐH VRV'!AF49 -> 0 | D21: ='4.1 ĐH VRV'!AG49 -> 0
A22: IV.2 | B22: HVAC - QUẠT | C22: ='4.2 Quạt'!AC145 -> 0 | D22: ='4.2 Quạt'!AD145 -> 0
A23: IV.3 | B23: HVAC - ĐHKK & TG | C23: ='4.3 DHKK & TG'!Q1110 -> 0 | D23: ='4.3 DHKK & TG'!R1110 -> 3.6142717e+09
A24: V | B24: HẠNG MỤC: NGĂN CHÁY LAN | C24: ='5. Ngăn cháy lan'!Q25 -> 0 | D24: ='5. Ngăn cháy lan'!R25 -> 0
A25: C | B25: TỔNG CỘNG GIÁ CHÀO TRƯỚC THUẾ: (C = A + B) | C25: =C7+C16 -> 1.519293e+11 | D25: =D7+D16 -> 1.5564203e+11
B26: THUẾ VAT | C26: =C25*8% -> 1.2154344e+10 | D26: =D25*8% -> 1.2451362e+10
A27: D | B27: TỔNG CỘNG GIÁ CHÀO SAU THUẾ | C27: =C25+C26 -> 1.6408364e+11 | D27: =D25+D26 -> 1.6809339e+11
A29: ( Số tiền bằng chữ: Một trăm sáu mươi tám tỷ, không trăm chín mươi ba triệu, ba trăm chín mươi ba nghìn, không trăm linh tám đồng./.)
C31: Hà Nội, ngày 08 tháng 12 năm 2025
C32: CÔNG TY TNHH XÂY LẮP VÀ THƯƠNG MẠI LINH ANH

Sheet 1. HT điện
A1: Dự án: TOÀ NHÀ HỖN HỢP HACOM MALL
A2: Gói thầu: CUNG CẤP VTTB VÀ THI CÔNG LẮP ĐẶT HỆ THỐNG CƠ ĐIỆN
A3: Hạng mục: HỆ THỐNG ĐIỆN
A5: KHỐI LƯỢNG MỜI THẦU | F5: CÔNG TY TNHH XÂY LẮP VÀ THƯƠNG MẠI LINH ANH
A6: STT | B6: Diễn giải | C6: Đơn vị | D6: KL Mời thầu Lần 2 | E6: Ghi chú | F6: KL Nhà thầu chào | G6: THÔNG TIN VỀ VẬT LIỆU CHÍNH | K6: ĐƠN GIÁ (chưa bao gồm VAT) | Q6: Thành tiền BOQ | S6: Ghi chú
G7: Mô tả/ Quy cách | H7: Mã hiệu | I7: Thương hiệu | J7: Xuất xứ | K7: VL chính | L7: VL phụ | M7: NC&M | N7: CF quản lý | O7: Lợi nhuận | P7: ĐG tổng hợp | Q7: Thành tiền KLMT | R7: Thành tiền Nhà thầu chào
A8: 1 | B8: 2 | C8: 3 | D8: 4 | E8: 5 | F8: 6 | G8: 7 | H8: 8 | I8: 9 | J8: 10 | K8: 11 | L8: 12 | M8: 13 | N8: 14 | O8: 15 | P8: 16=11+12+13+14+15 | Q8: 17=4*16 | R8: 18=6*16 | S8: 19
A9: A | B9: ĐẦU MỤC CÔNG VIỆC THEO KLMT | Q9: =SUBTOTAL(9,Q10:Q2681) -> 7.6346265e+10 | R9: =SUBTOTAL(9,R10:R2681) -> 7.6346265e+10
A10: I | B10: Tủ điện hạ thế
A11: =COUNT($A$10:$A10)+1 -> 1 | B11: Tủ điện LV-G.1+LV-G.2+LV-G.3+LV-G.4+LV-G.5+LV-G.6 | C11: Tủ | D11: 1 | F11: 1 | G11: Thiết bị đóng cắt: Schneider Nhà sản xuất vỏ tủ điện: ACIT Chi tiết cấu tạo theo danh mục tủ điện đính kèm | I11: ACIT | J11: Việt Nam | K11: 1.5206604e+09 | L11: 0 | M11: 21696000 | N11: 155522064 | O11: 1.0886544e+08 | P11: =SUM(K11:O11) -> 1.8067439e+09 | Q11: =D11*P11 -> 1.8067439e+09 | R11: =F11*P11 -> 1.8067439e+09
B12: Vỏ tủ form 3B | C12: Cái | D12: 1 | F12: 1
B13: Đầu vào:
B14: ACB Fixed 4P 3200AT 3200AF 65kA , bảo vệ quá dòng, chạm đất, quá áp, thấp áp, đo lường class 1, kết nối NFC/ Bluetooth. | C14: Cái | D14: 2 | F14: 2
B15: Motor sạc 220VAC cho ACB Fixed 4P 3200A 65kA | C15: Cái | D15: 2 | F15: 2
B16: Cuộn đóng 220VAC cho ACB Fixed 4P 3200A 65kA | C16: Cái | D16: 2 | F16: 2
B17: Cuộn cắt 220VAC cho ACB Fixed dòng MTZ | C17: Cái | D17: 2 | F17: 2
B18: Cuộn UVT 220VAC cho ACB Fixed dòng MTZ | C18: Cái | D18: 2 | F18: 2
B19: Khóa đóng cắt ACB | C19: Cái | D19: 2 | F19: 2
B20: Bộ hòa đồng bộ 2 máy phát | C20: Bộ | D20: 1 | F20: 1
B21: Đèn báo trạng thái On/OFF/TRIP ACB | C21: Cái | D21: 6 | F21: 6
B22: Biến dòng hạ thế 3200/5A | C22: Quả | D22: 12 | F22: 12
B23: Đồng hồ Volt 0-450VAC | C23: Cái | D23: 2 | F23: 2
B24: Chuyển mạch Volt 7 vị trí | C24: Cái | D24: 2 | F24: 2
B25: Đồng hồ Ampe 0-3200A | C25: Cái | D25: 6 | F25: 6
... B27: Cầu chi 2A | C27: Cái | D27: 18 | F27: 18
B28: Đầu ra:
B29: ACB Fixed 4P 3000AT 3200AF 65kA | C29: Cái | D29: 1 | F29: 1
B30: ="Motor sạc 220VAC cho " &B29 -> Motor sạc 220VAC cho ACB Fixed 4P 3000AT 3200AF 65kA | C30: Cái | D30: 1 | F30: 1
B31: ="Cuộn đóng 220VAC cho " &B29 -> Cuộn đóng 220VAC cho ACB Fixed 4P 3000AT 3200AF 65kA | C31: Cái | D31: 1 | F31: 1
B32: Cuộn cắt 220VAC cho ACB Fixed dòng MTZ | C32: Cái | D32: 1 | F32: 1
B33: ACB 4P 1600AT 1600AF 65kA Fixed | C33: Cái | D33: 1 | F33: 1
B34: ="Motor sạc 220VAC cho " &B33 -> Motor sạc 220VAC cho ACB 4P 1600AT 1600AF 65kA Fixed | C34: Cái | D34: 1 | F34: 1
B35: ="Cuộn đóng 220VAC cho " &B33 -> Cuộn đóng 220VAC cho ACB 4P 1600AT 1600AF 65kA Fixed | C35: Cái | D35: 1 | F35: 1
B36: ="Cuộn cắt 220VAC cho " &B33 -> Cuộn cắt 220VAC cho ACB 4P 1600AT 1600AF 65kA Fixed | C36: Cái | D36: 2 | F36: 2
B37: Đèn báo trạng thái On/OFF/TRIP ACB | C37: Cái | D37: 6 | F37: 6
B38: Khóa đóng cắt ACB | C38: Cái | D38: 2 | F38: 2
B39: MCCB 4P 1250AT 1250AF 50kA | C39: Cái | D39: 1 | F39: 1
B40: ="Tiếp điểm báo trạng thái cho " &B39 -> Tiếp điểm báo trạng thái cho MCCB 4P 1250AT 1250AF 50kA | C40: Cái | D40: 2 | F40: 2
B41: MCCB 4P 1000AT 1000AF 50kA | C41: Cái | D41: 1 | F41: 1
B42: ="Tiếp điểm báo trạng thái cho " &B41 -> Tiếp điểm báo trạng thái cho MCCB 4P 1000AT 1000AF 50kA | C42: Cái | D42: 2 | F42: 2
...

Sheet 2. HT điện nhẹ
A1: Dự án: TOÀ NHÀ HỖN HỢP HACOM MALL
A2: Gói thầu: CUNG CẤP VTTB VÀ THI CÔNG LẮP ĐẶT HỆ THỐNG CƠ ĐIỆN
A3: Hạng mục: HỆ THỐNG ĐIỆN NHẸ
A5: KHỐI LƯỢNG MỜI THẦU | F5: CÔNG TY TNHH XÂY LẮP VÀ THƯƠNG MẠI LINH ANH
A6: Stt | B6: Diễn giải | C6: Đơn vị | D6: KL Mời thầu Lần 2 | E6: Ghi chú | F6: KL Nhà thầu chào | G6: THÔNG TIN VỀ VẬT LIỆU CHÍNH | K6: ĐƠN GIÁ (chưa bao gồm VAT) | Q6: Thành tiền BOQ | S6: Ghi chú
G7: Mô tả/ Quy cách | H7: Mã hiệu | I7: Thương hiệu | J7: Xuất xứ | K7: VL chính | L7: VL phụ | M7: NC&M | N7: CF quản lý | O7: Lợi nhuận | P7: ĐG tổng hợp | Q7: Thành tiền KLMT | R7: Thành tiền Nhà thầu chào
A8: 1 | B8: 2 | C8: 3 | D8: 4 | E8: 5 | F8: 6 | G8: 7 | H8: 8 | I8: 9 | J8: 10 | K8: 11 | L8: 12 | M8: 13 | N8: 14 | O8: 15 | P8: 16=11+12+13+14+15 | Q8: 17=4*16 | R8: 18=6*16 | S8: 19
A9: A | B9: ĐẦU MỤC CÔNG VIỆC THEO KLMT | Q9: =SUBTOTAL(9,Q10:Q49) -> 2.4590214e+09 | R9: =SUBTOTAL(9,R10:R49) -> 2.4590214e+09
A10: I | B10: Vật tư thiết bị đầu tư cho BQL tòa nhà
A11: 1 | B11: Ổ cắm mạng đơn 1xRJ45, bao gồm mặt và hạt | C11: Cái | D11: 10 | E11: NT chỉ cung cấp và lắp đặt đế âm | F11: 10 | G11: Đế âm KT: 77x77x51mm | H11: PAV5 | I11: Sam Phú | J11: Việt Nam | K11: 4730.18 | L11: 0 | M11: 24391.728 | N11: 2577.16 | O11: 1804.012 | P11: =SUM(K11:O11) -> 33503.08 | Q11: =D11*P11 -> 335030.8 | R11: =F11*P11 -> 335030.8 | S11: NT chỉ cung cấp và lắp đặt đế âm
A12: 2 | B12: Ống PVC D20 | C12: m | D12: 100 | F12: 100 | G12: Lực nén 750N | H12: MD20 | I12: Sam Phú | J12: Việt Nam | K12: 5976.6164 | L12: 0 | M12: 21887.874 | N12: 2465.8841 | O12: 1726.1189 | P12: =SUM(K12:O12) -> 32056.493 | Q12: =D12*P12 -> 3205649.3 | R12: =F12*P12 -> 3205649.3 | S12: Bao gồm cả ống nổi + âm
A13: II | B13: PHẦN VẬT TƯ THIẾT BỊ ĐẦU TƯ CHO CĂN HỘ | D13: 0 | F13: 0
A14: 1 | B14: Ổ cắm mạng đơn 1xRJ45, bao gồm cả mặt và hạt | C14: Cái | D14: 1109 | E14: NT chỉ cung cấp và lắp đặt đế âm | F14: 1109 | G14: Đế âm KT: 77x77x51mm | H14: PAV5 | I14: Sam Phú | J14: Việt Nam | K14: 4730.18 | L14: 0 | M14: 24391.728 | N14: 2577.16 | O14: 1804.012 | P14: =SUM(K14:O14) -> 33503.08 | Q14: =D14*P14 -> 37154916 | R14: =F14*P14 -> 37154916 | S14: NT chỉ cung cấp và lắp đặt đế âm
A15: 2 | B15: Ổ cắm truyền hình, bao gồm mặt cả hạt | C15: Cái | D15: 1109 | E15: NT chỉ cung cấp và lắp đặt đế âm | F15: 1109 | G15: Đế âm KT: 77x77x51mm | H15: PAV5 | I15: Sam Phú | J15: Việt Nam | K15: 4730.18 | L15: 0 | M15: 24391.728 | N15: 2577.16 | O15: 1804.012 | P15: =SUM(K15:O15) -> 33503.08 | Q15: =D15*P15 -> 37154916 | R15: =F15*P15 -> 37154916 | S15: NT chỉ cung cấp và lắp đặt đế âm
A16: 3 | B16: Ống PVC D20 | C16: m | D16: 15826 | F16: 15826 | G16: Lực nén 750N | H16: MD20 | I16: Sam Phú | J16: Việt Nam | K16: 5976.6164 | L16: 0 | M16: 21887.874 | N16: 2465.8841 | O16: 1726.1189 | P16: =SUM(K16:O16) -> 32056.493 | Q16: =D16*P16 -> 5.0732606e+08 | R16: =F16*P16 -> 5.0732606e+08 | S16: Bao gồm cả ống nổi + âm
A17: 4 | B17: Vật tư phụ hoàn thiện toàn bộ hệ thống | C17: Lô | D17: 1 | F17: 1 | I17: Sam Phú | J17: Việt Nam | K17: 39758103 | L17: 0 | M17: 36401045 | N17: 6454165.1 | O17: 4517915.6 | P17: =SUM(K17:O17) -> 87131229 | Q17: =D17*P17 -> 87131229 | R17: =F17*P17 -> 87131229
A18: III | B18: Thang máng cáp
A19: 1 | B19: Thang cáp kim loại WxH-500x100mm | C19: m | D19: 209.3 | F19: 209.3 | G19: Thang cáp 500x100mm, dày 2.0mm, mạ kẽm nhúng nóng không bao gồm nắp | I19: Eusduct | J19: Việt Nam | K19: 365109.19 | L19: 0 | M19: 66302.142 | N19: 38760.166 | O19: 27132.116 | P19: =SUM(K19:O19) -> 497303.62 | Q19: =D19*P19 -> 1.0408565e+08 | R19: =F19*P19 -> 1.0408565e+08
B20: Tê nối thang cáp WxH=(500x100)mm | C20: Cái | D20: 2 | F20: 2 | G20: Tê nối thang cáp 500x100mm, dày 2.0mm, mạ kẽm nhúng nóng không bao gồm nắp | I20: Eusduct | J20: Việt Nam | K20: 598768.63 | L20: 0 | M20: 92349.411 | N20: 62115.634 | O20: 43480.944 | P20: =SUM(K20:O20) -> 796714.62 | Q20: =D20*P20 -> 1593429.2 | R20: =F20*P20 -> 1593429.2
B21: Chuyển hướng ngang 90 độ thang cáp WxH=(500x100)mm | C21: Cái | D21: 8 | F21: 8 | G21: Chuyển hướng ngang 90 độ thang cáp 500x100mm, dày 2.0mm, mạ kẽm nhúng nóng không bao gồm nắp | I21: Eusduct | J21: Việt Nam | K21: 581276.81 | L21: 0 | M21: 61566.274 | N21: 57815.623 | O21: 40470.936 | P21: =SUM(K21:O21) -> 741129.64 | Q21: =D21*P21 -> 5929037.1 | R21: =F21*P21 -> 5929037.1
B22: Chuyển hướng dọc 90 độ thang cáp WxH=(500x100)mm | C22: Cái | D22: 4 | F22: 4 | G22: Chuyển hướng dọc 90 độ thang cáp 500x100mm, dày 2.0mm, mạ kẽm nhúng nóng không bao gồm nắp | I22: Eusduct | J22: Việt Nam | K22: 581276.81 | L22: 0 | M22: 61566.274 | N22: 57815.623 | O22: 40470.936 | P22: =SUM(K22:O22) -> 741129.64 | Q22: =D22*P22 -> 2964518.6 | R22: =F22*P22 -> 2964518.6
A23: 2 | B23: Thang cáp kim loại WxH-400x100mm | C23: m | D23: 48.8 | F23: 48.8 | G23: Thang cáp 400x100mm, dày 2.0mm, mạ kẽm nhúng nóng không bao gồm nắp | I23: Eusduct | J23: Việt Nam | K23: 346834.15 | L23: 0 | M23: 59240.25 | N23: 36488.82 | O23: 25542.174 | P23: =SUM(K23:O23) -> 468105.4 | Q23: =D23*P23 -> 22843543 | R23: =F23*P23 -> 22843543
B24: Tê nối máng cáp WxH=(400x100)mm | C24: Cái | D24: 0 | F24: 0
B25: Chuyển hướng ngang 90 độ máng cáp WxH=(400x100)mm | C25: Cái | D25: 0 | F25: 0
B26: Chữ thập nối thang cáp WxH=(400x100)mm | C26: Cái | D26: 1 | F26: 1 | G26: Chuyển hướng 4 ngả thang cáp 400x100mm, dày 2.0mm, mạ kẽm nhúng nóng không bao gồm nắp | I26: Eusduct | J26: Việt Nam | K26: 651113.57 | L26: 0 | M26: 123132.55 | N26: 69555.566 | O26: 48688.896 | P26: =SUM(K26:O26) -> 892490.58 | Q26: =D26*P26 -> 892490.58 | R26: =F26*P26 -> 892490.58
B27: Chuyển hướng ngang 90 độ thang cáp WxH=(400x100)mm | C27: Cái | D27: 5 | F27: 5 | G27: Chuyển hướng ngang 90 độ thang cáp 400x100mm, dày 2.0mm, mạ kẽm nhúng nóng không bao gồm nắp | I27: Eusduct | J27: Việt Nam | K27: 488204.64 | L27: 0 | M27: 55008.804 | N27: 48850.436 | O27: 34195.305 | P27: =SUM(K27:O27) -> 626259.18 | Q27: =D27*P27 -> 3131295.9 | R27: =F27*P27 -> 3131295.9
B28: Chuyển hướng dọc 90 độ thang cáp WxH=(400x100)mm | C28: Cái | D28: 1 | F28: 1 | G28: Chuyển hướng dọc 90 độ thang cáp 400x100mm, dày 2.0mm, mạ kẽm nhúng nóng không bao gồm nắp | I28: Eusduct | J28: Việt Nam | K28: 488204.64 | L28: 0 | M28: 55008.804 | N28: 48850.436 | O28: 34195.305 | P28: =SUM(K28:O28) -> 626259.18 | Q28: =D28*P28 -> 626259.18 | R28: =F28*P28 -> 626259.18
A29: 3 | B29: Máng cáp kim loại WxH-200x100mm | C29: m | D29: 0 | F29: 0
B30: Chuyển hướng ngang 90 độ máng cáp WxH=(200x100)mm | C30: Cái | D30: 0 | F30: 0
B31: Tê nối máng cáp WxH=(200x100)mm | C31: Cái | D31: 0 | F31: 0
A32: 4 | B32: Máng cáp kim loại WxH-200x50mm | C32: m | D32: 871.99 | F32: 871.99 | G32: Máng cáp 200x50mm, dày 1.5mm, mạ kẽm nhúng nóng bao gồm nắp | I32: Eusduct | J32: Việt Nam | K32: 378162.79 | L32: 0 | M32: 62346.012 | N32: 39586.066 | O32: 27710.246 | P32: =SUM(K32:O32) -> 507805.12 | Q32: =D32*P32 -> 4.4280098e+08 | R32: =F32*P32 -> 4.4280098e+08
B33: Chuyển hướng ngang 90 độ máng cáp WxH=(200x50)mm | C33: Cái | D33: 40 | F33: 40 | G33: Chuyển hướng ngang 90 độ máng cáp 200x50mm, dày 1.5mm, mạ kẽm nhúng nóng bao gồm nắp | I33: Eusduct | J33: Việt Nam | K33: 378162.79 | L33: 0 | M33: 57892.725 | N33: 39191.97 | O33: 27434.379 | P33: =SUM(K33:O33) -> 502681.87 | Q33: =D33*P33 -> 20107275 | R33: =F33*P33 -> 20107275
B34: Chuyển hướng dọc 90 độ máng cáp WxH=(200x50)mm | C34: Cái | D34: 5 | F34: 5 | G34: Chuyển hướng dọc 90 độ máng cáp 200x50mm, dày 1.5mm, mạ kẽm nhúng nóng bao gồm nắp | I34: Eusduct | J34: Việt Nam | K34: 378162.79 | L34: 0 | M34: 57892.725 | N34: 39191.97 | O34: 27434.379 | P34: =SUM(K34:O34) -> 502681.87 | Q34: =D34*P34 -> 2513409.3 | R34: =F34*P34 -> 2513409.3
B35: Tê nối máng cáp WxH=(200x50)mm | C35: Cái | D35: 26 | F35: 26 | G35: Tê nối máng cáp 200x50mm, dày 1.5mm, mạ kẽm nhúng nóng bao gồm nắp | I35: Eusduct | J35: Việt Nam | K35: 449043.84 | L35: 0 | M35: 86839.088 | N35: 48139.275 | O35: 33697.493 | P35: =SUM(K35:O35) -> 617719.7 | Q35: =D35*P35 -> 16060712 | R35: =F35*P35 -> 16060712
A36: 5 | B36: Máng cáp kim loại WxH-150x50mm | C36: m | D36: 1724.49 | F36: 1724.49 | G36: Máng cáp 150x50mm, dày 1.5mm, mạ kẽm nhúng nóng bao gồm nắp | I36: Eusduct | J36: Việt Nam | K36: 307281.74 | L36: 0 | M36: 55645.763 | N36: 32607.444 | O36: 22825.211 | P36: =SUM(K36:O36) -> 418360.16 | Q36: =D36*P36 -> 7.2145792e+08 | R36: =F36*P36 -> 7.2145792e+08
B37: Tê nối máng cáp WxH=(150x50)mm | C37: Cái | D37: 20 | F37: 20 | G37: Tê nối máng cáp 150x50mm, dày 1.5mm, mạ kẽm nhúng nóng bao gồm nắp | I37: Eusduct | J37: Việt Nam | K37: 336913.42 | L37: 0 | M37: 77506.599 | N37: 37211.551 | O37: 26048.086 | P37: =SUM(K37:O37) -> 477679.65 | Q37: =D37*P37 -> 9553593 | R37: =F37*P37 -> 9553593
B38: Chuyển hướng ngang 90 độ máng cáp WxH=(150x50)mm | C38: Cái | D38: 89 | F38: 89 | G38: Chuyển hướng ngang 90 độ máng cáp 150x50mm, dày 1.5mm, mạ kẽm nhúng nóng bao gồm nắp | I38: Eusduct | J38: Việt Nam | K38: 277780.61 | L38: 0 | M38: 51671.066 | N38: 29597.941 | O38: 20718.559 | P38: =SUM(K38:O38) -> 379768.17 | Q38: =D38*P38 -> 33799367 | R38: =F38*P38 -> 33799367
B39: Chuyển hướng dọc 90 độ máng cáp WxH=(150x50)mm | C39: Cái | D39: 19 | F39: 19 | G39: Chuyển hướng dọc 90 độ máng cáp 150x50mm, dày 1.5mm, mạ kẽm nhúng nóng bao gồm nắp | I39: Eusduct | J39: Việt Nam | K39: 277780.61 | L39: 0 | M39: 51671.066 | N39: 29597.941 | O39: 20718.559 | P39: =SUM(K39:O39) -> 379768.17 | Q39: =D39*P39 -> 7215595.3 | R39: =F39*P39 -> 7215595.3
B40: Thang cáp WxH=(400x50)mm | C40: m | D40: 66 | F40: 66 | G40: Thang cáp 400x50mm, dày 2.0mm, mạ kẽm nhúng nóng không bao gồm nắp | I40: Eusduct | J40: Việt Nam | K40: 245407.68 | L40: 0 | M40: 59240.25 | N40: 27351.3 | O40: 19145.91 | P40: =SUM(K40:O40) -> 351145.14 | Q40: =D40*P40 -> 23175579 | R40: =F40*P40 -> 23175579
B41: Chuyển hướng ngang 90 độ thang cáp WxH=(400x50)mm | C41: Cái | D41: 4 | F41: 4 | G41: Chuyển hướng ngang 90 độ thang cáp 400x50mm, dày 2.0mm, mạ kẽm nhúng nóng không bao gồm nắp | I41: Eusduct | J41: Việt Nam | K41: 418628.95 | L41: 0 | M41: 55008.804 | N41: 42582.356 | O41: 29807.649 | P41: =SUM(K41:O41) -> 546027.76 | Q41: =D41*P41 -> 2184111 | R41: =F41*P41 -> 2184111
...

Sheet 3. HT CTN
A1: Dự án: TOÀ NHÀ HỖN HỢP HACOM MALL
A2: Gói thầu: CUNG CẤP VTTB VÀ THI CÔNG LẮP ĐẶT HỆ THỐNG CƠ ĐIỆN
A3: Hạng mục: HỆ THỐNG CẤP THOÁT NƯỚC
A5: KHỐI LƯỢNG MỜI THẦU | F5: CÔNG TY TNHH XÂY LẮP VÀ THƯƠNG MẠI LINH ANH
A6: STT | B6: Diễn giải | C6: Đơn vị | D6: KL Mời thầu Lần 2 | E6: Ghi chú | F6: KL Nhà thầu chào | G6: THÔNG TIN VỀ VẬT LIỆU CHÍNH | K6: ĐƠN GIÁ (chưa bao gồm VAT) | Q6: Thành tiền BOQ | S6: Ghi chú
G7: Mô tả/ Quy cách | H7: Mã hiệu | I7: Thương hiệu | J7: Xuất xứ | K7: VL chính | L7: VL phụ | M7: NC&M | N7: CF quản lý | O7: Lợi nhuận | P7: ĐG tổng hợp | Q7: Thành tiền KLMT | R7: Thành tiền Nhà thầu chào
A8: 1 | B8: 2 | C8: 3 | D8: 4 | F8: 6 | G8: 7 | H8: 8 | I8: 9 | J8: 10 | K8: 11 | L8: 12 | M8: 13 | N8: 14 | O8: 15 | P8: 16=11+12+13+14+15 | Q8: 17=4*16 | R8: 18=6*16 | S8: 19
A9: A | B9: ĐẦU MỤC CÔNG VIỆC THEO KLMT | Q9: =SUBTOTAL(9,Q10:Q813) -> 2.8952308e+10 | R9: =SUBTOTAL(9,R10:R813) -> 2.8952308e+10
A10: I | B10: Phần thiết bị + phụ kiện chính
A11: 1 | B11: Bơm thoát nước sàn hầm ( thông số 1 bơm Q=12m3/h. H=15m, N=2,5KW), ( bao gồm phụ kiện : khớp nối nhanh, xích kéo, thanh dẫn hướng…) | C11: Cụm | D11: 3 | E11: Bơm thả chìm, nguyên cụm (bao gồm 02 bơm) | F11: 3 | G11: Bơm chìm nước thải Q=12m3/h, H=15m, 1.5kW, 380V/3P/50Hz, 2Pole, Thân và cánh gang, trục thép không gỉ Bao gồm khớp nối nhanh chính hãng, xích kéo và thanh dẫn hướng Việt Nam, van phao điện Mac3 Italia… | H11: FAG 50C 20.30/15 | I11: Wilo | J11: China | K11: 48249320 | L11: 3604500 | M11: 2825000 | N11: 4934400 | O11: 3454080 | P11: =SUM(K11:O11) -> 63067300 | Q11: =D11*P11 -> 189201900 | R11: =F11*P11 -> 189201900
A12: 2 | B12: Bơm hố pít thang máy ( thông số 1 bơm Q=10m3/h. H=15m, N=1,5KW), ( bao gồm phụ kiện : khớp nối nhanh, xích kéo, thanh dẫn hướng…) | C12: Cụm | D12: 2 | E12: Bơm thả chìm, nguyên cụm (bao gồm 02 bơm) | F12: 2 | G12: Bơm chìm nước thải Q=10m3/h, H=15m, 1.5kW, 380V/3P/50Hz, 2Pole, Thân và cánh gang, trục thép không gỉ Bao gồm khớp nối nhanh chính hãng, xích kéo và thanh dẫn hướng Việt Nam, van phao điện Mac3 Italia… | H12: FAG 50C 20.30/15 | I12: Wilo | J12: China | K12: 48249320 | L12: 3604500 | M12: 2825000 | N12: 4934400 | O12: 3454080 | P12: =SUM(K12:O12) -> 63067300 | Q12: =D12*P12 -> 126134600 | R12: =F12*P12 -> 126134600
A13: 3 | B13: Bơm bể bơm trung chuyển ( thông số bơm Q=6m3/h. H=6m), ( bao gồm phụ kiện : khớp nối nhanh, xích kéo, thanh dẫn hướng…) | C13: Cụm | D13: 2 | E13: Bơm thả chìm, nguyên cụm (bao gồm 02 bơm) | F13: 2 | G13: Bơm chìm nước thải Q=6m3/h, H=6m, 0.45kW, 380V/3P/50Hz, 2Pole, Thân gang, cánh gang, trục thép không gỉ Bao gồm xích kéo và thanh dẫn hướng Việt Nam, van phao điện Mac3 Italia… | H13: FAG 50Z 11.14/4.5 | I13: Wilo | J13: China | K13: 31493280 | L13: 3604500 | M13: 2260000 | N13: 3257600 | O13: 2280320 | P13: =SUM(K13:O13) -> 42895700 | Q13: =D13*P13 -> 85791400 | R13: =F13*P13 -> 85791400
A14: 4 | B14: Bơm cấp nước lên mái khối A ( thông số 1 bơm Q=40m3/h. H=130m, N=22KW), ( bao gồm phụ kiện ) | C14: Cụm | D14: 1 | E14: Bơm trục đứng, đa tầng cánh, nguyên cụm (bao gồm 02 bơm) | F14: 1 | G14: Bơm cấp nước ly tâm, trục đứng, đa tầng cánh, Q=40m3/h, H=130m, 22kW, 380V/3P/50Hz, 2Pole, Thân gang, cánh và trục thép không gỉ | H14: Helix FIRST V 3608-5/25/E/KS/400-50 | I14: Wilo | J14: China | K14: 282632000 | L14: 0 | M14: 9887500 | N14: 28315000 | O14: 19820500 | P14: =SUM(K14:O14) -> 340655000 | Q14: =D14*P14 -> 340655000 | R14: =F14*P14 -> 340655000
A15: 5 | B15: Bơm cấp nước lên mái khối B ( thông số 1 bơm Q=40m3/h. H=120m, N=22KW), ( bao gồm phụ kiện ) | C15: Cụm | D15: 1 | E15: Bơm trục đứng, đa tầng cánh, nguyên cụm (bao gồm 02 bơm) | F15: 1 | G15: Bơm cấp nước ly tâm, trục đứng, đa tầng cánh, Q=40m3/h, H=120m, 22kW, 380V/3P/50Hz, 2Pole, Thân gang, cánh và trục thép không gỉ | H15: Helix FIRST V 3607-5/25/E/KS/400-50 | I15: Wilo | J15: China | K15: 264462800 | L15: 0 | M15: 9887500 | N15: 26551000 | O15: 18585700 | P15: =SUM(K15:O15) -> 319487000 | Q15: =D15*P15 -> 319487000 | R15: =F15*P15 -> 319487000
A16: 6 | B16: Bơm biến tần tăng áp khối đế (thông số 1 bơm Q=40m3/h. H=56m,N=11KW), ( bao gồm phụ kiện ) | C16: Cụm | D16: 1 | E16: Bơm trục đứng, đa tầng cánh, nguyên cụm (bao gồm 02 bơm) | F16: 1 | G16: Bơm tăng áp ly tâm, trục ngang, Q=2x40m3/h, H=56m, 11kW, 380V/3P/50Hz, 2Pole, Thân, cánh và trục thép không gỉ Tủ điện điều khiển bơm bằng biến tần, TBĐC: Schneider, phụ kiện cấu thành nguyên cụm được sản xuất và lắp ráp nguyên cụm tại Việt Nam | H16: SIBOOST-B-2-HELIX V3604/2-VRS-N | I16: Wilo | J16: China | K16: 328055000 | L16: 0 | M16: 6780000 | N16: 32450000 | O16: 22715000 | P16: =SUM(K16:O16) -> 390000000 | Q16: =D16*P16 -> 390000000 | R16: =F16*P16 -> 390000000
A17: 7 | B17: Bơm biến tần tăng áp mái khối A (thông số 1 bơm Q=27m3/h. H=25m,N=3.7KW), ( bao gồm phụ kiện ) | C17: Cụm | D17: 1 | E17: Bơm trục đứng, đa tầng cánh, nguyên cụm (bao gồm 02 bơm) | F17: 1 | G17: Bơm tăng áp ly tâm, trục ngang, Q=2x27m3/h, H=25m, 4kW, 380V/3P/50Hz, 2Pole, Thân, cánh và trục thép không gỉ Tủ điện điều khiển bơm bằng biến tần, TBĐC: Schneider, phụ kiện cấu thành nguyên cụm được sản xuất và lắp ráp nguyên cụm tại Việt Nam | H17: SIBOOST-B-2-HELIX V2203-VRS-N | I17: Wilo | J17: China | K17: 272538000 | L17: 0 | M17: 5650000 | N17: 26960000 | O17: 18872000 | P17: =SUM(K17:O17) -> 324020000 | Q17: =D17*P17 -> 324020000 | R17: =F17*P17 -> 324020000
A18: 8 | B18: Bơm biến tần tăng áp mái khối B (thông số 1 bơm Q=30m3/h. H=25m,N=3.7KW), ( bao gồm phụ kiện ) | C18: Cụm | D18: 1 | E18: Bơm trục đứng, đa tầng cánh, nguyên cụm (bao gồm 02 bơm) | F18: 1 | G18: Bơm tăng áp ly tâm, trục ngang, Q=2x30m3/h, H=25m, 4kW, 380V/3P/50Hz, 2Pole, Thân, cánh và trục thép không gỉ Tủ điện điều khiển bơm bằng biến tần, TBĐC: Schneider, phụ kiện cấu thành nguyên cụm được sản xuất và lắp ráp nguyên cụm tại Việt Nam | H18: SIBOOST-B-2-HELIX V2203-VRS-N | I18: Wilo | J18: China | K18: 272538000 | L18: 0 | M18: 5650000 | N18: 26960000 | O18: 18872000 | P18: =SUM(K18:O18) -> 324020000 | Q18: =D18*P18 -> 324020000 | R18: =F18*P18 -> 324020000
A19: 9 | B19: Bình tích áp 500L (bao gồm đồng hồ đo áp, công tắc áp lực liên động bơm tăng áp), ( bao gồm phụ kiện) | C19: Cụm | D19: 3 | F19: 3 | K19: 0 | L19: 0 | M19: 0 | N19: 0 | O19: 0 | P19: =SUM(K19:O19) -> 0 | Q19: =D19*P19 -> 0 | R19: =F19*P19 -> 0 | S19: Đã bao gồm trong cụm bơm tăng áp
A20: 10 | B20: Cụm đồng hồ nước DN100 (gồm 01 đồng hồ, 02 van bướm, 01 mối nối mềm) | C20: Cụm | D20: 1 | F20: 1 | G20: Đồng hồ đo nước thân gang, nối bích + Van bướm tay gạt, nối kẹp + Khớp nối mềm inox, nối bích | H20: OMF.100 + FSB.16 + FSSEF.16 | I20: Omega + Flowsure + Flowsure | J20: China | K20: 9741740 | L20: 0 | M20: 1016322 | N20: 1035740 | O20: 725018 | P20: =SUM(K20:O20) -> 12518820 | Q20: =D20*P20 -> 12518820 | R20: =F20*P20 -> 12518820 | S20: PN16
A21: 11 | B21: Cụm đồng hồ nước DN80 (gồm 01 đồng hồ, 02 van khóa, kèm phụ kiện) | C21: Cụm | D21: 1 | F21: 1 | G21: Đồng hồ đo nước thân gang, nối bích + Van cổng ty chìm, nối bích + Khớp nối mềm inox, nối bích | H21: OMF.80 + FSB.16 + FSSEF.16 | I21: Omega + Flowsure + Flowsure | J21: China | K21: 9367850 | L21: 0 | M21: 965472 | N21: 994940 | O21: 696458 | P21: =SUM(K21:O21) -> 12024720 | Q21: =D21*P21 -> 12024720 | R21: =F21*P21 -> 12024720 | S21: PN16
A22: 12 | B22: Cụm đồng hồ nước DN50 (gồm 01 đồng hồ, 02 van khóa, kèm phụ kiện) | C22: Cụm | D22: 2 | F22: 2 | G22: Đồng hồ đo nước thân đồng, nối ren + Van cổng đồng thau, nối ren | H22: OM.T01 + FSGT.16 | I22: Omega + Flowsure | J22: China | K22: 5085110 | L22: 0 | M22: 316219.2 | N22: 521684 | O22: 365178.8 | P22: =SUM(K22:O22) -> 6288192 | Q22: =D22*P22 -> 12576384 | R22: =F22*P22 -> 12576384 | S22: PN16
A23: 13 | B23: Cụm đồng hồ nước DN40 (gồm 01 đồng hồ, 02 van khóa, kèm phụ kiện) | C23: Cụm | D23: 5 | F23: 5 | G23: Đồng hồ đo nước thân đồng, nối ren + Van cổng đồng thau, nối ren | H23: OM.T01 + FSGT.16 | I23: Omega + Flowsure | J23: China | K23: 2787180 | L23: 0 | M23: 256012.8 | N23: 293256 | O23: 205279.2 | P23: =SUM(K23:O23) -> 3541728 | Q23: =D23*P23 -> 17708640 | R23: =F23*P23 -> 17708640 | S23: PN16
A24: 14 | B24: Cụm đồng hồ nước DN32 (gồm 01 đồng hồ, 02 van khóa, kèm phụ kiện) | C24: Cụm | D24: 2 | F24: 2 | G24: Đồng hồ đo nước thân đồng, nối ren + Van cổng đồng thau, nối ren | H24: OM.T01 + FSGT.16 | I24: Omega + Flowsure | J24: China | K24: 1776750 | L24: 0 | M24: 210993.6 | N24: 191172 | O24: 133820.4 | P24: =SUM(K24:O24) -> 2312736 | Q24: =D24*P24 -> 4625472 | R24: =F24*P24 -> 4625472 | S24: PN16
A25: 15 | B25: Cụm đồng hồ nước DN25 (gồm 01 đồng hồ, 02 van khóa, kèm phụ kiện) | C25: Cụm | D25: 6 | F25: 6 | G25: Đồng hồ đo nước thân đồng, nối ren + Van cổng đồng thau, nối ren | H25: OM.T01 + FSGT.16 | I25: Omega + Flowsure | J25: China | K25: 1562510 | L25: 0 | M25: 150787.2 | N25: 165044 | O25: 115530.8 | P25: =SUM(K25:O25) -> 1993872 | Q25: =D25*P25 -> 11963232 | R25: =F25*P25 -> 11963232 | S25: PN16
A26: 16 | B26: Cụm đồng hồ nước DN20 (gồm 01 đồng hồ, 02 van khóa, kèm phụ kiện) | C26: Cụm | D26: 432 | F26: 432 | G26: Đồng hồ đo nước thân đồng, nối ren + Van cổng đồng thau, nối ren | H26: OM.T01 + FSGT.16 | I26: Omega + Flowsure | J26: China | K26: 1294710 | L26: 0 | M26: 135600 | N26: 137700 | O26: 96390 | P26: =SUM(K26:O26) -> 1664400 | Q26: =D26*P26 -> 719020800 | R26: =F26*P26 -> 719020800 | S26: PN16
A27: 17 | B27: Cụm đồng hồ nước DN15 (gồm 01 đồng hồ, 02 van khóa, kèm phụ kiện) | C27: Cụm | D27: 84 | F27: 84 | G27: Đồng hồ đo nước thân đồng, nối ren + Van cổng đồng thau, nối ren | H27: OM.T01 + FSGT.16 | I27: Omega + Flowsure | J27: China | K27: 1063990 | L27: 0 | M27: 120412.8 | N27: 113956 | O27: 79769.2 | P27: =SUM(K27:O27) -> 1378128 | Q27: =D27*P27 -> 115762752 | R27: =F27*P27 -> 115762752 | S27: PN16
A28: 18 | B28: Cảm biến mực nước | C28: Cái | D28: 6 | F28: 6 | G28: Công tắc mực nước 3 cực | H28: 61F-GAP | I28: Omron | J28: Japan + China | K28: 6553890 | L28: 0 | M28: 164528 | N28: 650860 | O28: 455602 | P28: =SUM(K28:O28) -> 7824880 | Q28: =D28*P28 -> 46949280 | R28: =F28*P28 -> 46949280
A29: 19 | B29: Van búa nước DN80 | C29: Cái | D29: 2 | E29: PN25 | F29: 2 | G29: Van búa nước, nối bích | H29: FSWH.20 | I29: Flowsure | J29: China | K29: 9487330 | L29: 0 | M29: 289641.6 | N29: 946732 | O29: 662712.4 | P29: =SUM(K29:O29) -> 11386416 | Q29: =D29*P29 -> 22772832 | R29: =F29*P29 -> 22772832 | S29: PN20
A30: 20 | B30: Van chống va xả áp lực dư DN80 | C30: Cái | D30: 2 | E30: PN25 | F30: 2 | G30: Van xả áp, nối bích | H30: FSQR.25 | I30: Flowsure | J30: China | K30: 21508460 | L30: 0 | M30: 289641.6 | N30: 2113832 | O30: 1479682.4 | P30: =SUM(K30:O30) -> 25391616 | Q30: =D30*P30 -> 50783232 | R30: =F30*P30 -> 50783232 | S30: PN25
A31: 21 | B31: Van phao cơ DN100 | C31: Cái | D31: 2 | E31: PN16 | F31: 2 | G31: Van phao, nối bích | H31: FSFL.16 | I31: Flowsure | J31: China | K31: 10708910 | L31: 0 | M31: 203264.4 | N31: 1057688 | O31: 740381.6 | P31: =SUM(K31:O31) -> 12710244 | Q31: =D31*P31 -> 25420488 | R31: =F31*P31 -> 25420488 | S31: PN16
A32: 22 | B32: Van xả khí tự động DN25 | C32: Cái | D32: 9 | F32: 9 | G32: Van xả khí đồng thau, nối ren | H32: F.725.16 | I32: Flowsure | J32: China | K32: 438780 | L32: 0 | M32: 56545.2 | N32: 47604 | O32: 33322.8 | P32: =SUM(K32:O32) -> 576252 | Q32: =D32*P32 -> 5186268 | R32: =F32*P32 -> 5186268 | S32: PN16
A33: 23 | B33: Cụm van giảm áp DN100 (gồm 4 van khóa, 02 van giảm áp) | C33: Cụm | D33: 1 | E33: PN16 | F33: 1 | G33: Van cổng ty chìm, nối bích + Khớp nối mềm inox, nối bích + Van giảm áp, nối bích | H33: FSNG.16 + FSSEF.16 + FSPR.16 | I33: Flowsure | J33: China | K33: 32889960 | L33: 0 | M33: 1829379.6 | N33: 3355092 | O33: 2348564.4 | P33: =SUM(K33:O33) -> 40422996 | Q33: =D33*P33 -> 40422996 | R33: =F33*P33 -> 40422996 | S33: PN16
A34: 24 | B34: Cụm van giảm áp DN80 (gồm 4 van khóa, 02 van giảm áp) | C34: Cụm | D34: 5 | E34: PN16 | F34: 5 | G34: Van cổng ty chìm, nối bích + Khớp nối mềm inox, nối bích + Van giảm áp, nối bích | H34: FSNG.16 + FSSEF.16 + FSPR.16 | I34: Flowsure | J34: China | K34: 28912100 | L34: 0 | M34: 1737849.6 | N34: 2960792 | O34: 2072554.4 | P34: =SUM(K34:O34) -> 35683296 | Q34: =D34*P34 -> 178416480 | R34: =F34*P34 -> 178416480 | S34: PN16
A35: 25 | B35: Cảm biến áp suất | C35: Cái | D35: 2 | F35: 2 | G35: Công tắc áp suất kèm van bi tay gạt Việt Nam, áp lực làm việc PN2-PN14 | H35: KP36 | I35: Danfoss | J35: India | K35: 2656370 | L35: 0 | M35: 164528 | N35: 272460 | O35: 190722 | P35: =SUM(K35:O35) -> 3284080 | Q35: =D35*P35 -> 6568160 | R35: =F35*P35 -> 6568160
A36: 26 | B36: Cửa thăm | C36: Cái | D36: 1 | F36: 1 | S36: Thuộc phạm vi Nhà thầu xây dựng
A37: 27 | B37: Cửa thăm vuông có bản lề hapulico hoặc tương đương | C37: Cái | D37: 6 | F37: 6 | S37: Thuộc phạm vi Nhà thầu xây dựng
A38: 28 | B38: Tấm ghi đậy rãnh B300, KN12,5 | C38: m | D38: 16 | F38: 16 | S38: Thuộc phạm vi Nhà thầu xây dựng
A39: 29 | B39: Bể Inox lắp ghép mái tháp B 32m3 (AxBxH=4x4x2.5) | C39: Cái | D39: 1 | F39: 1 | G39: Bể Inox 304 lắp ghép - Kích thước: D4.0(2.0+2.0) x R4.0 x C2.5 (m); - Dung tích bể: 32m3; - Chia ngăn: Không chia ngăn; - Trọng lượng: Khoảng 1.8 tấn; - Vật liệu: Inox SUS 304; Tấm panel đáy bể dày 3.0mm dập chỏm cầu tăng cứng tại nhà máy, quy cách giống tấm thành và nóc, tấm panel thành 1 (1000x500) dày 2.5mm; Tấm panel thành 2 dày 2.0mm; thành 3 dày 1.5mm; Tấm móc bể dày 1.2mm; Sản xuất theo tiêu chuẩn JIS G4305:2012/ASTM-A240; Hệ giằng, chống trong bể V30x2.0-2.5mm; Hệ U100x45x4.0 chấn mạ kẽm nhúng nóng, lắp đặt bằng bulong mạ kẽm; - Sản xuất theo tiêu chuẩn hệ thống ISO 9001:2015; - Phương pháp lắp đặt: Hàn TIG tại hiện trường. | I39: Sơn Hà | J39: Việt Nam | K39: 304880000 | L39: 0 | M39: 12430000 | N39: 30700000 | O39: 21490000 | P39: =SUM(K39:O39) -> 369500000 | Q39: =D39*P39 -> 369500000 | R39: =F39*P39 -> 369500000
A40: 30 | B40: Bể Inox lắp ghép mái tháp A 36m3 (AxBxH=6x3x2.5) | C40: Cái | D40: 1 | F40: 1 | G40: Bể Inox 304 lắp ghép - Kích thước: D6.0(3.0+3.0) x R3.0 x C2.5 (m); - Dung tích bể: 36m3; - Chia ngăn: Không chia ngăn; - Trọng lượng: Khoảng 2.2 tấn; - Vật liệu: Inox SUS 304; Tấm panel đáy bể dày 3.0mm dập chỏm cầu tăng cứng tại nhà máy, quy cách giống tấm thành và nóc, tấm panel thành 1 (1000x500) dày 2.5mm; Tấm panel thành 2 dày 2.0mm; thành 3 dày 1.5mm; Tấm móc bể dày 1.2mm; Sản xuất theo tiêu chuẩn JIS G4305:2012/ASTM-A240; Hệ giằng, chống trong bể V30x2.0-2.5mm; Hệ U100x45x4.0 chấn mạ kẽm nhúng nóng, lắp đặt bằng bulong mạ kẽm; - Sản xuất theo tiêu chuẩn hệ thống ISO 9001:2015; - Phương pháp lắp đặt: Hàn TIG tại hiện trường. | I40: Sơn Hà | J40: Việt Nam | K40: 323832000 | L40: 0 | M40: 13560000 | N40: 32640000 | O40: 22848000 | P40: =SUM(K40:O40) -> 392880000 | Q40: =D40*P40 -> 392880000 | R40: =F40*P40 -> 392880000
A41: 31 | B41: Nắp ghi gang ga thu sàn 400x600 | C41: Cái | D41: 10 | F41: 10 | S41: Thuộc phạm vi Nhà thầu xây dựng
...

Sheet 4.1 ĐH VRV
A1: Dự án: TOÀ NHÀ HỖN HỢP HACOM MALL
A2: Gói thầu: CUNG CẤP VTTB VÀ THI CÔNG LẮP ĐẶT HỆ THỐNG CƠ ĐIỆN
A3: Hạng mục: HỆ THỐNG HVAC
A5: KHỐI LƯỢNG MỜI THẦU | U5: CÔNG TY TNHH XÂY LẮP VÀ THƯƠNG MẠI LINH ANH
A6: STT | B6: Diễn giải | C6: TẦNGH2 | D6: TẦNGH1 | E6: TẦNG1 | F6: TẦNG2 | G6: TẦNG3 | H6: TẦNG4 | I6: TẦNG5 | J6: TẦNG23 | K6: Đơn vị | L6: KL Mời thầu Lần 2 | M6: Công suất lạnh Kw | N6: Lưu lượng gió (m3/min) | O6: Cột áp (Pa) | P6: Công suất điện (W) | Q6: Điên áp (P/V/Hz) | R6: Môi chất lạnh | S6: Quy cách | T6: Ghi chú | U6: KL Nhà thầu chào | V6: THÔNG TIN VỀ VẬT LIỆU CHÍNH | Z6: ĐƠN GIÁ (chưa bao gồm VAT) | AF6: Thành tiền BOQ | AH6: Ghi chú
V7: Mô tả/ Quy cách | W7: Mã hiệu | X7: Thương hiệu | Y7: Xuất xứ | Z7: VL chính | AA7: VL phụ | AB7: NC&M | AC7: CF quản lý | AD7: Lợi nhuận | AE7: ĐG tổng hợp | AF7: Thành tiền KLMT | AG7: Thành tiền Nhà thầu chào
A8: 1 | B8: 2 | K8: 3 | L8: 4 | T8: 5 | U8: 6 | V8: 7 | W8: 8 | X8: 9 | Y8: 10 | Z8: 11 | AA8: 12 | AB8: 13 | AC8: 14 | AD8: 15 | AE8: 16=11+12+13+14+15 | AF8: 17=4*16 | AG8: 18=6*16 | AH8: 19
A9: A | B9: ĐẦU MỤC CÔNG VIỆC THEO KLMT | AF9: =SUBTOTAL(9,AF10:AF48) -> 7.3670039e+08 | AG9: =SUBTOTAL(9,AG10:AG48) -> 7.3670039e+08
B10: THIẾT BỊ ĐIỀU HOÀ KHÔNG KHÍ
A11: I. THIẾT BỊ ĐIỀU HÒA VRV (VRF)
A12: 1. DÀN LẠNH ĐIỀU HÒA VRV, VRF
A13: 1 | B13: Dàn lạnh 1 chiều lạnh loại âm trần nối ống gió | I13: 1 | K13: cái | L13: 1 | M13: 4.5 | N13: 16/13/11 | O13: 50-200 | P13: 151 | Q13: 1P/220/50 | R13: R410A | S13: Đồng bộ với dàn nóng kèm điều khiển từ xa loại có dây | T13: Nhà thầu lắp đặt, CĐT cấp thiết bị | U13: 1 | Y13: CĐT cấp, nhà thầu lắp đặt | Z13: 0 | AA13: 259848 | AB13: 405891.25 | AC13: 365302.12 | AD13: 243534.75 | AE13: =SUM(Z13:AD13) -> 1274576.1 | AF13: =L13*AE13 -> 1274576.1 | AG13: =U13*AE13 -> 1274576.1
A14: 2 | B14: Dàn lạnh 1 chiều lạnh loại âm trần nối ống gió | E14: 1 | F14: 4 | G14: 2 | H14: 8 | I14: 3 | K14: cái | L14: 18 | M14: 5.6 | N14: 18/16,5/15 | O14: 50-200 | P14: 128 | Q14: 1P/220/50 | R14: R410A | S14: Đồng bộ với dàn nóng kèm điều khiển từ xa loại có dây | U14: 18 | Y14: CĐT cấp, nhà thầu lắp đặt | Z14: 0 | AA14: 259848 | AB14: 405891.25 | AC14: 365302.12 | AD14: 243534.75 | AE14: =SUM(Z14:AD14) -> 1274576.1 | AF14: =L14*AE14 -> 22942370 | AG14: =U14*AE14 -> 22942370
A15: 3 | B15: Dàn lạnh 1 chiều lạnh loại âm trần nối ống gió | E15: 6 | F15: 7 | G15: 2 | I15: 6 | K15: cái | L15: 20 | M15: 7.1 | N15: 19.5/17.5/16 | O15: 50-200 | P15: 138 | Q15: 1P/220/50 | R15: R410A | S15: Đồng bộ với dàn nóng kèm điều khiển từ xa loại có dây | U15: 20 | Y15: CĐT cấp, nhà thầu lắp đặt | Z15: 0 | AA15: 259848 | AB15: 415644.38 | AC15: 374079.94 | AD15: 249386.62 | AE15: =SUM(Z15:AD15) -> 1298958.9 | AF15: =L15*AE15 -> 25979179 | AG15: =U15*AE15 -> 25979179
A16: 4 | B16: Dàn lạnh 1 chiều lạnh loại âm trần nối ống gió | E16: 2 | F16: 11 | G16: 7 | H16: 8 | I16: 8 | K16: cái | L16: 34 | M16: 9 | N16: 25/22,2/20 | O16: 50-200 | P16: 185 | Q16: 1P/220/50 | R16: R410A | S16: Đồng bộ với dàn nóng kèm điều khiển từ xa loại có dây | U16: 34 | Y16: CĐT cấp, nhà thầu lắp đặt | Z16: 0 | AA16: 259848 | AB16: 425397.5 | AC16: 382857.75 | AD16: 255238.5 | AE16: =SUM(Z16:AD16) -> 1323341.8 | AF16: =L16*AE16 -> 44993620 | AG16: =U16*AE16 -> 44993620
A17: 5 | B17: Dàn lạnh 1 chiều lạnh loại âm trần nối ống gió | E17: 8 | F17: 10 | G17: 16 | H17: 13 | I17: 3 | K17: cái | L17: 51 | M17: 11.2 | N17: 32/27/23 | O17: 50-200 | P17: 215 | Q17: 1P/220/50 | R17: R410A | S17: Đồng bộ với dàn nóng kèm điều khiển từ xa loại có dây | U17: 51 | Y17: CĐT cấp, nhà thầu lắp đặt | Z17: 0 | AA17: 259848 | AB17: 535970 | AC17: 482373 | AD17: 321582 | AE17: =SUM(Z17:AD17) -> 1599773 | AF17: =L17*AE17 -> 81588423 | AG17: =U17*AE17 -> 81588423
A18: 6 | B18: Dàn lạnh 1 chiều lạnh loại âm trần nối ống gió | E18: 1 | F18: 4 | G18: 4 | H18: 4 | I18: 2 | K18: cái | L18: 16 | M18: 14 | N18: 39/33/28 | O18: 50-200 | P18: 284 | Q18: 1P/220/50 | R18: R410A | S18: Đồng bộ với dàn nóng kèm điều khiển từ xa loại có dây | U18: 16 | Y18: CĐT cấp, nhà thầu lắp đặt | Z18: 0 | AA18: 259848 | AB18: 619171.88 | AC18: 557254.69 | AD18: 371503.12 | AE18: =SUM(Z18:AD18) -> 1807777.7 | AF18: =L18*AE18 -> 28924443 | AG18: =U18*AE18 -> 28924443
A19: 7 | B19: Dàn lạnh 1 chiều lạnh loại âm trần nối ống gió | E19: 1 | F19: 21 | G19: 28 | H19: 19 | I19: 17 | K19: cái | L19: 85 | M19: 16 | N19: 16/39/32 | O19: 50-200 | P19: 405 | Q19: 1P/220/50 | R19: R410A | S19: Đồng bộ với dàn nóng kèm điều khiển từ xa loại có dây | U19: 85 | Y19: CĐT cấp, nhà thầu lắp đặt | Z19: 0 | AA19: 259848 | AB19: 702373.75 | AC19: 632136.38 | AD19: 421424.25 | AE19: =SUM(Z19:AD19) -> 2015782.4 | AF19: =L19*AE19 -> 1.713415e+08 | AG19: =U19*AE19 -> 1.713415e+08
A20: 8 | B20: Dàn lạnh 1 chiều lạnh loại âm trần nối ống gió | E20: 8 | I20: 6 | K20: cái | L20: 14 | M20: 22.4 | N20: 16/39/32 | O20: 50-200 | P20: 405 | Q20: 1P/220/50 | R20: R410A | S20: Đồng bộ với dàn nóng kèm điều khiển từ xa loại có dây | U20: 14 | Y20: CĐT cấp, nhà thầu lắp đặt | Z20: 0 | AA20: 259848 | AB20: 880343.75 | AC20: 792309.38 | AD20: 528206.25 | AE20: =SUM(Z20:AD20) -> 2460707.4 | AF20: =L20*AE20 -> 34449903 | AG20: =U20*AE20 -> 34449903
A21: 9 | B21: Dàn lạnh 1 chiều lạnh loại treo tường | I21: 1 | K21: cái | L21: 1 | M21: 2.2 | N21: 16/39/32 | O21: 50-200 | P21: 405 | Q21: 1P/220/50 | R21: R410A | S21: Đồng bộ với dàn nóng kèm điều khiển từ xa loại có dây | U21: 1 | Y21: CĐT cấp, nhà thầu lắp đặt | Z21: 0 | AA21: 0 | AB21: 262431.25 | AC21: 236188.12 | AD21: 157458.75 | AE21: =SUM(Z21:AD21) -> 656078.12 | AF21: =L21*AE21 -> 656078.12 | AG21: =U21*AE21 -> 656078.12
A22: 10 | B22: Dàn lạnh 1 chiều lạnh loại cassette âm trần | I22: 1 | K22: cái | L22: 1 | M22: 2.2 | N22: 9,5/8/7 | O22: 50-200 | P22: 60 | Q22: 1P/220/50 | R22: R410A | S22: Đồng bộ với dàn nóng kèm điều khiển từ xa loại có dây | U22: 1 | Y22: CĐT cấp, nhà thầu lắp đặt | Z22: 0 | AA22: 259848 | AB22: 405891.25 | AC22: 365302.12 | AD22: 243534.75 | AE22: =SUM(Z22:AD22) -> 1274576.1 | AF22: =L22*AE22 -> 1274576.1 | AG22: =U22*AE22 -> 1274576.1
A23: 11 | B23: Dàn lạnh 1 chiều lạnh loại cassette âm trần | I23: 1 | K23: cái | L23: 1 | M23: 7.1 | N23: 16/39/32 | O23: 50-200 | P23: 405 | Q23: 1P/220/50 | R23: R410A | S23: Đồng bộ với dàn nóng kèm điều khiển từ xa loại có dây | U23: 1 | Y23: CĐT cấp, nhà thầu lắp đặt | Z23: 0 | AA23: 259848 | AB23: 415644.38 | AC23: 374079.94 | AD23: 249386.62 | AE23: =SUM(Z23:AD23) -> 1298958.9 | AF23: =L23*AE23 -> 1298958.9 | AG23: =U23*AE23 -> 1298958.9
A24: 12 | B24: Dàn lạnh 1 chiều lạnh loại cassette âm trần | I24: 2 | K24: cái | L24: 2 | M24: 14 | N24: 16/39/32 | O24: 50-200 | P24: 405 | Q24: 1P/220/50 | R24: R410A | S24: Đồng bộ với dàn nóng kèm điều khiển từ xa loại có dây | U24: 2 | Y24: CĐT cấp, nhà thầu lắp đặt | Z24: 0 | AA24: 259848 | AB24: 619171.88 | AC24: 557254.69 | AD24: 371503.12 | AE24: =SUM(Z24:AD24) -> 1807777.7 | AF24: =L24*AE24 -> 3615555.4 | AG24: =U24*AE24 -> 3615555.4
A25: 2. DÀN NÓNG ĐIỀU HÒA VRV, VRF
A26: 1 | B26: Dàn nóng 1 chiều lạnh (22HP). | E26: 1 | K26: cái | L26: 1 | M26: 61.5 | N26: -- | O26: -- | P26: 16100 | Q26: 3P/380/50 | R26: R410A | S26: Trọn bộ | T26: Nhà thầu lắp đặt, CĐT cấp thiết bị | U26: 1 | Y26: CĐT cấp, nhà thầu lắp đặt | Z26: 0 | AA26: 2154600 | AB26: 1972731.7 | AC26: 1775458.5 | AD26: 1183639 | AE26: =SUM(Z26:AD26) -> 7086429.2 | AF26: =L26*AE26 -> 7086429.2 | AG26: =U26*AE26 -> 7086429.2
A27: 2 | B27: Dàn nóng 1 chiều lạnh (24HP). | E27: 1 | K27: cái | L27: 1 | M27: 67 | N27: -- | O27: -- | P27: 17800 | Q27: 3P/380/50 | R27: R410A | S27: Trọn bộ | U27: 1 | Y27: CĐT cấp, nhà thầu lắp đặt | Z27: 0 | AA27: 2154600 | AB27: 2465914.4 | AC27: 2219323 | AD27: 1479548.7 | AE27: =SUM(Z27:AD27) -> 8319386.1 | AF27: =L27*AE27 -> 8319386.1 | AG27: =U27*AE27 -> 8319386.1
A28: 3 | B28: Dàn nóng 1 chiều lạnh (26HP). | E28: 1 | K28: cái | L28: 1 | M28: 73.5 | N28: -- | O28: -- | P28: 19900 | Q28: 3P/380/50 | R28: R410A | S28: Trọn bộ | U28: 1 | Y28: CĐT cấp, nhà thầu lắp đặt | Z28: 0 | AA28: 2154600 | AB28: 2465914.4 | AC28: 2219323 | AD28: 1479548.7 | AE28: =SUM(Z28:AD28) -> 8319386.1 | AF28: =L28*AE28 -> 8319386.1 | AG28: =U28*AE28 -> 8319386.1
A29: 4 | B29: Dàn nóng 1 chiều lạnh (32HP). | H29: 1 | K29: cái | L29: 1 | M29: 90 | N29: -- | O29: -- | P29: 25800 | Q29: 3P/380/50 | R29: R410A | S29: Trọn bộ | U29: 1 | Y29: CĐT cấp, nhà thầu lắp đặt | Z29: 0 | AA29: 2154600 | AB29: 2860461.1 | AC29: 2574415 | AD29: 1716276.7 | AE29: =SUM(Z29:AD29) -> 9305752.8 | AF29: =L29*AE29 -> 9305752.8 | AG29: =U29*AE29 -> 9305752.8
A30: 5 | B30: Dàn nóng 1 chiều lạnh (34HP). | I30: 1 | K30: cái | L30: 1 | M30: 95 | N30: -- | O30: -- | P30: 28200 | Q30: 3P/380/50 | R30: R410A | S30: Trọn bộ | U30: 1 | Y30: CĐT cấp, nhà thầu lắp đặt | Z30: 0 | AA30: 2154600 | AB30: 3255007.8 | AC30: 2929507 | AD30: 1953004.7 | AE30: =SUM(Z30:AD30) -> 10292119 | AF30: =L30*AE30 -> 10292119 | AG30: =U30*AE30 -> 10292119
A31: 6 | B31: Dàn nóng 1 chiều lạnh (36HP). | H31: 2 | K31: cái | L31: 2 | M31: 101 | N31: -- | O31: -- | P31: 30600 | Q31: 3P/380/50 | R31: R410A | S31: Trọn bộ | U31: 2 | Y31: CĐT cấp, nhà thầu lắp đặt | Z31: 0 | AA31: 2154600 | AB31: 3255007.8 | AC31: 2929507 | AD31: 1953004.7 | AE31: =SUM(Z31:AD31) -> 10292119 | AF31: =L31*AE31 -> 20584239 | AG31: =U31*AE31 -> 20584239
A32: 7 | B32: Dàn nóng 1 chiều lạnh (38HP). | H32: 1 | I32: 1 | K32: cái | L32: 2 | M32: 106 | N32: -- | O32: -- | P32: 33000 | Q32: 3P/380/50 | R32: R410A | S32: Trọn bộ | U32: 2 | Y32: CĐT cấp, nhà thầu lắp đặt | Z32: 0 | AA32: 2154600 | AB32: 3255007.8 | AC32: 2929507 | AD32: 1953004.7 | AE32: =SUM(Z32:AD32) -> 10292119 | AF32: =L32*AE32 -> 20584239 | AG32: =U32*AE32 -> 20584239
A33: 8 | B33: Dàn nóng 1 chiều lạnh (40HP). | F33: 1 | G33: 1 | K33: cái | L33: 2 | M33: 112 | N33: -- | O33: -- | P33: 35400 | Q33: 3P/380/50 | R33: R410A | S33: Trọn bộ | U33: 2 | Y33: CĐT cấp, nhà thầu lắp đặt | Z33: 0 | AA33: 2154600 | AB33: 3255007.8 | AC33: 2929507 | AD33: 1953004.7 | AE33: =SUM(Z33:AD33) -> 10292119 | AF33: =L33*AE33 -> 20584239 | AG33: =U33*AE33 -> 20584239
A34: 9 | B34: Dàn nóng 1 chiều lạnh (42HP). | F34: 1 | H34: 1 | K34: cái | L34: 2 | M34: 117 | N34: -- | O34: -- | P34: 32700 | Q34: 3P/380/50 | R34: R410A | S34: Trọn bộ | U34: 2 | Y34: CĐT cấp, nhà thầu lắp đặt | Z34: 0 | AA34: 2154600 | AB34: 3476940 | AC34: 3129246 | AD34: 2086164 | AE34: =SUM(Z34:AD34) -> 10846950 | AF34: =L34*AE34 -> 21693900 | AG34: =U34*AE34 -> 21693900
A35: 10 | B35: Dàn nóng 1 chiều lạnh (44HP). | F35: 1 | K35: cái | L35: 1 | M35: 123 | N35: -- | O35: -- | P35: 35100 | Q35: 3P/380/50 | R35: R410A | S35: Trọn bộ | U35: 1 | Y35: CĐT cấp, nhà thầu lắp đặt | Z35: 0 | AA35: 2154600 | AB35: 3476940 | AC35: 3129246 | AD35: 2086164 | AE35: =SUM(Z35:AD35) -> 10846950 | AF35: =L35*AE35 -> 10846950 | AG35: =U35*AE35 -> 10846950
A36: 11 | B36: Dàn nóng 1 chiều lạnh (46HP). | H36: 1 | K36: cái | L36: 1 | M36: 145 | N36: -- | O36: -- | P36: 36500 | Q36: 3P/380/50 | R36: R410A | S36: Trọn bộ | U36: 1 | Y36: CĐT cấp, nhà thầu lắp đặt | Z36: 0 | AA36: 2154600 | AB36: 4438646.7 | AC36: 3994782 | AD36: 2663188 | AE36: =SUM(Z36:AD36) -> 13251217 | AF36: =L36*AE36 -> 13251217 | AG36: =U36*AE36 -> 13251217
A37: 12 | B37: Dàn nóng 1 chiều lạnh (50HP). | I37: 2 | K37: cái | L37: 2 | M37: 140 | N37: -- | O37: -- | P37: 41100 | Q37: 3P/380/50 | R37: R410A | S37: Trọn bộ | U37: 2 | Y37: CĐT cấp, nhà thầu lắp đặt | Z37: 0 | AA37: 2154600 | AB37: 3698872.2 | AC37: 3328985 | AD37: 2219323.3 | AE37: =SUM(Z37:AD37) -> 11401781 | AF37: =L37*AE37 -> 22803561 | AG37: =U37*AE37 -> 22803561
A38: 13 | B38: Dàn nóng 1 chiều lạnh (58HP). | E38: 1 | K38: cái | L38: 1 | M38: 162 | N38: -- | O38: -- | P38: 50700 | Q38: 3P/380/50 | R38: R410A | S38: Trọn bộ | U38: 1 | Y38: CĐT cấp, nhà thầu lắp đặt | Z38: 0 | AA38: 2154600 | AB38: 5178421.1 | AC38: 4660579 | AD38: 3107052.7 | AE38: =SUM(Z38:AD38) -> 15100653 | AF38: =L38*AE38 -> 15100653 | AG38: =U38*AE38 -> 15100653
A39: 14 | B39: Dàn nóng 1 chiều lạnh (60HP). | F39: 2 | G39: 4 | I39: 1 | K39: cái | L39: 7 | M39: 158 | N39: -- | O39: -- | P39: 53100 | Q39: 3P/380/50 | R39: R410A | S39: Trọn bộ | U39: 7 | Y39: CĐT cấp, nhà thầu lắp đặt | Z39: 0 | AA39: 2154600 | AB39: 5178421.1 | AC39: 4660579 | AD39: 3107052.7 | AE39: =SUM(Z39:AD39) -> 15100653 | AF39: =L39*AE39 -> 1.0570457e+08 | AG39: =U39*AE39 -> 1.0570457e+08
A40: II. THIẾT BỊ ĐIỀU HÒA CỤC BỘ
A41: 1. HỆ THỐNG ĐIỀU HÒA CỤC BỘ
...

Sheet 4.2 Quạt
A1: Dự án: TOÀ NHÀ HỖN HỢP HACOM MALL
A2: Gói thầu: CUNG CẤP VTTB VÀ THI CÔNG LẮP ĐẶT HỆ THỐNG CƠ ĐIỆN
A3: Hạng mục: HỆ THỐNG HVAC
A5: KHỐI LƯỢNG MỜI THẦU | R5: CÔNG TY TNHH XÂY LẮP VÀ THƯƠNG MẠI LINH ANH
A6: STT | B6: DANH MỤC QUẠT THÔNG GIÓ | C6: Đơn vị | D6: KL Mời thầu Lần 1 | E6: KL BIM | F6: KL Mời thầu Lần 2 | G6: KÍ HIỆU | H6: LƯU LƯỢNG | I6: CỘP ÁP | J6: QUY CÁCH | K6: NHIỆT ĐỘ LÀM VIỆC | L6: CÔNG SUẤT ĐIỆN | M6: NGUỒN ĐIỆN | N6: ĐỘ ỒN | O6: HIỆU SUẤT | P6: Tốc độ vòng quay | Q6: GHI CHÚ | R6: KL Nhà thầu chào | S6: THÔNG TIN VỀ VẬT LIỆU CHÍNH | W6: ĐƠN GIÁ (chưa bao gồm VAT) | AC6: Thành tiền BOQ | AE6: Ghi chú
I7: Pa | K7: oC | L7: kW | M7: V/Ph/Hz | N7: dBA @ 3M | S7: Mô tả/ Quy cách | T7: Mã hiệu | U7: Thương hiệu | V7: Xuất xứ | W7: VL chính | X7: VL phụ | Y7: NC&M | Z7: CF quản lý | AA7: Lợi nhuận | AB7: ĐG tổng hợp | AC7: Thành tiền KLMT | AD7: Thành tiền Nhà thầu chào
A8: 1 | B8: 2 | C8: 3 | F8: 4 | Q8: 5 | R8: 6 | S8: 7 | T8: 8 | U8: 9 | V8: 10 | W8: 11 | X8: 12 | Y8: 13 | Z8: 14 | AA8: 15 | AB8: 16=11+12+13+14+15 | AC8: 17=4*16 | AD8: 18=6*16 | AE8: 19
A9: A | B9: ĐẦU MỤC CÔNG VIỆC THEO KLMT | AC9: =SUBTOTAL(9,AC10:AC144) -> 3.2077763e+09 | AD9: =SUBTOTAL(9,AD10:AD144) -> 3.2077763e+09
A10: I | B10: QUẠT THÔNG GIÓ CẤP, HÚT
B11: QUẠT THÔNG GIÓ CẤP, HÚT TẦNG HẦM - TUM
B12: Tầng hầm 2
A13: 1 | B13: QUẠT HÚT PHÒNG QUẠT HÚT 1 | C13: Cái | D13: 1 | E13: 1 | F13: =E13 -> 1 | G13: TH2/EF-03 | H13: 650 | I13: 25 | J13: Fan wall mounted | K13: 55 | L13: 0.37 | M13: 220/1/50 | N13: ≤ 65 dBA | O13: ≥ 50 % | P13: ≤ 2900 rpm | R13: 1 | S13: Quạt hút gắn tường TH2/EF-03, Q=650m3/h, 25Pa, CSĐ: 0.034kW, Điện áp 1P/220V/50Hz, Độ ồn 48 dBA (dBA @ 1m), Tốc độ vòng quay 4P, IP44, Nhựa PP | T13: VNS-AV6-25 | U13: TH VINASUN | V13: Việt Nam | W13: 422712 | X13: 0 | Y13: 164231.12 | Z13: 55573.727 | AA13: 38901.609 | AB13: =SUM(W13:AA13) -> 681418.45 | AC13: =F13*AB13 -> 681418.45 | AD13: =R13*AB13 -> 681418.45
A14: 2 | B14: QUẠT HÚT PHÒNG QUẠT HÚT 2 | C14: Cái | D14: 1 | E14: 1 | F14: =E14 -> 1 | G14: TH2/EF-04 | H14: 650 | I14: 25 | J14: Fan wall mounted | K14: 55 | L14: 0.37 | M14: 220/1/50 | N14: ≤ 65 dBA | O14: ≥ 50 % | P14: ≤ 2900 rpm | R14: 1 | S14: Quạt hút gắn tường TH2/EF-04, Q=650m3/h, 25Pa, CSĐ: 0.034kW, Điện áp 1P/220V/50Hz, Độ ồn 48 dBA (dBA @ 1m), Tốc độ vòng quay 4P, IP44, Nhựa PP | T14: VNS-AV6-25 | U14: TH VINASUN | V14: Việt Nam | W14: 422712 | X14: 0 | Y14: 164231.12 | Z14: 55573.727 | AA14: 38901.609 | AB14: =SUM(W14:AA14) -> 681418.45 | AC14: =F14*AB14 -> 681418.45 | AD14: =R14*AB14 -> 681418.45
A15: 3 | B15: QUẠT HÚT PHÒNG QUẠT HÚT 3 | C15: Cái | D15: 1 | E15: 1 | F15: =E15 -> 1 | G15: TH2/EF-05 | H15: 1000 | I15: 50 | J15: Fan wall mounted | K15: 55 | L15: 0.37 | M15: 220/1/50 | N15: ≤ 65 dBA | O15: ≥ 50 % | P15: ≤ 2900 rpm | R15: 1 | S15: Quạt hút gắn tường TH2/EF-05, Q=1000m3/h, 50Pa, CSĐ: 0.034kW, Điện áp 1P/220V/50Hz, Độ ồn 48 dBA (dBA @ 1m), Tốc độ vòng quay 4P, IP44, Nhựa PP | T15: VNS-AV6-25 | U15: TH VINASUN | V15: Việt Nam | W15: 422712 | X15: 0 | Y15: 164231.12 | Z15: 55573.727 | AA15: 38901.609 | AB15: =SUM(W15:AA15) -> 681418.45 | AC15: =F15*AB15 -> 681418.45 | AD15: =R15*AB15 -> 681418.45
A16: 4 | B16: QUẠT HÚT PHÒNG QUẠT CẤP | C16: Cái | D16: 1 | E16: 1 | F16: =E16 -> 1 | G16: TH2/EF-06 | H16: 650 | I16: 25 | J16: Fan wall mounted | K16: 55 | L16: 0.37 | M16: 220/1/50 | N16: ≤ 65 dBA | O16: ≥ 50 % | P16: ≤ 2900 rpm | R16: 1 | S16: Quạt hút gắn tường TH2/EF-06, Q=650m3/h, 25Pa, CSĐ: 0.034kW, Điện áp 1P/220V/50Hz, Độ ồn 48 dBA (dBA @ 1m), Tốc độ vòng quay 4P, IP44, Nhựa PP | T16: VNS-AV6-25 | U16: TH VINASUN | V16: Việt Nam | W16: 422712 | X16: 0 | Y16: 164231.12 | Z16: 55573.727 | AA16: 38901.609 | AB16: =SUM(W16:AA16) -> 681418.45 | AC16: =F16*AB16 -> 681418.45 | AD16: =R16*AB16 -> 681418.45
A17: 6 | B17: QUẠT HÚT KHO 1 | C17: Cái | D17: 1 | E17: 1 | F17: =E17 -> 1 | G17: TH2/EF-08 | H17: 650 | I17: 25 | J17: Fan wall mounted | K17: 55 | L17: 0.37 | M17: 220/1/50 | N17: ≤ 65 dBA | O17: ≥ 50 % | P17: ≤ 2900 rpm | R17: 1 | S17: Quạt hút gắn tường TH2/EF-08, Q=650m3/h, 25Pa, CSĐ: 0.034kW, Điện áp 1P/220V/50Hz, Độ ồn 48 dBA (dBA @ 1m), Tốc độ vòng quay 4P, IP44, Nhựa PP | T17: VNS-AV6-25 | U17: TH VINASUN | V17: Việt Nam | W17: 422712 | X17: 0 | Y17: 164231.12 | Z17: 55573.727 | AA17: 38901.609 | AB17: =SUM(W17:AA17) -> 681418.45 | AC17: =F17*AB17 -> 681418.45 | AD17: =R17*AB17 -> 681418.45
A18: 7 | B18: QUẠT HÚT KHO 2 | C18: Cái | D18: 1 | E18: 1 | F18: =E18 -> 1 | G18: TH2/EF-09 | H18: 250 | I18: 20 | J18: Fan wall mounted | K18: 55 | L18: 0.37 | M18: 220/1/50 | N18: ≤ 65 dBA | O18: ≥ 50 % | P18: ≤ 1450 rpm | R18: 1 | S18: Quạt hút gắn tường TH2/EF-09, Q=250m3/h, 20Pa, CSĐ: 0.029kW, Điện áp 1P/220V/50Hz, Độ ồn 45 dBA (dBA @ 1m), Tốc độ vòng quay 4P, IP44, Nhựa PP | T18: VNS-AV6-15 | U18: TH VINASUN | V18: Việt Nam | W18: 344844 | X18: 0 | Y18: 136854.3 | Z18: 45591 | AA18: 31913.7 | AB18: =SUM(W18:AA18) -> 559203 | AC18: =F18*AB18 -> 559203 | AD18: =R18*AB18 -> 559203
A19: 8 | B19: QUẠT HÚT KHO 3 | C19: Cái | D19: 1 | E19: 1 | F19: =E19 -> 1 | G19: TH2/EF-10 | H19: 350 | I19: 25 | J19: Fan wall mounted | K19: 55 | L19: 0.37 | M19: 220/1/50 | N19: ≤ 65 dBA | O19: ≥ 50 % | P19: ≤ 1450 rpm | R19: 1 | S19: Quạt hút gắn tường TH2/EF-10, Q=350m3/h, 25Pa, CSĐ: 0.031kW, Điện áp 1P/220V/50Hz, Độ ồn 47 dBA (dBA @ 1m), Tốc độ vòng quay 4P, IP44, Nhựa PP | T19: VNS-AV6-20 | U19: TH VINASUN | V19: Việt Nam | W19: 389340 | X19: 0 | Y19: 136854.3 | Z19: 49911 | AA19: 34937.7 | AB19: =SUM(W19:AA19) -> 611043 | AC19: =F19*AB19 -> 611043 | AD19: =R19*AB19 -> 611043
A20: 9 | B20: QUẠT HÚT KHO 4 | C20: Cái | D20: 1 | E20: 1 | F20: =E20 -> 1 | G20: TH2/EF-11 | H20: 150 | I20: 20 | J20: Fan wall mounted | K20: 55 | L20: 0.37 | M20: 220/1/50 | N20: ≤ 65 dBA | O20: ≥ 50 % | R20: 1 | S20: Quạt hút gắn tường TH2/EF-11, Q=150m3/h, 20Pa, CSĐ: 0.029kW, Điện áp 1P/220V/50Hz, Độ ồn 45 dBA (dBA @ 1m), Tốc độ vòng quay 4P, IP44, Nhựa PP | T20: VNS-AV6-15 | U20: TH VINASUN | V20: Việt Nam | W20: 344844 | X20: 0 | Y20: 136854.3 | Z20: 45591 | AA20: 31913.7 | AB20: =SUM(W20:AA20) -> 559203 | AC20: =F20*AB20 -> 559203 | AD20: =R20*AB20 -> 559203
A21: 10 | B21: QUẠT CẤP GIÓ TẦNG HẦM ZONE 1 | C21: Cái | D21: 2 | E21: 2 | F21: =E21 -> 2 | G21: TH2/SF-01.1,2 | H21: 20500 | I21: 400 | J21: Axial Fan/In-Line Fan/ Cabinet Fan | K21: 55 | L21: 11 | M21: 380/3/50 | N21: ≤ 65 dBA | O21: ≥ 50 % | R21: 2 | S21: Quạt cấp gió ly tâm dạng hộp TH2/SF-01.1,2, Q=20500m3/h, 400Pa, CSĐ: 7.5W, Điện áp 3P/380V/50Hz, Độ ồn 61 dBA (dBA @ 3m), Tốc độ vòng quay 4P, IP55, Thép SS400 mạ kẽm nhúng nóng | T21: VNS-CF1S-7T Động cơ ATT IE1 | U21: TH VINASUN | V21: Việt Nam | W21: 31703400 | X21: 259848 | Y21: 1724120.1 | Z21: 3230577 | AA21: 2261403.9 | AB21: =SUM(W21:AA21) -> 39179349 | AC21: =F21*AB21 -> 78358698 | AD21: =R21*AB21 -> 78358698
A22: 11 | B22: QUẠT CẤP GIÓ TẦNG HẦM ZONE 2 | C22: Cái | D22: 1 | E22: 1 | F22: =E22 -> 1 | G22: TH2/SF-02 | H22: 39000 | I22: 400 | J22: Axial Fan/In-Line Fan/ Cabinet Fan | K22: 55 | L22: 15 | M22: 380/3/50 | N22: ≤ 65 dBA | O22: ≥ 50 % | R22: 1 | S22: Quạt cấp gió ly tâm dạng hộp TH2/SF-02, Q=39000m3/h, 400Pa, CSĐ: 11kW, Điện áp 3P/380V/50Hz, Độ ồn 64 dBA (dBA @ 3m), Tốc độ vòng quay 4P, IP55, Thép SS400 mạ kẽm nhúng nóng | T22: VNS-CF1S-8T Động cơ ATT IE1 | U22: TH VINASUN | V22: Việt Nam | W22: 46128447 | X22: 259848 | Y22: 2229872.1 | Z22: 4675823.8 | AA22: 3273076.7 | AB22: =SUM(W22:AA22) -> 56567068 | AC22: =F22*AB22 -> 56567068 | AD22: =R22*AB22 -> 56567068
B23: Tầng hầm 1
A24: 12 | B24: QUẠT HÚT PHÒNG QUẠT HÚT 1 | C24: Cái | D24: 1 | E24: 1 | F24: =E24 -> 1 | G24: TH1/EF-03 | H24: 1000 | I24: 50 | J24: Fan wall mounted | K24: 55 | L24: 0.37 | M24: 220/1/50 | N24: ≤ 65 dBA | O24: ≥ 50 % | R24: 1 | S24: Quạt hút gắn tường TH1/EF-03, Q=1000m3/h, 50Pa, CSĐ: 0.034kW, Điện áp 1P/220V/50Hz, Độ ồn 48 dBA (dBA @ 1m), Tốc độ vòng quay 4P, IP44, Nhựa PP | T24: VNS-AV6-25 | U24: TH VINASUN | V24: Việt Nam | W24: 422712 | X24: 0 | Y24: 164231.12 | Z24: 55573.727 | AA24: 38901.609 | AB24: =SUM(W24:AA24) -> 681418.45 | AC24: =F24*AB24 -> 681418.45 | AD24: =R24*AB24 -> 681418.45
A25: =A24+1 -> 13 | B25: QUẠT HÚT PHÒNG QUẠT HÚT 2 | C25: Cái | D25: 1 | E25: 1 | F25: =E25 -> 1 | G25: TH1/EF-04 | H25: 650 | I25: 25 | J25: Fan wall mounted | K25: 55 | L25: 0.37 | M25: 220/1/50 | N25: ≤ 65 dBA | O25: ≥ 50 % | R25: 1 | S25: Quạt hút gắn tường TH1/EF-04, Q=650m3/h, 25Pa, CSĐ: 0.034kW, Điện áp 1P/220V/50Hz, Độ ồn 48 dBA (dBA @ 1m), Tốc độ vòng quay 4P, IP44, Nhựa PP | T25: VNS-AV6-25 | U25: TH VINASUN | V25: Việt Nam | W25: 422712 | X25: 0 | Y25: 164231.12 | Z25: 55573.727 | AA25: 38901.609 | AB25: =SUM(W25:AA25) -> 681418.45 | AC25: =F25*AB25 -> 681418.45 | AD25: =R25*AB25 -> 681418.45
A26: =A25+1 -> 14 | B26: QUẠT HÚT PHÒNG QUẠT HÚT 3 | C26: Cái | D26: 1 | E26: 1 | F26: =E26 -> 1 | G26: TH1/EF-05 | H26: 1000 | I26: 50 | J26: Fan wall mounted | K26: 55 | L26: 0.37 | M26: 220/1/50 | N26: ≤ 65 dBA | O26: ≥ 50 % | R26: 1 | S26: Quạt hút gắn tường TH1/EF-05, Q=1000m3/h, 50Pa, CSĐ: 0.034kW, Điện áp 1P/220V/50Hz, Độ ồn 48 dBA (dBA @ 1m), Tốc độ vòng quay 4P, IP44, Nhựa PP | T26: VNS-AV6-25 | U26: TH VINASUN | V26: Việt Nam | W26: 422712 | X26: 0 | Y26: 164231.12 | Z26: 55573.727 | AA26: 38901.609 | AB26: =SUM(W26:AA26) -> 681418.45 | AC26: =F26*AB26 -> 681418.45 | AD26: =R26*AB26 -> 681418.45
A27: =A26+1 -> 15 | B27: QUẠT HÚT PHÒNG QUẠT CẤP | C27: Cái | D27: 1 | E27: 1 | F27: =E27 -> 1 | G27: TH1/EF-06 | H27: 650 | I27: 25 | J27: Fan wall mounted | K27: 55 | L27: 0.37 | M27: 220/1/50 | N27: ≤ 65 dBA | O27: ≥ 50 % | R27: 1 | S27: Quạt hút gắn tường TH1/EF-06, Q=650m3/h, 25Pa, CSĐ: 0.034kW, Điện áp 1P/220V/50Hz, Độ ồn 48 dBA (dBA @ 1m), Tốc độ vòng quay 4P, IP44, Nhựa PP | T27: VNS-AV6-25 | U27: TH VINASUN | V27: Việt Nam | W27: 422712 | X27: 0 | Y27: 164231.12 | Z27: 55573.727 | AA27: 38901.609 | AB27: =SUM(W27:AA27) -> 681418.45 | AC27: =F27*AB27 -> 681418.45 | AD27: =R27*AB27 -> 681418.45
A28: =A27+1 -> 16 | B28: QUẠT HÚT PHÒNG BƠM PCCC | C28: Cái | D28: 1 | E28: 1 | F28: =E28 -> 1 | G28: TH1/EF-07 | H28: 1000 | I28: 50 | J28: Fan wall mounted | K28: 55 | L28: 0.37 | M28: 220/1/50 | N28: ≤ 65 dBA | O28: ≥ 50 % | R28: 1 | S28: Quạt hút gắn tường TH1/EF-07, Q=1000m3/h, 50Pa, CSĐ: 0.034kW, Điện áp 1P/220V/50Hz, Độ ồn 48 dBA (dBA @ 1m), Tốc độ vòng quay 4P, IP44, Nhựa PP | T28: VNS-AV6-25 | U28: TH VINASUN | V28: Việt Nam | W28: 422712 | X28: 0 | Y28: 164231.12 | Z28: 55573.727 | AA28: 38901.609 | AB28: =SUM(W28:AA28) -> 681418.45 | AC28: =F28*AB28 -> 681418.45 | AD28: =R28*AB28 -> 681418.45
A29: =A28+1 -> 17 | B29: QUẠT HÚT PHÒNG HẠ THẾ | C29: Cái | D29: 1 | E29: 1 | F29: =E29 -> 1 | G29: TH1/EF-08 | H29: 3500 | I29: 50 | J29: Fan wall mounted | K29: 55 | L29: 0.55 | M29: 220/1/50 | N29: ≤ 65 dBA | O29: ≥ 50 % | R29: 1 | S29: Quạt hút hướng trục vuông TH1/EF-08, Q=3500m3/h, 50Pa, CSĐ: 0.16kW, Điện áp 1P/220V/50Hz, Độ ồn 65 dBA (dBA @ 1m), Tốc độ vòng quay 4P, IP54, Thép mạ kẽm | T29: VNS-AF9-4T | U29: TH VINASUN | V29: Việt Nam | W29: 4088070 | X29: 259848 | Y29: 390084.22 | Z29: 431420.73 | AA29: 301994.51 | AB29: =SUM(W29:AA29) -> 5471417.5 | AC29: =F29*AB29 -> 5471417.5 | AD29: =R29*AB29 -> 5471417.5
A30: =A29+1 -> 18 | B30: QUẠT HÚT PHÒNG KĨ THUẬT | C30: Cái | D30: 1 | E30: 1 | F30: =E30 -> 1 | G30: TH1/EF-09 | H30: 450 | I30: 25 | J30: Fan wall mounted | K30: 55 | L30: 0.37 | M30: 220/1/50 | N30: ≤ 65 dBA | O30: ≥ 50 % | R30: 1 | S30: Quạt hút gắn tường TH1/EF-09, Q=450m3/h, 25Pa, CSĐ: 0.031kW, Điện áp 1P/220V/50Hz, Độ ồn 47 dBA (dBA @ 1m), Tốc độ vòng quay 4P, IP44, Nhựa PP | T30: VNS-AV6-20 | U30: TH VINASUN | V30: Việt Nam | W30: 389340 | X30: 0 | Y30: 164231.12 | Z30: 52333.727 | AA30: 36633.609 | AB30: =SUM(W30:AA30) -> 642538.45 | AC30: =F30*AB30 -> 642538.45 | AD30: =R30*AB30 -> 642538.45
A31: =A30+1 -> 19 | B31: QUẠT HÚT NHÀ ĐIỀU HÀNH XLNT | C31: Cái | D31: 1 | E31: 1 | F31: =E31 -> 1 | G31: TH1/EF-10 | H31: 450 | I31: 25 | J31: Fan wall mounted | K31: 55 | L31: 0.37 | M31: 220/1/50 | N31: ≤ 65 dBA | O31: ≥ 50 % | R31: 1 | S31: Quạt hút gắn tường TH1/EF-10, Q=450m3/h, 25Pa, CSĐ: 0.031kW, Điện áp 1P/220V/50Hz, Độ ồn 47 dBA (dBA @ 1m), Tốc độ vòng quay 4P, IP44, Nhựa PP | T31: VNS-AV6-20 | U31: TH VINASUN | V31: Việt Nam | W31: 389340 | X31: 0 | Y31: 164231.12 | Z31: 52333.727 | AA31: 36633.609 | AB31: =SUM(W31:AA31) -> 642538.45 | AC31: =F31*AB31 -> 642538.45 | AD31: =R31*AB31 -> 642538.45
A32: =A31+1 -> 20 | B32: QUẠT HÚT PHÒNG BƠM SINH HOẠT | C32: Cái | D32: 1 | E32: 1 | F32: =E32 -> 1 | G32: TH1/EF-11 | H32: 1000 | I32: 50 | J32: Fan wall mounted | K32: 55 | L32: 3.7 | M32: 220/1/50 | N32: ≤ 65 dBA | O32: ≥ 50 % | R32: 1 | S32: Quạt hút gắn tường TH1/EF-11, Q=1000m3/h, 50Pa, CSĐ: 0.034kW, Điện áp 1P/220V/50Hz, Độ ồn 48 dBA (dBA @ 1m), Tốc độ vòng quay 4P, IP44, Nhựa PP | T32: VNS-AV6-25 | U32: TH VINASUN | V32: Việt Nam | W32: 422712 | X32: 0 | Y32: 164231.12 | Z32: 55573.727 | AA32: 38901.609 | AB32: =SUM(W32:AA32) -> 681418.45 | AC32: =F32*AB32 -> 681418.45 | AD32: =R32*AB32 -> 681418.45
A33: =A32+1 -> 21 | B33: QUẠT HÚT PHÒNG RÁC THÁP A | C33: Cái | D33: 1 | E33: 1 | F33: =E33 -> 1 | G33: TH1/EF-12 | H33: 6500 | I33: 400 | J33: Axial Fan/In-Line Fan/ Cabinet Fan | K33: 55 | L33: 3.7 | M33: 380/3/50 | N33: ≤ 65 dBA | O33: ≥ 50 % | R33: 1 | S33: Quạt hút ly tâm dạng hộp TH1/EF-12, Q=6500m3/h, 400Pa, CSĐ: 1.5W, Điện áp 3P/380V/50Hz, Độ ồn 65 dBA (dBA @ 3m), Tốc độ vòng quay 6P, IP55, Thép SS400 mạ kẽm | T33: VNS-VF-400S Động cơ ATT IE1 | U33: TH VINASUN | V33: Việt Nam | W33: 15462360 | X33: 259848 | Y33: 635069.25 | Z33: 1557400.8 | AA33: 1090180.6 | AB33: =SUM(W33:AA33) -> 19004859 | AC33: =F33*AB33 -> 19004859 | AD33: =R33*AB33 -> 19004859
A34: =A33+1 -> 22 | B34: QUẠT CẤP GIÓ TẦNG HẦM ZONE 1 | C34: Cái | D34: 2 | E34: 2 | F34: =E34 -> 2 | G34: TH1/SF-01.1,2 | H34: 20500 | I34: 400 | J34: Axial Fan/In-Line Fan/ Cabinet Fan | K34: 55 | L34: 11 | M34: 380/3/50 | N34: ≤ 65 dBA | O34: ≥ 50 % | R34: 2 | S34: Quạt cấp gió hướng trục TH1/SF-01.1,2, Q=20500m3/h, 400Pa, CSĐ: 7.5kW, Điện áp 3P/380V/50Hz, Độ ồn 61 dBA (dBA @ 3m), Tốc độ vòng quay 4P, IP55, Thép SS400 mạ kẽm nhúng nóng | T34: VNS-CF1S-7T Động cơ ATT IE1 | U34: TH VINASUN | V34: Việt Nam | W34: 31703400 | X34: 259848 | Y34: 1724120.1 | Z34: 3230577 | AA34: 2261403.9 | AB34: =SUM(W34:AA34) -> 39179349 | AC34: =F34*AB34 -> 78358698 | AD34: =R34*AB34 -> 78358698
