Workbook
Name \a: #N/A
Name \p: #N/A
Name \q: #N/A
Name \w: #N/A
Name _: #REF!
Name ________CON1: #REF!
Name ________CON2: #REF!
Name _______C: #N/A
Name _______NET2: #REF!
Name _______R: #N/A
Name ______C: #N/A
Name ______CON1: #REF!
Name ______CON2: #REF!
Name ______NET2: #REF!
Name ______R: #N/A
Name _____C: #N/A
Name _____CON1: #REF!
Name _____CON2: #REF!
Name _____NET2: #REF!
Name _____R: #N/A
Name ____C: #N/A
Name ____CON1: #REF!
Name ____CON2: #REF!
Name ____IDR100: #REF!
Name ____NET2: #REF!
Name ____R: #N/A
Name ___C: #N/A
Name ___CON1: #REF!
Name ___CON2: #REF!
Name ___IDR100: #REF!
Name ___NET2: #REF!
Name ___R: #N/A
Name ___SM6: #REF!
Name __AA1: #REF!
Name __add1: #REF!
Name __add2: #REF!
Name __add3: #REF!
Name __C: #N/A
Name __C100000: #REF!
Name __C19579: #REF!
Name __CON1: #REF!
Name __CON2: #REF!
Name __H66766: #REF!
Name __IDR100: #REF!
Name __LP1: #REF!
Name __LP2: #REF!
Name __NET2: #REF!
Name __R: #N/A
Name __SM6: #REF!
Name __SUM1: #REF!
Name __SUM10: #REF!
Name __SUM11: #REF!
Name __SUM12: #REF!
Name __SUM13: #REF!
Name __SUM14: #REF!
Name __SUM15: #REF!
Name __SUM16: #REF!
Name __SUM17: #REF!
Name __SUM18: #REF!
Name __SUM19: #REF!

Sheet Tổng hợp
E1: Mẫu số 03.1
A2: BẢNG CHÀO GIÁ TỔNG HỢP
A3: Dự án: TOÀ NHÀ HỖN HỢP HACOM MALL
A4: Gói thầu: CUNG CẤP VTTB VÀ THI CÔNG LẮP ĐẶT HỆ THỐNG CƠ ĐIỆN
A5: Địa điểm xây dựng: PHƯỜNG ĐÔNG HẢI, TỈNH KHÁNH HÒA
A7: Stt | B7: Mô tả công việc mời thầu | C7: Thành tiền | E7: Ghi chú
C8: Theo KLMT | D8: Nhà thầu chào
A9: A | B9: ĐẦU MỤC CÔNG VIỆC THEO KLMT | C9: =SUBTOTAL(9,C10:C14) -> 1.7569442e+11 | D9: =SUBTOTAL(9,D10:D14) -> 1.7240658e+11
A10: I | B10: HẠNG MỤC: ĐIỆN | C10: ='1. HT điện'!Q9 -> 8.3870083e+10 | D10: ='1. HT điện'!R9 -> 79743614085
A11: II | B11: HẠNG MỤC: ĐIỆN NHẸ | C11: ='2. HT điện nhẹ'!Q9 -> 3.0129423e+09 | D11: ='2. HT điện nhẹ'!R9 -> 2429901290
A12: III | B12: HẠNG MỤC: CẤP THOÁT NƯỚC | C12: ='3. HT CTN'!Q9 -> 3.6031654e+10 | D12: ='3. HT CTN'!R9 -> 36276380384
A13: IV | B13: HẠNG MỤC: HVAC | C13: ='4.1 ĐH VRV'!AF9+'4.2 Quạt'!AC9+'4.3 DHKK & TG'!Q9 -> 5.1250971e+10 | D13: ='4.1 ĐH VRV'!AG9+'4.2 Quạt'!AD9+'4.3 DHKK & TG'!R9 -> 5.242572e+10
A14: V | B14: HẠNG MỤC: NGĂN CHÁY LAN | C14: ='5. Ngăn cháy lan'!Q9 -> 1.528773e+09 | D14: ='5. Ngăn cháy lan'!R9 -> 1.5309678e+09
A15: B | B15: ĐẦU MỤC CÔNG VIỆC PHÁT SINH NGOÀI KLMT | C15: =SUBTOTAL(9,C16:C18) -> 0 | D15: =SUBTOTAL(9,D16:D18) -> 2056393860
A16: I | B16: HẠNG MỤC: ĐIỆN | C16: ='1. HT điện'!Q2682 -> 0 | D16: ='1. HT điện'!R2682 -> 441506970
A17: III | B17: HẠNG MỤC: CẤP THOÁT NƯỚC | C17: ='3. HT CTN'!Q814 -> 0 | D17: ='3. HT CTN'!R814 -> 905142910
A18: IV | B18: HẠNG MỤC: HVAC | C18: ='4.1 ĐH VRV'!AF49+'4.2 Quạt'!AC145+'4.3 DHKK & TG'!Q1110 -> 0 | D18: ='4.1 ĐH VRV'!AG49+'4.2 Quạt'!AD145+'4.3 DHKK & TG'!R1110 -> 709743980
A19: C | B19: TỔNG CỘNG GIÁ CHÀO TRƯỚC THUẾ: (C = A + B) | C19: =C15+C9 -> 1.7569442e+11 | D19: =D15+D9 -> 1.7446298e+11
B20: Thuế Vat | C20: =C19*8% -> 1.4055554e+10 | D20: =D19*8% -> 1.3957038e+10
A21: D | B21: TỔNG CỘNG GIÁ CHÀO SAU THUẾ | C21: =ROUND(C19+C20,-3) -> 189749978000 | D21: =ROUND(D19+D20,-3) -> 188420016000
A23: Bằng chữ: Một trăm tám mươi tám tỷ, bốn trăm hai mươi triệu, không trăm mười sáu ngàn đồng./
C24: ĐẠI DIỆN HỢP PHÁP CỦA NHÀ THẦU
C25: (Ghi tên, chức danh, ký tên và đóng dấu)
C26: THÀNH VIÊN ĐỨNG ĐẦU LIÊN DANH | D26: THÀNH VIÊN LIÊN DANH
C27: CÔNG TY TNHH VĂN LANG | D27: CÔNG TY TNHH XÂY DỰNG CƠ ĐIỆN TRÍ TRUNG

Sheet 1. HT điện
A1: Dự án: TOÀ NHÀ HỖN HỢP HACOM MALL
A2: Gói thầu: CUNG CẤP VTTB VÀ THI CÔNG LẮP ĐẶT HỆ THỐNG CƠ ĐIỆN
A3: Hạng mục: HỆ THỐNG ĐIỆN
A5: KHỐI LƯỢNG MỜI THẦU | F5: LIÊN DANH CÔNG TY TNHH VĂN LANG VÀ CÔNG TY TNHH XÂY DỰNG CƠ ĐIỆN TRÍ TRUNG
A6: STT | B6: Diễn giải | C6: Đơn vị | D6: KL Mời thầu Lần 2 | E6: Ghi chú | F6: KL Nhà thầu chào | G6: THÔNG TIN VỀ VẬT LIỆU CHÍNH | K6: ĐƠN GIÁ (chưa bao gồm VAT) | Q6: Thành tiền BOQ | S6: Ghi chú
G7: Mô tả/ Quy cách | H7: Mã hiệu | I7: Thương hiệu | J7: Xuất xứ | K7: VL chính | L7: VL phụ | M7: NC&M | N7: CF quản lý | O7: Lợi nhuận | P7: ĐG tổng hợp | Q7: Thành tiền KLMT | R7: Thành tiền Nhà thầu chào
A8: 1 | B8: 2 | C8: 3 | D8: 4 | E8: 5 | F8: 6 | G8: 7 | H8: 8 | I8: 9 | J8: 10 | K8: 11 | L8: 12 | M8: 13 | N8: 14 | O8: 15 | P8: 16=11+12+13+14+15 | Q8: 17=4*16 | R8: 18=6*16 | S8: 19
A9: A | B9: ĐẦU MỤC CÔNG VIỆC THEO KLMT | Q9: =SUBTOTAL(9,Q11:Q2682) -> 8.3870083e+10 | R9: =SUBTOTAL(9,R11:R2682) -> 79743614085
A10: I | B10: Tủ điện hạ thế
A11: =COUNT($A$10:$A10)+1 -> 1 | B11: Tủ điện LV-G.1+LV-G.2+LV-G.3+LV-G.4+LV-G.5+LV-G.6 | C11: Tủ | D11: 1 | F11: 1 | I11: ACIT / Bích Hạnh | J11: Việt Nam | K11: 1646024460 | L11: 8778300 | M11: 44892790 | N11: =ROUND((K11+L11+M11)*10%,-1) -> 169969560 | O11: =ROUND((K11+L11+M11+N11)*7%,-1) -> 130876560 | P11: =K11+L11+M11+N11+O11 -> 2000541670 | Q11: =P11*D11 -> 2000541670 | R11: =P11*F11 -> 2000541670
B12: Vỏ tủ form 3B | C12: Cái | D12: 1 | F12: 1
B13: Đầu vào:
B14: ACB Fixed 4P 3200AT 3200AF 65kA , bảo vệ quá dòng, chạm đất, quá áp, thấp áp, đo lường class 1, kết nối NFC/ Bluetooth. | C14: Cái | D14: 2 | F14: 2
B15: Motor sạc 220VAC cho ACB Fixed 4P 3200A 65kA | C15: Cái | D15: 2 | F15: 2
B16: Cuộn đóng 220VAC cho ACB Fixed 4P 3200A 65kA | C16: Cái | D16: 2 | F16: 2
B17: Cuộn cắt 220VAC cho ACB Fixed dòng MTZ | C17: Cái | D17: 2 | F17: 2
B18: Cuộn UVT 220VAC cho ACB Fixed dòng MTZ | C18: Cái | D18: 2 | F18: 2
B19: Khóa đóng cắt ACB | C19: Cái | D19: 2 | F19: 2
B20: Bộ hòa đồng bộ 2 máy phát | C20: Bộ | D20: 1 | F20: 1
B21: Đèn báo trạng thái On/OFF/TRIP ACB | C21: Cái | D21: 6 | F21: 6
B22: Biến dòng hạ thế 3200/5A | C22: Quả | D22: 12 | F22: 12
B23: Đồng hồ Volt 0-450VAC | C23: Cái | D23: 2 | F23: 2
B24: Chuyển mạch Volt 7 vị trí | C24: Cái | D24: 2 | F24: 2
B25: Đồng hồ Ampe 0-3200A | C25: Cái | D25: 6 | F25: 6
... B27: Cầu chi 2A | C27: Cái | D27: 18 | F27: 18
B28: Đầu ra:
B29: ACB Fixed 4P 3000AT 3200AF 65kA | C29: Cái | D29: 1 | F29: 1
B30: ="Motor sạc 220VAC cho " &B29 -> Motor sạc 220VAC cho ACB Fixed 4P 3000AT 3200AF 65kA | C30: Cái | D30: 1 | F30: 1
B31: ="Cuộn đóng 220VAC cho " &B29 -> Cuộn đóng 220VAC cho ACB Fixed 4P 3000AT 3200AF 65kA | C31: Cái | D31: 1 | F31: 1
B32: Cuộn cắt 220VAC cho ACB Fixed dòng MTZ | C32: Cái | D32: 1 | F32: 1
B33: ACB 4P 1600AT 1600AF 65kA Fixed | C33: Cái | D33: 1 | F33: 1
B34: ="Motor sạc 220VAC cho " &B33 -> Motor sạc 220VAC cho ACB 4P 1600AT 1600AF 65kA Fixed | C34: Cái | D34: 1 | F34: 1
B35: ="Cuộn đóng 220VAC cho " &B33 -> Cuộn đóng 220VAC cho ACB 4P 1600AT 1600AF 65kA Fixed | C35: Cái | D35: 1 | F35: 1
B36: ="Cuộn cắt 220VAC cho " &B33 -> Cuộn cắt 220VAC cho ACB 4P 1600AT 1600AF 65kA Fixed | C36: Cái | D36: 2 | F36: 2
B37: Đèn báo trạng thái On/OFF/TRIP ACB | C37: Cái | D37: 6 | F37: 6
B38: Khóa đóng cắt ACB | C38: Cái | D38: 2 | F38: 2
B39: MCCB 4P 1250AT 1250AF 50kA | C39: Cái | D39: 1 | F39: 1
B40: ="Tiếp điểm báo trạng thái cho " &B39 -> Tiếp điểm báo trạng thái cho MCCB 4P 1250AT 1250AF 50kA | C40: Cái | D40: 2 | F40: 2
B41: MCCB 4P 1000AT 1000AF 50kA | C41: Cái | D41: 1 | F41: 1
B42: ="Tiếp điểm báo trạng thái cho " &B41 -> Tiếp điểm báo trạng thái cho MCCB 4P 1000AT 1000AF 50kA | C42: Cái | D42: 2 | F42: 2
...

Sheet 2. HT điện nhẹ
A1: Dự án: TOÀ NHÀ HỖN HỢP HACOM MALL
A2: Gói thầu: CUNG CẤP VTTB VÀ THI CÔNG LẮP ĐẶT HỆ THỐNG CƠ ĐIỆN
A3: Hạng mục: HỆ THỐNG ĐIỆN NHẸ
A5: KHỐI LƯỢNG MỜI THẦU | F5: LIÊN DANH CÔNG TY TNHH VĂN LANG VÀ CÔNG TY TNHH XÂY DỰNG CƠ ĐIỆN TRÍ TRUNG
A6: Stt | B6: Diễn giải | C6: Đơn vị | D6: KL Mời thầu Lần 2 | E6: Ghi chú | F6: KL Nhà thầu chào | G6: THÔNG TIN VỀ VẬT LIỆU CHÍNH | K6: ĐƠN GIÁ (chưa bao gồm VAT) | Q6: Thành tiền BOQ | S6: Ghi chú
G7: Mô tả/ Quy cách | H7: Mã hiệu | I7: Thương hiệu | J7: Xuất xứ | K7: VL chính | L7: VL phụ | M7: NC&M | N7: CF quản lý | O7: Lợi nhuận | P7: ĐG tổng hợp | Q7: Thành tiền KLMT | R7: Thành tiền Nhà thầu chào
A8: 1 | B8: 2 | C8: 3 | D8: 4 | E8: 5 | F8: 6 | G8: 7 | H8: 8 | I8: 9 | J8: 10 | K8: 11 | L8: 12 | M8: 13 | N8: 14 | O8: 15 | P8: 16=11+12+13+14+15 | Q8: 17=4*16 | R8: 18=6*16 | S8: 19
A9: A | B9: ĐẦU MỤC CÔNG VIỆC THEO KLMT | Q9: =SUBTOTAL(9,Q10:Q50) -> 3.0129423e+09 | R9: =SUBTOTAL(9,R10:R50) -> 2429901290
A10: I | B10: Vật tư thiết bị đầu tư cho BQL tòa nhà
A11: 1 | B11: Ổ cắm mạng đơn 1xRJ45, bao gồm mặt và hạt | C11: Cái | D11: 10 | E11: NT chỉ cung cấp và lắp đặt đế âm | F11: 10 | I11: Sam Phú / AC | J11: Việt Nam | K11: 10400 | L11: 200 | M11: 26940 | N11: =ROUND((K11+L11+M11)*10%,-1) -> 3750 | O11: =ROUND((K11+L11+M11+N11)*7%,-1) -> 2890 | P11: =K11+L11+M11+N11+O11 -> 44180 | Q11: =P11*D11 -> 441800 | R11: =P11*F11 -> 441800
A12: 2 | B12: Ống PVC D20 | C12: m | D12: 100 | F12: 100 | G12: 750N | I12: Sam Phú / AC | J12: Việt Nam | K12: 6290 | L12: 190 | M12: 68590 | N12: =ROUND((K12+L12+M12)*10%,-1) -> 7510 | O12: =ROUND((K12+L12+M12+N12)*7%,-1) -> 5780 | P12: =K12+L12+M12+N12+O12 -> 88360 | Q12: =P12*D12 -> 8836000 | R12: =P12*F12 -> 8836000
A13: II | B13: PHẦN VẬT TƯ THIẾT BỊ ĐẦU TƯ CHO CĂN HỘ
A14: 1 | B14: Ổ cắm mạng đơn 1xRJ45, bao gồm cả mặt và hạt | C14: Cái | D14: 1109 | E14: NT chỉ cung cấp và lắp đặt đế âm | F14: 1109 | I14: Sam Phú / AC | J14: Việt Nam | K14: 10400 | L14: 200 | M14: 26940 | N14: =ROUND((K14+L14+M14)*10%,-1) -> 3750 | O14: =ROUND((K14+L14+M14+N14)*7%,-1) -> 2890 | P14: =K14+L14+M14+N14+O14 -> 44180 | Q14: =P14*D14 -> 48995620 | R14: =P14*F14 -> 48995620
A15: 2 | B15: Ổ cắm truyền hình, bao gồm mặt cả hạt | C15: Cái | D15: 1109 | E15: NT chỉ cung cấp và lắp đặt đế âm | F15: 1109 | I15: Sam Phú / AC | J15: Việt Nam | K15: 10400 | L15: 200 | M15: 26940 | N15: =ROUND((K15+L15+M15)*10%,-1) -> 3750 | O15: =ROUND((K15+L15+M15+N15)*7%,-1) -> 2890 | P15: =K15+L15+M15+N15+O15 -> 44180 | Q15: =P15*D15 -> 48995620 | R15: =P15*F15 -> 48995620
A16: 3 | B16: Ống PVC D20 | C16: m | D16: 15826 | F16: 10236 | G16: 750N | I16: Sam Phú / AC | J16: Việt Nam | K16: 6290 | L16: 190 | M16: 68590 | N16: =ROUND((K16+L16+M16)*10%,-1) -> 7510 | O16: =ROUND((K16+L16+M16+N16)*7%,-1) -> 5780 | P16: =K16+L16+M16+N16+O16 -> 88360 | Q16: =P16*D16 -> 1398385360 | R16: =P16*F16 -> 904452960
A17: 4 | B17: Vật tư phụ hoàn thiện toàn bộ hệ thống | C17: Lô | D17: 1 | F17: 1 | J17: Việt Nam | K17: 4534320 | L17: 0 | M17: 1482230 | N17: =ROUND((K17+L17+M17)*10%,-1) -> 601660 | O17: =ROUND((K17+L17+M17+N17)*7%,-1) -> 463270 | P17: =K17+L17+M17+N17+O17 -> 7081480 | Q17: =P17*D17 -> 7081480 | R17: =P17*F17 -> 7081480
A18: III | B18: Thang máng cáp
A19: 1 | B19: Thang cáp kim loại WxH-500x100mm | C19: m | D19: 209.3 | F19: 218 | G19: Lớp phủ Sơn tĩnh điện | I19: ACIT / Bích Hạnh | J19: Việt Nam | K19: 261120 | L19: 7830 | M19: 144020 | N19: =ROUND((K19+L19+M19)*10%,-1) -> 41300 | O19: =ROUND((K19+L19+M19+N19)*7%,-1) -> 31800 | P19: =K19+L19+M19+N19+O19 -> 486070 | Q19: =P19*D19 -> 101734451 | R19: =P19*F19 -> 105963260
B20: Tê nối thang cáp WxH=(500x100)mm | C20: Cái | D20: 2 | F20: 2 | G20: Lớp phủ Sơn tĩnh điện | I20: ACIT / Bích Hạnh | J20: Việt Nam | K20: 794580 | L20: 23840 | M20: 309580 | N20: =ROUND((K20+L20+M20)*10%,-1) -> 112800 | O20: =ROUND((K20+L20+M20+N20)*7%,-1) -> 86860 | P20: =K20+L20+M20+N20+O20 -> 1327660 | Q20: =P20*D20 -> 2655320 | R20: =P20*F20 -> 2655320
B21: Chuyển hướng ngang 90 độ thang cáp WxH=(500x100)mm | C21: Cái | D21: 8 | F21: 8 | G21: Lớp phủ Sơn tĩnh điện | I21: ACIT / Bích Hạnh | J21: Việt Nam | K21: 564060 | L21: 16920 | M21: 309580 | N21: =ROUND((K21+L21+M21)*10%,-1) -> 89060 | O21: =ROUND((K21+L21+M21+N21)*7%,-1) -> 68570 | P21: =K21+L21+M21+N21+O21 -> 1048190 | Q21: =P21*D21 -> 8385520 | R21: =P21*F21 -> 8385520
B22: Chuyển hướng dọc 90 độ thang cáp WxH=(500x100)mm | C22: Cái | D22: 4 | F22: 4 | G22: Lớp phủ Sơn tĩnh điện | I22: ACIT / Bích Hạnh | J22: Việt Nam | K22: 564060 | L22: 16920 | M22: 309580 | N22: =ROUND((K22+L22+M22)*10%,-1) -> 89060 | O22: =ROUND((K22+L22+M22+N22)*7%,-1) -> 68570 | P22: =K22+L22+M22+N22+O22 -> 1048190 | Q22: =P22*D22 -> 4192760 | R22: =P22*F22 -> 4192760
A23: 2 | B23: Thang cáp kim loại WxH-400x100mm | C23: m | D23: 48.8 | F23: 49 | G23: Lớp phủ Sơn tĩnh điện | I23: ACIT / Bích Hạnh | J23: Việt Nam | K23: 247860 | L23: 7440 | M23: 124740 | N23: =ROUND((K23+L23+M23)*10%,-1) -> 38000 | O23: =ROUND((K23+L23+M23+N23)*7%,-1) -> 29260 | P23: =K23+L23+M23+N23+O23 -> 447300 | Q23: =P23*D23 -> 21828240 | R23: =P23*F23 -> 21917700
B24: Tê nối máng cáp WxH=(400x100)mm | C24: Cái | D24: 0 | F24: 0 | G24: Lớp phủ Sơn tĩnh điện | I24: ACIT / Bích Hạnh | J24: Việt Nam | K24: 794580 | L24: 19850 | M24: 153600 | N24: =ROUND((K24+L24+M24)*10%,-1) -> 96800 | O24: =ROUND((K24+L24+M24+N24)*7%,-1) -> 74540 | P24: =K24+L24+M24+N24+O24 -> 1139370 | Q24: =P24*D24 -> 0 | R24: =P24*F24 -> 0
B25: Chuyển hướng ngang 90 độ máng cáp WxH=(400x100)mm | C25: Cái | D25: 0 | F25: 0 | G25: Lớp phủ Sơn tĩnh điện | I25: ACIT / Bích Hạnh | J25: Việt Nam | K25: 564060 | L25: 16140 | M25: 153600 | N25: =ROUND((K25+L25+M25)*10%,-1) -> 73380 | O25: =ROUND((K25+L25+M25+N25)*7%,-1) -> 56500 | P25: =K25+L25+M25+N25+O25 -> 863680 | Q25: =P25*D25 -> 0 | R25: =P25*F25 -> 0
B26: Chữ thập nối thang cáp WxH=(400x100)mm | C26: Cái | D26: 1 | F26: 1 | G26: Lớp phủ Sơn tĩnh điện | I26: ACIT / Bích Hạnh | J26: Việt Nam | K26: 705840 | L26: 21180 | M26: 146290 | N26: =ROUND((K26+L26+M26)*10%,-1) -> 87330 | O26: =ROUND((K26+L26+M26+N26)*7%,-1) -> 67240 | P26: =K26+L26+M26+N26+O26 -> 1027880 | Q26: =P26*D26 -> 1027880 | R26: =P26*F26 -> 1027880
B27: Chuyển hướng ngang 90 độ thang cáp WxH=(400x100)mm | C27: Cái | D27: 5 | F27: 5 | G27: Lớp phủ Sơn tĩnh điện | I27: ACIT / Bích Hạnh | J27: Việt Nam | K27: 496740 | L27: 14900 | M27: 146290 | N27: =ROUND((K27+L27+M27)*10%,-1) -> 65790 | O27: =ROUND((K27+L27+M27+N27)*7%,-1) -> 50660 | P27: =K27+L27+M27+N27+O27 -> 774380 | Q27: =P27*D27 -> 3871900 | R27: =P27*F27 -> 3871900
B28: Chuyển hướng dọc 90 độ thang cáp WxH=(400x100)mm | C28: Cái | D28: 1 | F28: 1 | G28: Lớp phủ Sơn tĩnh điện | I28: ACIT / Bích Hạnh | J28: Việt Nam | K28: 496740 | L28: 14900 | M28: 146290 | N28: =ROUND((K28+L28+M28)*10%,-1) -> 65790 | O28: =ROUND((K28+L28+M28+N28)*7%,-1) -> 50660 | P28: =K28+L28+M28+N28+O28 -> 774380 | Q28: =P28*D28 -> 774380 | R28: =P28*F28 -> 774380
A29: 3 | B29: Máng cáp kim loại WxH-200x100mm | C29: m | D29: 0 | F29: 145 | G29: Lớp phủ Sơn tĩnh điện | I29: ACIT / Bích Hạnh | J29: Việt Nam | K29: 284580 | L29: 8540 | M29: 74840 | N29: =ROUND((K29+L29+M29)*10%,-1) -> 36800 | O29: =ROUND((K29+L29+M29+N29)*7%,-1) -> 28330 | P29: =K29+L29+M29+N29+O29 -> 433090 | Q29: =P29*D29 -> 0 | R29: =P29*F29 -> 62798050
B30: Chuyển hướng ngang 90 độ máng cáp WxH=(200x100)mm | C30: Cái | D30: 0 | F30: 0 | G30: Lớp phủ Sơn tĩnh điện | I30: ACIT / Bích Hạnh | J30: Việt Nam | K30: 214200 | L30: 6430 | M30: 92990 | N30: =ROUND((K30+L30+M30)*10%,-1) -> 31360 | O30: =ROUND((K30+L30+M30+N30)*7%,-1) -> 24150 | P30: =K30+L30+M30+N30+O30 -> 369130 | Q30: =P30*D30 -> 0 | R30: =P30*F30 -> 0
B31: Tê nối máng cáp WxH=(200x100)mm | C31: Cái | D31: 0 | F31: 0 | G31: Lớp phủ Sơn tĩnh điện | I31: ACIT / Bích Hạnh | J31: Việt Nam | K31: 281520 | L31: 8450 | M31: 92990 | N31: =ROUND((K31+L31+M31)*10%,-1) -> 38300 | O31: =ROUND((K31+L31+M31+N31)*7%,-1) -> 29490 | P31: =K31+L31+M31+N31+O31 -> 450750 | Q31: =P31*D31 -> 0 | R31: =P31*F31 -> 0
A32: 4 | B32: Máng cáp kim loại WxH-200x50mm | C32: m | D32: 871.99 | F32: 618 | G32: Lớp phủ Sơn tĩnh điện | I32: ACIT / Bích Hạnh | J32: Việt Nam | K32: 237660 | L32: 7130 | M32: 74840 | N32: =ROUND((K32+L32+M32)*10%,-1) -> 31960 | O32: =ROUND((K32+L32+M32+N32)*7%,-1) -> 24610 | P32: =K32+L32+M32+N32+O32 -> 376200 | Q32: =P32*D32 -> 3.2804264e+08 | R32: =P32*F32 -> 232491600
B33: Chuyển hướng ngang 90 độ máng cáp WxH=(200x50)mm | C33: Cái | D33: 40 | F33: 40 | G33: Lớp phủ Sơn tĩnh điện | I33: ACIT / Bích Hạnh | J33: Việt Nam | K33: 180540 | L33: 5420 | M33: 92990 | N33: =ROUND((K33+L33+M33)*10%,-1) -> 27900 | O33: =ROUND((K33+L33+M33+N33)*7%,-1) -> 21480 | P33: =K33+L33+M33+N33+O33 -> 328330 | Q33: =P33*D33 -> 13133200 | R33: =P33*F33 -> 13133200
B34: Chuyển hướng dọc 90 độ máng cáp WxH=(200x50)mm | C34: Cái | D34: 5 | F34: 5 | G34: Lớp phủ Sơn tĩnh điện | I34: ACIT / Bích Hạnh | J34: Việt Nam | K34: 285600 | L34: 8570 | M34: 92990 | N34: =ROUND((K34+L34+M34)*10%,-1) -> 38720 | O34: =ROUND((K34+L34+M34+N34)*7%,-1) -> 29810 | P34: =K34+L34+M34+N34+O34 -> 455690 | Q34: =P34*D34 -> 2278450 | R34: =P34*F34 -> 2278450
B35: Tê nối máng cáp WxH=(200x50)mm | C35: Cái | D35: 26 | F35: 26 | G35: Lớp phủ Sơn tĩnh điện | I35: ACIT / Bích Hạnh | J35: Việt Nam | K35: 250920 | L35: 7530 | M35: 92990 | N35: =ROUND((K35+L35+M35)*10%,-1) -> 35140 | O35: =ROUND((K35+L35+M35+N35)*7%,-1) -> 27060 | P35: =K35+L35+M35+N35+O35 -> 413640 | Q35: =P35*D35 -> 10754640 | R35: =P35*F35 -> 10754640
A36: 5 | B36: Máng cáp kim loại WxH-150x50mm | C36: m | D36: 1724.49 | F36: 1731 | G36: Lớp phủ Sơn tĩnh điện | I36: ACIT / Bích Hạnh | J36: Việt Nam | K36: 193800 | L36: 5810 | M36: 74840 | N36: =ROUND((K36+L36+M36)*10%,-1) -> 27450 | O36: =ROUND((K36+L36+M36+N36)*7%,-1) -> 21130 | P36: =K36+L36+M36+N36+O36 -> 323030 | Q36: =P36*D36 -> 5.57062e+08 | R36: =P36*F36 -> 559164930
B37: Tê nối máng cáp WxH=(150x50)mm | C37: Cái | D37: 20 | F37: 20 | G37: Lớp phủ Sơn tĩnh điện | I37: ACIT / Bích Hạnh | J37: Việt Nam | K37: 207060 | L37: 6210 | M37: 92990 | N37: =ROUND((K37+L37+M37)*10%,-1) -> 30630 | O37: =ROUND((K37+L37+M37+N37)*7%,-1) -> 23580 | P37: =K37+L37+M37+N37+O37 -> 360470 | Q37: =P37*D37 -> 7209400 | R37: =P37*F37 -> 7209400
B38: Chuyển hướng ngang 90 độ máng cáp WxH=(150x50)mm | C38: Cái | D38: 89 | F38: 89 | G38: Lớp phủ Sơn tĩnh điện | I38: ACIT / Bích Hạnh | J38: Việt Nam | K38: 144840 | L38: 4350 | M38: 92990 | N38: =ROUND((K38+L38+M38)*10%,-1) -> 24220 | O38: =ROUND((K38+L38+M38+N38)*7%,-1) -> 18650 | P38: =K38+L38+M38+N38+O38 -> 285050 | Q38: =P38*D38 -> 25369450 | R38: =P38*F38 -> 25369450
B39: Chuyển hướng dọc 90 độ máng cáp WxH=(150x50)mm | C39: Cái | D39: 19 | F39: 19 | G39: Lớp phủ Sơn tĩnh điện | I39: ACIT / Bích Hạnh | J39: Việt Nam | K39: 144840 | L39: 4350 | M39: 92990 | N39: =ROUND((K39+L39+M39)*10%,-1) -> 24220 | O39: =ROUND((K39+L39+M39+N39)*7%,-1) -> 18650 | P39: =K39+L39+M39+N39+O39 -> 285050 | Q39: =P39*D39 -> 5415950 | R39: =P39*F39 -> 5415950
B40: Thang cáp WxH=(400x50)mm | C40: m | D40: 66 | F40: 66 | G40: Lớp phủ Sơn tĩnh điện | I40: ACIT / Bích Hạnh | J40: Việt Nam | K40: 277440 | L40: 8320 | M40: 124740 | N40: =ROUND((K40+L40+M40)*10%,-1) -> 41050 | O40: =ROUND((K40+L40+M40+N40)*7%,-1) -> 31610 | P40: =K40+L40+M40+N40+O40 -> 483160 | Q40: =P40*D40 -> 31888560 | R40: =P40*F40 -> 31888560
B41: Chuyển hướng ngang 90 độ thang cáp WxH=(400x50)mm | C41: Cái | D41: 4 | F41: 4 | G41: Lớp phủ Sơn tĩnh điện | I41: ACIT / Bích Hạnh | J41: Việt Nam | K41: 437580 | L41: 13130 | M41: 146290 | N41: =ROUND((K41+L41+M41)*10%,-1) -> 59700 | O41: =ROUND((K41+L41+M41+N41)*7%,-1) -> 45970 | P41: =K41+L41+M41+N41+O41 -> 702670 | Q41: =P41*D41 -> 2810680 | R41: =P41*F41 -> 2810680
...

Sheet 3. HT CTN
A1: Dự án: TOÀ NHÀ HỖN HỢP HACOM MALL
A2: Gói thầu: CUNG CẤP VTTB VÀ THI CÔNG LẮP ĐẶT HỆ THỐNG CƠ ĐIỆN
A3: Hạng mục: HỆ THỐNG CẤP THOÁT NƯỚC
A5: KHỐI LƯỢNG MỜI THẦU | F5: LIÊN DANH CÔNG TY TNHH VĂN LANG VÀ CÔNG TY TNHH XÂY DỰNG CƠ ĐIỆN TRÍ TRUNG
A6: STT | B6: Diễn giải | C6: Đơn vị | D6: KL Mời thầu Lần 2 | E6: Ghi chú | F6: KL Nhà thầu chào | G6: THÔNG TIN VỀ VẬT LIỆU CHÍNH | K6: ĐƠN GIÁ (chưa bao gồm VAT) | Q6: Thành tiền BOQ | S6: Ghi chú
G7: Mô tả/ Quy cách | H7: Mã hiệu | I7: Thương hiệu | J7: Xuất xứ | K7: VL chính | L7: VL phụ | M7: NC&M | N7: CF quản lý | O7: Lợi nhuận | P7: ĐG tổng hợp | Q7: Thành tiền KLMT | R7: Thành tiền Nhà thầu chào
A8: 1 | B8: 2 | C8: 3 | D8: 4 | E8: 5 | F8: 6 | G8: 7 | H8: 8 | I8: 9 | J8: 10 | K8: 11 | L8: 12 | M8: 13 | N8: 14 | O8: 15 | P8: 16=11+12+13+14+15 | Q8: 17=4*16 | R8: 18=6*16 | S8: 19
A9: A | B9: ĐẦU MỤC CÔNG VIỆC THEO KLMT | Q9: =SUBTOTAL(9,Q11:Q814) -> 3.6031654e+10 | R9: =SUBTOTAL(9,R11:R814) -> 36276380384
A10: I | B10: Phần thiết bị + phụ kiện chính
A11: 1 | B11: Bơm thoát nước sàn hầm ( thông số 1 bơm Q=12m3/h. H=15m, N=2,5KW), ( bao gồm phụ kiện : khớp nối nhanh, xích kéo, thanh dẫn hướng…) | C11: Cụm | D11: 3 | E11: Bơm thả chìm, nguyên cụm (bao gồm 02 bơm) | F11: 3 | G11: Bơm chìm Q=12m3/h. H=15m, N=1,5KW Thân Bơm: Gang Cánh Bơm: Gang Trục bơm: Thép không rỉ | H11: Model : FAG 50C 20.30/15 | I11: Willo | J11: China | K11: 54933120 | L11: 1647990 | M11: 7371000 | N11: =ROUND((K11+L11+M11)*10%,-1) -> 6395210 | O11: =ROUND((K11+L11+M11+N11)*7%,-1) -> 4924310 | P11: =K11+L11+M11+N11+O11 -> 75271630 | Q11: =P11*D11 -> 225814890 | R11: =P11*F11 -> 225814890
A12: 2 | B12: Bơm hố pít thang máy ( thông số 1 bơm Q=10m3/h. H=15m, N=1,5KW), ( bao gồm phụ kiện : khớp nối nhanh, xích kéo, thanh dẫn hướng…) | C12: Cụm | D12: 2 | E12: Bơm thả chìm, nguyên cụm (bao gồm 02 bơm) | F12: 2 | G12: Bơm chìm Q=10m3/h. H=15m, N=1,5KW Thân Bơm: Gang Cánh Bơm: Gang Trục bơm: Thép không rỉ | H12: Model : FAG 50C 20.30/15 | I12: Willo | J12: China | K12: 54933120 | L12: 1647990 | M12: 7371000 | N12: =ROUND((K12+L12+M12)*10%,-1) -> 6395210 | O12: =ROUND((K12+L12+M12+N12)*7%,-1) -> 4924310 | P12: =K12+L12+M12+N12+O12 -> 75271630 | Q12: =P12*D12 -> 150543260 | R12: =P12*F12 -> 150543260
A13: 3 | B13: Bơm bể bơm trung chuyển ( thông số bơm Q=6m3/h. H=6m), ( bao gồm phụ kiện : khớp nối nhanh, xích kéo, thanh dẫn hướng…) | C13: Cụm | D13: 2 | E13: Bơm thả chìm, nguyên cụm (bao gồm 02 bơm) | F13: 2 | G13: Bơm chìm Q=6m3/h. H=6m, N=0.45KW Thân Bơm: Gang Cánh Bơm: Gang Trục bơm: Thép không rỉ | H13: Model : FAG 50Z 11.14/4.5 | I13: Willo | J13: China | K13: 37662480 | L13: 1129870 | M13: 7371000 | N13: =ROUND((K13+L13+M13)*10%,-1) -> 4616340 | O13: =ROUND((K13+L13+M13+N13)*7%,-1) -> 3554580 | P13: =K13+L13+M13+N13+O13 -> 54334270 | Q13: =P13*D13 -> 108668540 | R13: =P13*F13 -> 108668540
A14: 4 | B14: Bơm cấp nước lên mái khối A ( thông số 1 bơm Q=40m3/h. H=130m, N=22KW), ( bao gồm phụ kiện ) | C14: Cụm | D14: 1 | E14: Bơm trục đứng, đa tầng cánh, nguyên cụm (bao gồm 02 bơm) | F14: 1 | G14: Ly tâm, trục đứng, đa tầng cánh Q=40m3/h. H=130m, N=22KW Thân Bơm: Gang Cánh Bơm: Gang Trục bơm: Thép không rỉ | H14: Model : Helix FIRST V 3608-5/25/E/KS/400-50 | I14: Willo | J14: China | K14: 291312000 | L14: 2913120 | M14: 7822330 | N14: =ROUND((K14+L14+M14)*10%,-1) -> 30204750 | O14: =ROUND((K14+L14+M14+N14)*7%,-1) -> 23257650 | P14: =K14+L14+M14+N14+O14 -> 355509850 | Q14: =P14*D14 -> 355509850 | R14: =P14*F14 -> 355509850
A15: 5 | B15: Bơm cấp nước lên mái khối B ( thông số 1 bơm Q=40m3/h. H=120m, N=22KW), ( bao gồm phụ kiện ) | C15: Cụm | D15: 1 | E15: Bơm trục đứng, đa tầng cánh, nguyên cụm (bao gồm 02 bơm) | F15: 1 | G15: Ly tâm, trục đứng, đa tầng cánh Q=40m3/h. H=120m, N=22KW Thân Bơm: Gang Cánh Bơm: Gang Trục bơm: Thép không rỉ | H15: Model : Helix FIRST V 3607-5/25/E/KS/400-50 | I15: Willo | J15: China | K15: 272584800 | L15: 2725850 | M15: 7822330 | N15: =ROUND((K15+L15+M15)*10%,-1) -> 28313300 | O15: =ROUND((K15+L15+M15+N15)*7%,-1) -> 21801240 | P15: =K15+L15+M15+N15+O15 -> 333247520 | Q15: =P15*D15 -> 333247520 | R15: =P15*F15 -> 333247520
A16: 6 | B16: Bơm biến tần tăng áp khối đế (thông số 1 bơm Q=40m3/h. H=56m,N=11KW), ( bao gồm phụ kiện ) | C16: Cụm | D16: 1 | E16: Bơm trục đứng, đa tầng cánh, nguyên cụm (bao gồm 02 bơm) | F16: 1 | G16: Nguyên bộ nhập khẩu Bao gồm: Máy bơm Ly tâm trục đứng đa tầng cánh , tủ điều khiển, hệ cơ khí và phụ kiện liên quan Q=2*40m3/h. H=56m, N=2*11KW Thân Bơm: Thép không rỉ Cánh Bơm: Thép không rỉ Trục bơm: Thép không rỉ | H16: Model : SIBOOST-B-2-HELIX V3604/2-VRS-N | I16: Willo | J16: China | K16: 338130000 | L16: 3381300 | M16: 5554330 | N16: =ROUND((K16+L16+M16)*10%,-1) -> 34706560 | O16: =ROUND((K16+L16+M16+N16)*7%,-1) -> 26724050 | P16: =K16+L16+M16+N16+O16 -> 408496240 | Q16: =P16*D16 -> 408496240 | R16: =P16*F16 -> 408496240
A17: 7 | B17: Bơm biến tần tăng áp mái khối A (thông số 1 bơm Q=27m3/h. H=25m,N=3.7KW), ( bao gồm phụ kiện ) | C17: Cụm | D17: 1 | E17: Bơm trục đứng, đa tầng cánh, nguyên cụm (bao gồm 02 bơm) | F17: 1 | G17: Nguyên bộ nhập khẩu Bao gồm: Máy bơm Ly tâm trục đứng đa tầng cánh, tủ điều khiển, hệ cơ khí và phụ kiện liên quan Q=2*27m3/h. H=56m, N=2*4KW Thân Bơm: Thép không rỉ Cánh Bơm: Thép không rỉ Trục bơm: Thép không rỉ | H17: Model : SIBOOST-B-2-HELIX V2203-VRS-N | I17: Willo | J17: China | K17: 280908000 | L17: 2809080 | M17: 5554330 | N17: =ROUND((K17+L17+M17)*10%,-1) -> 28927140 | O17: =ROUND((K17+L17+M17+N17)*7%,-1) -> 22273900 | P17: =K17+L17+M17+N17+O17 -> 340472450 | Q17: =P17*D17 -> 340472450 | R17: =P17*F17 -> 340472450
A18: 8 | B18: Bơm biến tần tăng áp mái khối B (thông số 1 bơm Q=30m3/h. H=25m,N=3.7KW), ( bao gồm phụ kiện ) | C18: Cụm | D18: 1 | E18: Bơm trục đứng, đa tầng cánh, nguyên cụm (bao gồm 02 bơm) | F18: 1 | G18: Nguyên bộ nhập khẩu Bao gồm: Máy bơm Ly tâm trục đứng đa tầng cánh, tủ điều khiển, hệ cơ khí và phụ kiện liên quan Q=2*30m3/h. H=56m, N=2*4KW Thân Bơm: Thép không rỉ Cánh Bơm: Thép không rỉ Trục bơm: Thép không rỉ | H18: Model : SIBOOST-B-2-HELIX V2203-VRS-N | I18: Willo | J18: China | K18: 280908000 | L18: 2809080 | M18: 5554330 | N18: =ROUND((K18+L18+M18)*10%,-1) -> 28927140 | O18: =ROUND((K18+L18+M18+N18)*7%,-1) -> 22273900 | P18: =K18+L18+M18+N18+O18 -> 340472450 | Q18: =P18*D18 -> 340472450 | R18: =P18*F18 -> 340472450
A19: 9 | B19: Bình tích áp 500L (bao gồm đồng hồ đo áp, công tắc áp lực liên động bơm tăng áp), ( bao gồm phụ kiện) | C19: Cụm | D19: 3 | F19: 3 | G19: Bình tích áp: 500l-10bar | H19: Model: US500461CS000000 | I19: Varem | J19: Ý | K19: 22176840 | L19: 510000 | M19: 1190700 | N19: =ROUND((K19+L19+M19)*10%,-1) -> 2387750 | O19: =ROUND((K19+L19+M19+N19)*7%,-1) -> 1838570 | P19: =K19+L19+M19+N19+O19 -> 28103860 | Q19: =P19*D19 -> 84311580 | R19: =P19*F19 -> 84311580
A20: 10 | B20: Cụm đồng hồ nước DN100 (gồm 01 đồng hồ, 02 van bướm, 01 mối nối mềm) | C20: Cụm | D20: 1 | F20: 1 | G20: Đồng hồ nước DN100 PN16 Van bướm DN100 PN16 Khớp nối mềm DN100 PN16 | H20: WTM - 100+KVS - 300+KVS 505 - F | I20: KVS | J20: Asia | K20: 12392540 | L20: 123930 | M20: 1673780 | N20: =ROUND((K20+L20+M20)*10%,-1) -> 1419030 | O20: =ROUND((K20+L20+M20+N20)*7%,-1) -> 1092650 | P20: =K20+L20+M20+N20+O20 -> 16701930 | Q20: =P20*D20 -> 16701930 | R20: =P20*F20 -> 16701930
A21: 11 | B21: Cụm đồng hồ nước DN80 (gồm 01 đồng hồ, 02 van khóa, kèm phụ kiện) | C21: Cụm | D21: 1 | F21: 1 | G21: Áp Lực 16 Bar, Bích PN16 | H21: WTM - 100 +KVS - 400 A | I21: KVS | J21: Asia | K21: 12402180 | L21: 248040 | M21: 1644300 | N21: =ROUND((K21+L21+M21)*10%,-1) -> 1429450 | O21: =ROUND((K21+L21+M21+N21)*7%,-1) -> 1100680 | P21: =K21+L21+M21+N21+O21 -> 16824650 | Q21: =P21*D21 -> 16824650 | R21: =P21*F21 -> 16824650
A22: 12 | B22: Cụm đồng hồ nước DN50 (gồm 01 đồng hồ, 02 van khóa, kèm phụ kiện) | C22: Cụm | D22: 2 | F22: 2 | G22: Đồng hồ nước DN50 PN16 Van khóa DN50 PN16 | H22: MTF - 55+KVS - 402 | I22: KVS | J22: Asia | K22: 3750640 | L22: 37510 | M22: 920810 | N22: =ROUND((K22+L22+M22)*10%,-1) -> 470900 | O22: =ROUND((K22+L22+M22+N22)*7%,-1) -> 362590 | P22: =K22+L22+M22+N22+O22 -> 5542450 | Q22: =P22*D22 -> 11084900 | R22: =P22*F22 -> 11084900
A23: 13 | B23: Cụm đồng hồ nước DN40 (gồm 01 đồng hồ, 02 van khóa, kèm phụ kiện) | C23: Cụm | D23: 5 | F23: 5 | G23: Đồng hồ nước DN40 PN10 Van khóa DN40 PN16 | H23: MTM - 55 +KVS - 402 | I23: KVS | J23: Asia | K23: 4748810 | L23: 47490 | M23: 494420 | N23: =ROUND((K23+L23+M23)*10%,-1) -> 529070 | O23: =ROUND((K23+L23+M23+N23)*7%,-1) -> 407390 | P23: =K23+L23+M23+N23+O23 -> 6227180 | Q23: =P23*D23 -> 31135900 | R23: =P23*F23 -> 31135900
A24: 14 | B24: Cụm đồng hồ nước DN32 (gồm 01 đồng hồ, 02 van khóa, kèm phụ kiện) | C24: Cụm | D24: 2 | F24: 2 | G24: Đồng hồ nước DN32 PN10 Van khóa DN32 PN16 | H24: MTM - 55 +KVS - 402 | I24: KVS | J24: Asia | K24: 3368300 | L24: 33680 | M24: 421850 | N24: =ROUND((K24+L24+M24)*10%,-1) -> 382380 | O24: =ROUND((K24+L24+M24+N24)*7%,-1) -> 294430 | P24: =K24+L24+M24+N24+O24 -> 4500640 | Q24: =P24*D24 -> 9001280 | R24: =P24*F24 -> 9001280
A25: 15 | B25: Cụm đồng hồ nước DN25 (gồm 01 đồng hồ, 02 van khóa, kèm phụ kiện) | C25: Cụm | D25: 6 | F25: 6 | G25: Đồng hồ nước DN25 PN10 Van khóa DN25 PN16 | H25: MTM - 55 +KVS - 402 | I25: KVS | J25: Asia | K25: 2219110 | L25: 22200 | M25: 374220 | N25: =ROUND((K25+L25+M25)*10%,-1) -> 261550 | O25: =ROUND((K25+L25+M25+N25)*7%,-1) -> 201400 | P25: =K25+L25+M25+N25+O25 -> 3078480 | Q25: =P25*D25 -> 18470880 | R25: =P25*F25 -> 18470880
A26: 16 | B26: Cụm đồng hồ nước DN20 (gồm 01 đồng hồ, 02 van khóa, kèm phụ kiện) | C26: Cụm | D26: 432 | F26: 432 | G26: Đồng hồ nước DN20 PN10 Van khóa DN20 PN16 | H26: MTM - 55 +KVS - 402 | I26: KVS | J26: Asia | K26: 1273420 | L26: 12730 | M26: 358340 | N26: =ROUND((K26+L26+M26)*10%,-1) -> 164450 | O26: =ROUND((K26+L26+M26+N26)*7%,-1) -> 126630 | P26: =K26+L26+M26+N26+O26 -> 1935570 | Q26: =P26*D26 -> 836166240 | R26: =P26*F26 -> 836166240
A27: 17 | B27: Cụm đồng hồ nước DN15 (gồm 01 đồng hồ, 02 van khóa, kèm phụ kiện) | C27: Cụm | D27: 84 | F27: 84 | G27: Đồng hồ nước DN15 PN10 Van khóa DN15 PN16 | H27: MTM - 55 +KVS - 402 | I27: KVS | J27: Asia | K27: 1090280 | L27: 10900 | M27: 349270 | N27: =ROUND((K27+L27+M27)*10%,-1) -> 145050 | O27: =ROUND((K27+L27+M27+N27)*7%,-1) -> 111690 | P27: =K27+L27+M27+N27+O27 -> 1707190 | Q27: =P27*D27 -> 143403960 | R27: =P27*F27 -> 143403960
A28: 18 | B28: Cảm biến mực nước | C28: Cái | D28: 6 | F28: 6 | I28: Omron | J28: Jpana | K28: 5194350 | L28: 51950 | M28: 292570 | N28: =ROUND((K28+L28+M28)*10%,-1) -> 553890 | O28: =ROUND((K28+L28+M28+N28)*7%,-1) -> 426490 | P28: =K28+L28+M28+N28+O28 -> 6519250 | Q28: =P28*D28 -> 39115500 | R28: =P28*F28 -> 39115500
A29: 19 | B29: Van búa nước DN80 | C29: Cái | D29: 2 | E29: PN25 | F29: 2 | G29: PN25 | H29: WHA-9000 | I29: KVS | J29: Asia | K29: 7501280 | L29: 75010 | M29: 589680 | N29: =ROUND((K29+L29+M29)*10%,-1) -> 816600 | O29: =ROUND((K29+L29+M29+N29)*7%,-1) -> 628780 | P29: =K29+L29+M29+N29+O29 -> 9611350 | Q29: =P29*D29 -> 19222700 | R29: =P29*F29 -> 19222700
A30: 20 | B30: Van chống va xả áp lực dư DN80 | C30: Cái | D30: 2 | E30: PN25 | F30: 2 | G30: PN25 | H30: KVS 702 - G | I30: KVS | J30: Asia | K30: 29669910 | L30: 296700 | M30: 612360 | N30: =ROUND((K30+L30+M30)*10%,-1) -> 3057900 | O30: =ROUND((K30+L30+M30+N30)*7%,-1) -> 2354580 | P30: =K30+L30+M30+N30+O30 -> 35991450 | Q30: =P30*D30 -> 71982900 | R30: =P30*F30 -> 71982900
A31: 21 | B31: Van phao cơ DN100 | C31: Cái | D31: 2 | E31: PN16 | F31: 2 | G31: PN16 | H31: KVS 703 - A | I31: KVS | J31: Asia | K31: 13658460 | L31: 136590 | M31: 657720 | N31: =ROUND((K31+L31+M31)*10%,-1) -> 1445280 | O31: =ROUND((K31+L31+M31+N31)*7%,-1) -> 1112860 | P31: =K31+L31+M31+N31+O31 -> 17010910 | Q31: =P31*D31 -> 34021820 | R31: =P31*F31 -> 34021820
A32: 22 | B32: Van xả khí tự động DN25 | C32: Cái | D32: 9 | F32: 9 | G32: PN16 | H32: KVS - 870 | I32: KVS | J32: Asia | K32: 1295910 | L32: 12960 | M32: 292570 | N32: =ROUND((K32+L32+M32)*10%,-1) -> 160140 | O32: =ROUND((K32+L32+M32+N32)*7%,-1) -> 123310 | P32: =K32+L32+M32+N32+O32 -> 1884890 | Q32: =P32*D32 -> 16964010 | R32: =P32*F32 -> 16964010
A33: 23 | B33: Cụm van giảm áp DN100 (gồm 4 van khóa, 02 van giảm áp) | C33: Cụm | D33: 1 | E33: PN16 | F33: 1 | G33: PN16 | H33: KVS - 400 A+KVS 701 - G | I33: KVS | J33: Asia | K33: 36953780 | L33: 369540 | M33: 2084290 | N33: =ROUND((K33+L33+M33)*10%,-1) -> 3940760 | O33: =ROUND((K33+L33+M33+N33)*7%,-1) -> 3034390 | P33: =K33+L33+M33+N33+O33 -> 46382760 | Q33: =P33*D33 -> 46382760 | R33: =P33*F33 -> 46382760
A34: 24 | B34: Cụm van giảm áp DN80 (gồm 4 van khóa, 02 van giảm áp) | C34: Cụm | D34: 5 | E34: PN16 | F34: 5 | G34: PN16 | H34: KVS - 400 A+KVS 701 - G | I34: KVS | J34: Asia | K34: 33239560 | L34: 332400 | M34: 2025320 | N34: =ROUND((K34+L34+M34)*10%,-1) -> 3559730 | O34: =ROUND((K34+L34+M34+N34)*7%,-1) -> 2740990 | P34: =K34+L34+M34+N34+O34 -> 41898000 | Q34: =P34*D34 -> 209490000 | R34: =P34*F34 -> 209490000
A35: 25 | B35: Cảm biến áp suất | C35: Cái | D35: 2 | F35: 2 | G35: 10 Bar | I35: Mass | J35: India | K35: 1985570 | L35: 19860 | M35: 292570 | N35: =ROUND((K35+L35+M35)*10%,-1) -> 229800 | O35: =ROUND((K35+L35+M35+N35)*7%,-1) -> 176950 | P35: =K35+L35+M35+N35+O35 -> 2704750 | Q35: =P35*D35 -> 5409500 | R35: =P35*F35 -> 5409500
A36: 26 | B36: Cửa thăm | C36: Cái | D36: 1 | F36: 0 | K36: 0 | L36: 0 | M36: 0 | N36: =ROUND((K36+L36+M36)*10%,-1) -> 0 | O36: =ROUND((K36+L36+M36+N36)*7%,-1) -> 0 | P36: =K36+L36+M36+N36+O36 -> 0 | Q36: =P36*D36 -> 0 | R36: =P36*F36 -> 0 | S36: Theo TCQ 02 ngày 04/10/2025
A37: 27 | B37: Cửa thăm vuông có bản lề hapulico hoặc tương đương | C37: Cái | D37: 6 | F37: 0 | K37: 0 | L37: 0 | M37: 0 | N37: =ROUND((K37+L37+M37)*10%,-1) -> 0 | O37: =ROUND((K37+L37+M37+N37)*7%,-1) -> 0 | P37: =K37+L37+M37+N37+O37 -> 0 | Q37: =P37*D37 -> 0 | R37: =P37*F37 -> 0 | S37: Theo TCQ 02 ngày 04/10/2025
A38: 28 | B38: Tấm ghi đậy rãnh B300, KN12,5 | C38: m | D38: 16 | F38: 0 | K38: 0 | L38: 0 | M38: 0 | N38: =ROUND((K38+L38+M38)*10%,-1) -> 0 | O38: =ROUND((K38+L38+M38+N38)*7%,-1) -> 0 | P38: =K38+L38+M38+N38+O38 -> 0 | Q38: =P38*D38 -> 0 | R38: =P38*F38 -> 0 | S38: Theo TCQ 02 ngày 04/10/2025
A39: 29 | B39: Bể Inox lắp ghép mái tháp B 32m3 (AxBxH=4x4x2.5) | C39: Cái | D39: 1 | F39: 1 | G39: - Kích thước: D4,0(2,0+2,0)×R4,0×C3,0(m); -Dung tích bể: 32m3; -Chia ngǎn: Chia 02 ngǎn; -Trọng lượng : Khoảng 2.2 Tấn -Vật liệu: Inox 304; Tấm panel đáy bể dày 3.0mm dập chỏm cầu tăng cứng tại nhà máy, quy cách giống tấm thành và nóc, tấm panel thành 1 dày 2.5mm; tấm thành 2 dày 2.0mm; tấm thành 3 dày 1.5mm; tấm nóc bê dày 1.2mm; Sản xuất theo tiêu chuẩn Jis G4305:2012/ASTM-A240;Hệ giằng, chống trong bê V30x2.0-2.5mm. Hệ U100x45x4.0 chấn mạ kẽm nhúng nóng, lắp đặt bằng bulong ma kẽm. | I39: Sơn Hà | J39: Việt Nam | K39: 380672310 | L39: 6978110 | M39: 38789600 | N39: =ROUND((K39+L39+M39)*10%,-1) -> 42644000 | O39: =ROUND((K39+L39+M39+N39)*7%,-1) -> 32835880 | P39: =K39+L39+M39+N39+O39 -> 501919900 | Q39: =P39*D39 -> 501919900 | R39: =P39*F39 -> 501919900
A40: 30 | B40: Bể Inox lắp ghép mái tháp A 36m3 (AxBxH=6x3x2.5) | C40: Cái | D40: 1 | F40: 1 | G40: -Kích thước : D6,0(3,0+3,0)×R3,0×C3,0(m); -Dung tích bể : 36m3; -Chia ngǎn: Chia 02 ngǎn; -Trong luợng: Khoảng 2.4 Tấn - Vật liệu: Inox 304; Tấm panel đáy bể dày 3.0mm dập chóm cầu tăng cứng tại nhà máy, quy cách giống tấm thành và nóc, tấm panel thành 1 dày 2.5mm; tấm thành 2 dày 2.0mm;tấm thành 3 dày 1.5mm; tấm nóc bể dày 1.2mm; Sản xuất theo tiêu chuẩn Jis G4305:2012/ASTM-A240;Hệ giằng,chống trong bể V30x2.0-2.5mm. Hệ U100x45x4.0 chấn mạ kẽm nhúng nóng, lắp đặt bằng bulong ma kēm. | I40: Sơn Hà | J40: Việt Nam | K40: 402454980 | L40: 7382730 | M40: 38789600 | N40: =ROUND((K40+L40+M40)*10%,-1) -> 44862730 | O40: =ROUND((K40+L40+M40+N40)*7%,-1) -> 34544300 | P40: =K40+L40+M40+N40+O40 -> 528034340 | Q40: =P40*D40 -> 528034340 | R40: =P40*F40 -> 528034340
A41: 31 | B41: Nắp ghi gang ga thu sàn 400x600 | C41: Cái | D41: 10 | E41: Chưa bao gồm | F41: 0 | K41: 0 | L41: 0 | M41: 0 | N41: =ROUND((K41+L41+M41)*10%,-1) -> 0 | O41: =ROUND((K41+L41+M41+N41)*7%,-1) -> 0 | P41: =K41+L41+M41+N41+O41 -> 0 | Q41: =P41*D41 -> 0 | R41: =P41*F41 -> 0 | S41: Theo TCQ 02 ngày 04/10/2025
...

Sheet 4.1 ĐH VRV
A1: Dự án: TOÀ NHÀ HỖN HỢP HACOM MALL
A2: Gói thầu: CUNG CẤP VTTB VÀ THI CÔNG LẮP ĐẶT HỆ THỐNG CƠ ĐIỆN
A3: Hạng mục: HỆ THỐNG HVAC
A5: KHỐI LƯỢNG MỜI THẦU | U5: LIÊN DANH CÔNG TY TNHH VĂN LANG VÀ CÔNG TY TNHH XÂY DỰNG CƠ ĐIỆN TRÍ TRUNG
A6: STT | B6: Diễn giải | C6: TẦNGH2 | D6: TẦNGH1 | E6: TẦNG1 | F6: TẦNG2 | G6: TẦNG3 | H6: TẦNG4 | I6: TẦNG5 | J6: TẦNG23 | K6: Đơn vị | L6: KL Mời thầu Lần 2 | M6: Công suất lạnh Kw | N6: Lưu lượng gió (m3/min) | O6: Cột áp (Pa) | P6: Công suất điện (W) | Q6: Điên áp (P/V/Hz) | R6: Môi chất lạnh | S6: Quy cách | T6: Ghi chú | U6: KL Nhà thầu chào | V6: THÔNG TIN VỀ VẬT LIỆU CHÍNH | Z6: ĐƠN GIÁ (chưa bao gồm VAT) | AF6: Thành tiền BOQ | AH6: Ghi chú
V7: Mô tả/ Quy cách | W7: Mã hiệu | X7: Thương hiệu | Y7: Xuất xứ | Z7: VL chính | AA7: VL phụ | AB7: NC&M | AC7: CF quản lý | AD7: Lợi nhuận | AE7: ĐG tổng hợp | AF7: Thành tiền KLMT | AG7: Thành tiền Nhà thầu chào
A8: 1 | B8: 2 | K8: 3 | L8: 4 | T8: 5 | U8: 6 | V8: 7 | W8: 8 | X8: 9 | Y8: 10 | Z8: 11 | AA8: 12 | AB8: 13 | AC8: 14 | AD8: 15 | AE8: 16=11+12+13+14+15 | AF8: 17=4*16 | AG8: 18=6*16 | AH8: 19
A9: A | B9: ĐẦU MỤC CÔNG VIỆC THEO KLMT | AF9: =SUBTOTAL(9,AF11:AF49) -> 848202920 | AG9: =SUBTOTAL(9,AG11:AG49) -> 852532280
B10: THIẾT BỊ ĐIỀU HOÀ KHÔNG KHÍ
A11: I. THIẾT BỊ ĐIỀU HÒA VRV (VRF)
A12: 1. DÀN LẠNH ĐIỀU HÒA VRV, VRF
A13: 1 | B13: Dàn lạnh 1 chiều lạnh loại âm trần nối ống gió | I13: 1 | K13: cái | L13: 1 | M13: 4.5 | N13: 16/13/11 | O13: 50-200 | P13: 151 | Q13: 1P/220/50 | R13: R410A | S13: Đồng bộ với dàn nóng kèm điều khiển từ xa loại có dây | T13: Nhà thầu lắp đặt, CĐT cấp thiết bị | U13: 1 | AA13: 122400 | AB13: 1312500 | AC13: =ROUND((Z13+AA13+AB13)*10%,-1) -> 143490 | AD13: =ROUND((Z13+AA13+AB13+AC13)*7%,-1) -> 110490 | AE13: =Z13+AA13+AB13+AC13+AD13 -> 1688880 | AF13: =AE13*L13 -> 1688880 | AG13: =AE13*U13 -> 1688880
A14: 2 | B14: Dàn lạnh 1 chiều lạnh loại âm trần nối ống gió | E14: 1 | F14: 4 | G14: 2 | H14: 8 | I14: 3 | K14: cái | L14: 18 | M14: 5.6 | N14: 18/16,5/15 | O14: 50-200 | P14: 128 | Q14: 1P/220/50 | R14: R410A | S14: Đồng bộ với dàn nóng kèm điều khiển từ xa loại có dây | U14: 18 | AA14: 122400 | AB14: 1312500 | AC14: =ROUND((Z14+AA14+AB14)*10%,-1) -> 143490 | AD14: =ROUND((Z14+AA14+AB14+AC14)*7%,-1) -> 110490 | AE14: =Z14+AA14+AB14+AC14+AD14 -> 1688880 | AF14: =AE14*L14 -> 30399840 | AG14: =AE14*U14 -> 30399840
A15: 3 | B15: Dàn lạnh 1 chiều lạnh loại âm trần nối ống gió | E15: 6 | F15: 7 | G15: 2 | I15: 6 | K15: cái | L15: 20 | M15: 7.1 | N15: 19.5/17.5/16 | O15: 50-200 | P15: 138 | Q15: 1P/220/50 | R15: R410A | S15: Đồng bộ với dàn nóng kèm điều khiển từ xa loại có dây | U15: 21 | AA15: 122400 | AB15: 1454250 | AC15: =ROUND((Z15+AA15+AB15)*10%,-1) -> 157670 | AD15: =ROUND((Z15+AA15+AB15+AC15)*7%,-1) -> 121400 | AE15: =Z15+AA15+AB15+AC15+AD15 -> 1855720 | AF15: =AE15*L15 -> 37114400 | AG15: =AE15*U15 -> 38970120
A16: 4 | B16: Dàn lạnh 1 chiều lạnh loại âm trần nối ống gió | E16: 2 | F16: 11 | G16: 7 | H16: 8 | I16: 8 | K16: cái | L16: 34 | M16: 9 | N16: 25/22,2/20 | O16: 50-200 | P16: 185 | Q16: 1P/220/50 | R16: R410A | S16: Đồng bộ với dàn nóng kèm điều khiển từ xa loại có dây | U16: 35 | AA16: 122400 | AB16: 1454250 | AC16: =ROUND((Z16+AA16+AB16)*10%,-1) -> 157670 | AD16: =ROUND((Z16+AA16+AB16+AC16)*7%,-1) -> 121400 | AE16: =Z16+AA16+AB16+AC16+AD16 -> 1855720 | AF16: =AE16*L16 -> 63094480 | AG16: =AE16*U16 -> 64950200
A17: 5 | B17: Dàn lạnh 1 chiều lạnh loại âm trần nối ống gió | E17: 8 | F17: 10 | G17: 16 | H17: 13 | I17: 3 | K17: cái | L17: 51 | M17: 11.2 | N17: 32/27/23 | O17: 50-200 | P17: 215 | Q17: 1P/220/50 | R17: R410A | S17: Đồng bộ với dàn nóng kèm điều khiển từ xa loại có dây | U17: 51 | AA17: 122400 | AB17: 1646400 | AC17: =ROUND((Z17+AA17+AB17)*10%,-1) -> 176880 | AD17: =ROUND((Z17+AA17+AB17+AC17)*7%,-1) -> 136200 | AE17: =Z17+AA17+AB17+AC17+AD17 -> 2081880 | AF17: =AE17*L17 -> 106175880 | AG17: =AE17*U17 -> 106175880
A18: 6 | B18: Dàn lạnh 1 chiều lạnh loại âm trần nối ống gió | E18: 1 | F18: 4 | G18: 4 | H18: 4 | I18: 2 | K18: cái | L18: 16 | M18: 14 | N18: 39/33/28 | O18: 50-200 | P18: 284 | Q18: 1P/220/50 | R18: R410A | S18: Đồng bộ với dàn nóng kèm điều khiển từ xa loại có dây | U18: 15 | AA18: 122400 | AB18: 1942500 | AC18: =ROUND((Z18+AA18+AB18)*10%,-1) -> 206490 | AD18: =ROUND((Z18+AA18+AB18+AC18)*7%,-1) -> 159000 | AE18: =Z18+AA18+AB18+AC18+AD18 -> 2430390 | AF18: =AE18*L18 -> 38886240 | AG18: =AE18*U18 -> 36455850
A19: 7 | B19: Dàn lạnh 1 chiều lạnh loại âm trần nối ống gió | E19: 1 | F19: 21 | G19: 28 | H19: 19 | I19: 17 | K19: cái | L19: 85 | M19: 16 | N19: 16/39/32 | O19: 50-200 | P19: 405 | Q19: 1P/220/50 | R19: R410A | S19: Đồng bộ với dàn nóng kèm điều khiển từ xa loại có dây | U19: 86 | AA19: 122400 | AB19: 2467500 | AC19: =ROUND((Z19+AA19+AB19)*10%,-1) -> 258990 | AD19: =ROUND((Z19+AA19+AB19+AC19)*7%,-1) -> 199420 | AE19: =Z19+AA19+AB19+AC19+AD19 -> 3048310 | AF19: =AE19*L19 -> 259106350 | AG19: =AE19*U19 -> 262154660
A20: 8 | B20: Dàn lạnh 1 chiều lạnh loại âm trần nối ống gió | E20: 8 | I20: 6 | K20: cái | L20: 14 | M20: 22.4 | N20: 16/39/32 | O20: 50-200 | P20: 405 | Q20: 1P/220/50 | R20: R410A | S20: Đồng bộ với dàn nóng kèm điều khiển từ xa loại có dây | U20: 14 | AA20: 122400 | AB20: 2992500 | AC20: =ROUND((Z20+AA20+AB20)*10%,-1) -> 311490 | AD20: =ROUND((Z20+AA20+AB20+AC20)*7%,-1) -> 239850 | AE20: =Z20+AA20+AB20+AC20+AD20 -> 3666240 | AF20: =AE20*L20 -> 51327360 | AG20: =AE20*U20 -> 51327360
A21: 9 | B21: Dàn lạnh 1 chiều lạnh loại treo tường | I21: 1 | K21: cái | L21: 1 | M21: 2.2 | N21: 16/39/32 | O21: 50-200 | P21: 405 | Q21: 1P/220/50 | R21: R410A | S21: Đồng bộ với dàn nóng kèm điều khiển từ xa loại có dây | U21: 1 | AA21: 81600 | AB21: 682500 | AC21: =ROUND((Z21+AA21+AB21)*10%,-1) -> 76410 | AD21: =ROUND((Z21+AA21+AB21+AC21)*7%,-1) -> 58840 | AE21: =Z21+AA21+AB21+AC21+AD21 -> 899350 | AF21: =AE21*L21 -> 899350 | AG21: =AE21*U21 -> 899350
A22: 10 | B22: Dàn lạnh 1 chiều lạnh loại cassette âm trần | I22: 1 | K22: cái | L22: 1 | M22: 2.2 | N22: 9,5/8/7 | O22: 50-200 | P22: 60 | Q22: 1P/220/50 | R22: R410A | S22: Đồng bộ với dàn nóng kèm điều khiển từ xa loại có dây | U22: 1 | AA22: 122400 | AB22: 892500 | AC22: =ROUND((Z22+AA22+AB22)*10%,-1) -> 101490 | AD22: =ROUND((Z22+AA22+AB22+AC22)*7%,-1) -> 78150 | AE22: =Z22+AA22+AB22+AC22+AD22 -> 1194540 | AF22: =AE22*L22 -> 1194540 | AG22: =AE22*U22 -> 1194540
A23: 11 | B23: Dàn lạnh 1 chiều lạnh loại cassette âm trần | I23: 1 | K23: cái | L23: 1 | M23: 7.1 | N23: 16/39/32 | O23: 50-200 | P23: 405 | Q23: 1P/220/50 | R23: R410A | S23: Đồng bộ với dàn nóng kèm điều khiển từ xa loại có dây | U23: 1 | AA23: 122400 | AB23: 1412250 | AC23: =ROUND((Z23+AA23+AB23)*10%,-1) -> 153470 | AD23: =ROUND((Z23+AA23+AB23+AC23)*7%,-1) -> 118170 | AE23: =Z23+AA23+AB23+AC23+AD23 -> 1806290 | AF23: =AE23*L23 -> 1806290 | AG23: =AE23*U23 -> 1806290
A24: 12 | B24: Dàn lạnh 1 chiều lạnh loại cassette âm trần | I24: 2 | K24: cái | L24: 2 | M24: 14 | N24: 16/39/32 | O24: 50-200 | P24: 405 | Q24: 1P/220/50 | R24: R410A | S24: Đồng bộ với dàn nóng kèm điều khiển từ xa loại có dây | U24: 2 | AA24: 122400 | AB24: 1942500 | AC24: =ROUND((Z24+AA24+AB24)*10%,-1) -> 206490 | AD24: =ROUND((Z24+AA24+AB24+AC24)*7%,-1) -> 159000 | AE24: =Z24+AA24+AB24+AC24+AD24 -> 2430390 | AF24: =AE24*L24 -> 4860780 | AG24: =AE24*U24 -> 4860780
A25: 2. DÀN NÓNG ĐIỀU HÒA VRV, VRF
A26: 1 | B26: Dàn nóng 1 chiều lạnh (22HP). | E26: 1 | K26: cái | L26: 1 | M26: 61.5 | N26: -- | O26: -- | P26: 16100 | Q26: 3P/380/50 | R26: R410A | S26: Trọn bộ | T26: Nhà thầu lắp đặt, CĐT cấp thiết bị | U26: 1 | AA26: 1020000 | AB26: 6825000 | AC26: =ROUND((Z26+AA26+AB26)*10%,-1) -> 784500 | AD26: =ROUND((Z26+AA26+AB26+AC26)*7%,-1) -> 604070 | AE26: =Z26+AA26+AB26+AC26+AD26 -> 9233570 | AF26: =AE26*L26 -> 9233570 | AG26: =AE26*U26 -> 9233570
A27: 2 | B27: Dàn nóng 1 chiều lạnh (24HP). | E27: 1 | K27: cái | L27: 1 | M27: 67 | N27: -- | O27: -- | P27: 17800 | Q27: 3P/380/50 | R27: R410A | S27: Trọn bộ | U27: 1 | AA27: 1020000 | AB27: 6825000 | AC27: =ROUND((Z27+AA27+AB27)*10%,-1) -> 784500 | AD27: =ROUND((Z27+AA27+AB27+AC27)*7%,-1) -> 604070 | AE27: =Z27+AA27+AB27+AC27+AD27 -> 9233570 | AF27: =AE27*L27 -> 9233570 | AG27: =AE27*U27 -> 9233570
A28: 3 | B28: Dàn nóng 1 chiều lạnh (26HP). | E28: 1 | K28: cái | L28: 1 | M28: 73.5 | N28: -- | O28: -- | P28: 19900 | Q28: 3P/380/50 | R28: R410A | S28: Trọn bộ | U28: 1 | AA28: 1020000 | AB28: 6825000 | AC28: =ROUND((Z28+AA28+AB28)*10%,-1) -> 784500 | AD28: =ROUND((Z28+AA28+AB28+AC28)*7%,-1) -> 604070 | AE28: =Z28+AA28+AB28+AC28+AD28 -> 9233570 | AF28: =AE28*L28 -> 9233570 | AG28: =AE28*U28 -> 9233570
A29: 4 | B29: Dàn nóng 1 chiều lạnh (32HP). | H29: 1 | K29: cái | L29: 1 | M29: 90 | N29: -- | O29: -- | P29: 25800 | Q29: 3P/380/50 | R29: R410A | S29: Trọn bộ | U29: 1 | AA29: 1020000 | AB29: 6825000 | AC29: =ROUND((Z29+AA29+AB29)*10%,-1) -> 784500 | AD29: =ROUND((Z29+AA29+AB29+AC29)*7%,-1) -> 604070 | AE29: =Z29+AA29+AB29+AC29+AD29 -> 9233570 | AF29: =AE29*L29 -> 9233570 | AG29: =AE29*U29 -> 9233570
A30: 5 | B30: Dàn nóng 1 chiều lạnh (34HP). | I30: 1 | K30: cái | L30: 1 | M30: 95 | N30: -- | O30: -- | P30: 28200 | Q30: 3P/380/50 | R30: R410A | S30: Trọn bộ | U30: 1 | AA30: 1020000 | AB30: 6825000 | AC30: =ROUND((Z30+AA30+AB30)*10%,-1) -> 784500 | AD30: =ROUND((Z30+AA30+AB30+AC30)*7%,-1) -> 604070 | AE30: =Z30+AA30+AB30+AC30+AD30 -> 9233570 | AF30: =AE30*L30 -> 9233570 | AG30: =AE30*U30 -> 9233570
A31: 6 | B31: Dàn nóng 1 chiều lạnh (36HP). | H31: 2 | K31: cái | L31: 2 | M31: 101 | N31: -- | O31: -- | P31: 30600 | Q31: 3P/380/50 | R31: R410A | S31: Trọn bộ | U31: 2 | AA31: 1020000 | AB31: 6825000 | AC31: =ROUND((Z31+AA31+AB31)*10%,-1) -> 784500 | AD31: =ROUND((Z31+AA31+AB31+AC31)*7%,-1) -> 604070 | AE31: =Z31+AA31+AB31+AC31+AD31 -> 9233570 | AF31: =AE31*L31 -> 18467140 | AG31: =AE31*U31 -> 18467140
A32: 7 | B32: Dàn nóng 1 chiều lạnh (38HP). | H32: 1 | I32: 1 | K32: cái | L32: 2 | M32: 106 | N32: -- | O32: -- | P32: 33000 | Q32: 3P/380/50 | R32: R410A | S32: Trọn bộ | U32: 2 | AA32: 1020000 | AB32: 6825000 | AC32: =ROUND((Z32+AA32+AB32)*10%,-1) -> 784500 | AD32: =ROUND((Z32+AA32+AB32+AC32)*7%,-1) -> 604070 | AE32: =Z32+AA32+AB32+AC32+AD32 -> 9233570 | AF32: =AE32*L32 -> 18467140 | AG32: =AE32*U32 -> 18467140
A33: 8 | B33: Dàn nóng 1 chiều lạnh (40HP). | F33: 1 | G33: 1 | K33: cái | L33: 2 | M33: 112 | N33: -- | O33: -- | P33: 35400 | Q33: 3P/380/50 | R33: R410A | S33: Trọn bộ | U33: 2 | AA33: 1020000 | AB33: 6825000 | AC33: =ROUND((Z33+AA33+AB33)*10%,-1) -> 784500 | AD33: =ROUND((Z33+AA33+AB33+AC33)*7%,-1) -> 604070 | AE33: =Z33+AA33+AB33+AC33+AD33 -> 9233570 | AF33: =AE33*L33 -> 18467140 | AG33: =AE33*U33 -> 18467140
A34: 9 | B34: Dàn nóng 1 chiều lạnh (42HP). | F34: 1 | H34: 1 | K34: cái | L34: 2 | M34: 117 | N34: -- | O34: -- | P34: 32700 | Q34: 3P/380/50 | R34: R410A | S34: Trọn bộ | U34: 2 | AA34: 1020000 | AB34: 6825000 | AC34: =ROUND((Z34+AA34+AB34)*10%,-1) -> 784500 | AD34: =ROUND((Z34+AA34+AB34+AC34)*7%,-1) -> 604070 | AE34: =Z34+AA34+AB34+AC34+AD34 -> 9233570 | AF34: =AE34*L34 -> 18467140 | AG34: =AE34*U34 -> 18467140
A35: 10 | B35: Dàn nóng 1 chiều lạnh (44HP). | F35: 1 | K35: cái | L35: 1 | M35: 123 | N35: -- | O35: -- | P35: 35100 | Q35: 3P/380/50 | R35: R410A | S35: Trọn bộ | U35: 1 | AA35: 1020000 | AB35: 6825000 | AC35: =ROUND((Z35+AA35+AB35)*10%,-1) -> 784500 | AD35: =ROUND((Z35+AA35+AB35+AC35)*7%,-1) -> 604070 | AE35: =Z35+AA35+AB35+AC35+AD35 -> 9233570 | AF35: =AE35*L35 -> 9233570 | AG35: =AE35*U35 -> 9233570
A36: 11 | B36: Dàn nóng 1 chiều lạnh (46HP). | H36: 1 | K36: cái | L36: 1 | M36: 145 | N36: -- | O36: -- | P36: 36500 | Q36: 3P/380/50 | R36: R410A | S36: Trọn bộ | U36: 1 | AA36: 1020000 | AB36: 6825000 | AC36: =ROUND((Z36+AA36+AB36)*10%,-1) -> 784500 | AD36: =ROUND((Z36+AA36+AB36+AC36)*7%,-1) -> 604070 | AE36: =Z36+AA36+AB36+AC36+AD36 -> 9233570 | AF36: =AE36*L36 -> 9233570 | AG36: =AE36*U36 -> 9233570
A37: 12 | B37: Dàn nóng 1 chiều lạnh (50HP). | I37: 2 | K37: cái | L37: 2 | M37: 140 | N37: -- | O37: -- | P37: 41100 | Q37: 3P/380/50 | R37: R410A | S37: Trọn bộ | U37: 2 | AA37: 1020000 | AB37: 6825000 | AC37: =ROUND((Z37+AA37+AB37)*10%,-1) -> 784500 | AD37: =ROUND((Z37+AA37+AB37+AC37)*7%,-1) -> 604070 | AE37: =Z37+AA37+AB37+AC37+AD37 -> 9233570 | AF37: =AE37*L37 -> 18467140 | AG37: =AE37*U37 -> 18467140
A38: 13 | B38: Dàn nóng 1 chiều lạnh (58HP). | E38: 1 | K38: cái | L38: 1 | M38: 162 | N38: -- | O38: -- | P38: 50700 | Q38: 3P/380/50 | R38: R410A | S38: Trọn bộ | U38: 1 | AA38: 1020000 | AB38: 6825000 | AC38: =ROUND((Z38+AA38+AB38)*10%,-1) -> 784500 | AD38: =ROUND((Z38+AA38+AB38+AC38)*7%,-1) -> 604070 | AE38: =Z38+AA38+AB38+AC38+AD38 -> 9233570 | AF38: =AE38*L38 -> 9233570 | AG38: =AE38*U38 -> 9233570
A39: 14 | B39: Dàn nóng 1 chiều lạnh (60HP). | F39: 2 | G39: 4 | I39: 1 | K39: cái | L39: 7 | M39: 158 | N39: -- | O39: -- | P39: 53100 | Q39: 3P/380/50 | R39: R410A | S39: Trọn bộ | U39: 7 | AA39: 1020000 | AB39: 6825000 | AC39: =ROUND((Z39+AA39+AB39)*10%,-1) -> 784500 | AD39: =ROUND((Z39+AA39+AB39+AC39)*7%,-1) -> 604070 | AE39: =Z39+AA39+AB39+AC39+AD39 -> 9233570 | AF39: =AE39*L39 -> 64634990 | AG39: =AE39*U39 -> 64634990
A40: II. THIẾT BỊ ĐIỀU HÒA CỤC BỘ
A41: 1. HỆ THỐNG ĐIỀU HÒA CỤC BỘ
...

Sheet 4.2 Quạt
A1: Dự án: TOÀ NHÀ HỖN HỢP HACOM MALL
A2: Gói thầu: CUNG CẤP VTTB VÀ THI CÔNG LẮP ĐẶT HỆ THỐNG CƠ ĐIỆN
A3: Hạng mục: HỆ THỐNG HVAC
A5: KHỐI LƯỢNG MỜI THẦU | R5: LIÊN DANH CÔNG TY TNHH VĂN LANG VÀ CÔNG TY TNHH XÂY DỰNG CƠ ĐIỆN TRÍ TRUNG
A6: STT | B6: DANH MỤC QUẠT THÔNG GIÓ | C6: Đơn vị | D6: KL Mời thầu Lần 1 | E6: KL BIM | F6: KL Mời thầu Lần 2 | G6: KÍ HIỆU | H6: LƯU LƯỢNG | I6: CỘP ÁP | J6: QUY CÁCH | K6: NHIỆT ĐỘ LÀM VIỆC | L6: CÔNG SUẤT ĐIỆN | M6: NGUỒN ĐIỆN | N6: ĐỘ ỒN | O6: HIỆU SUẤT | P6: Tốc độ vòng quay | Q6: GHI CHÚ | R6: KL Nhà thầu chào | S6: THÔNG TIN VỀ VẬT LIỆU CHÍNH | W6: ĐƠN GIÁ (chưa bao gồm VAT) | AC6: Thành tiền BOQ | AE6: Ghi chú
I7: Pa | K7: oC | L7: kW | M7: V/Ph/Hz | N7: dBA @ 3M | S7: Mô tả/ Quy cách | T7: Mã hiệu | U7: Thương hiệu | V7: Xuất xứ | W7: VL chính | X7: VL phụ | Y7: NC&M | Z7: CF quản lý | AA7: Lợi nhuận | AB7: ĐG tổng hợp | AC7: Thành tiền KLMT | AD7: Thành tiền Nhà thầu chào
A8: 1 | B8: 2 | C8: 3 | F8: 4 | Q8: 5 | R8: 6 | S8: 7 | T8: 8 | U8: 9 | V8: 10 | W8: 11 | X8: 12 | Y8: 13 | Z8: 14 | AA8: 15 | AB8: 16=11+12+13+14+15 | AC8: 17=4*16 | AD8: 18=6*16 | AE8: 19
A9: A | B9: ĐẦU MỤC CÔNG VIỆC THEO KLMT | AC9: =SUBTOTAL(9,AC11:AC145) -> 4318893890 | AD9: =SUBTOTAL(9,AD11:AD145) -> 4337316010
A10: I | B10: QUẠT THÔNG GIÓ CẤP, HÚT
B11: QUẠT THÔNG GIÓ CẤP, HÚT TẦNG HẦM - TUM
B12: Tầng hầm 2
A13: 1 | B13: QUẠT HÚT PHÒNG QUẠT HÚT 1 | C13: Cái | D13: 1 | E13: 1 | F13: =E13 -> 1 | G13: TH2/EF-03 | H13: 650 | I13: 25 | J13: Fan wall mounted | K13: 55 | L13: 0.37 | M13: 220/1/50 | N13: ≤ 65 dBA | O13: ≥ 50 % | P13: ≤ 2900 rpm | R13: 1 | S13: Quạt gắn tường | T13: VNS-AV6-25 | U13: TH VINASUN | V13: Việt Nam | W13: 479400 | X13: 42000 | Y13: 714000 | Z13: =ROUND((W13+X13+Y13)*10%,-1) -> 123540 | AA13: =ROUND((W13+X13+Y13+Z13)*7%,-1) -> 95130 | AB13: =W13+X13+Y13+Z13+AA13 -> 1454070 | AC13: =AB13*F13 -> 1454070 | AD13: =AB13*R13 -> 1454070
A14: 2 | B14: QUẠT HÚT PHÒNG QUẠT HÚT 2 | C14: Cái | D14: 1 | E14: 1 | F14: =E14 -> 1 | G14: TH2/EF-04 | H14: 650 | I14: 25 | J14: Fan wall mounted | K14: 55 | L14: 0.37 | M14: 220/1/50 | N14: ≤ 65 dBA | O14: ≥ 50 % | P14: ≤ 2900 rpm | R14: 1 | S14: Quạt gắn tường | T14: VNS-AV6-25 | U14: TH VINASUN | V14: Việt Nam | W14: 479400 | X14: 42000 | Y14: 714000 | Z14: =ROUND((W14+X14+Y14)*10%,-1) -> 123540 | AA14: =ROUND((W14+X14+Y14+Z14)*7%,-1) -> 95130 | AB14: =W14+X14+Y14+Z14+AA14 -> 1454070 | AC14: =AB14*F14 -> 1454070 | AD14: =AB14*R14 -> 1454070
A15: 3 | B15: QUẠT HÚT PHÒNG QUẠT HÚT 3 | C15: Cái | D15: 1 | E15: 1 | F15: =E15 -> 1 | G15: TH2/EF-05 | H15: 1000 | I15: 50 | J15: Fan wall mounted | K15: 55 | L15: 0.37 | M15: 220/1/50 | N15: ≤ 65 dBA | O15: ≥ 50 % | P15: ≤ 2900 rpm | R15: 1 | S15: Quạt gắn tường | T15: VNS-AV6-25 | U15: TH VINASUN | V15: Việt Nam | W15: 479400 | X15: 42000 | Y15: 714000 | Z15: =ROUND((W15+X15+Y15)*10%,-1) -> 123540 | AA15: =ROUND((W15+X15+Y15+Z15)*7%,-1) -> 95130 | AB15: =W15+X15+Y15+Z15+AA15 -> 1454070 | AC15: =AB15*F15 -> 1454070 | AD15: =AB15*R15 -> 1454070
A16: 4 | B16: QUẠT HÚT PHÒNG QUẠT CẤP | C16: Cái | D16: 1 | E16: 1 | F16: =E16 -> 1 | G16: TH2/EF-06 | H16: 650 | I16: 25 | J16: Fan wall mounted | K16: 55 | L16: 0.37 | M16: 220/1/50 | N16: ≤ 65 dBA | O16: ≥ 50 % | P16: ≤ 2900 rpm | R16: 1 | S16: Quạt gắn tường | T16: VNS-AV6-25 | U16: TH VINASUN | V16: Việt Nam | W16: 479400 | X16: 42000 | Y16: 714000 | Z16: =ROUND((W16+X16+Y16)*10%,-1) -> 123540 | AA16: =ROUND((W16+X16+Y16+Z16)*7%,-1) -> 95130 | AB16: =W16+X16+Y16+Z16+AA16 -> 1454070 | AC16: =AB16*F16 -> 1454070 | AD16: =AB16*R16 -> 1454070
A17: 6 | B17: QUẠT HÚT KHO 1 | C17: Cái | D17: 1 | E17: 1 | F17: =E17 -> 1 | G17: TH2/EF-08 | H17: 650 | I17: 25 | J17: Fan wall mounted | K17: 55 | L17: 0.37 | M17: 220/1/50 | N17: ≤ 65 dBA | O17: ≥ 50 % | P17: ≤ 2900 rpm | R17: 1 | S17: Quạt gắn tường | T17: VNS-AV6-25 | U17: TH VINASUN | V17: Việt Nam | W17: 479400 | X17: 42000 | Y17: 714000 | Z17: =ROUND((W17+X17+Y17)*10%,-1) -> 123540 | AA17: =ROUND((W17+X17+Y17+Z17)*7%,-1) -> 95130 | AB17: =W17+X17+Y17+Z17+AA17 -> 1454070 | AC17: =AB17*F17 -> 1454070 | AD17: =AB17*R17 -> 1454070
A18: 7 | B18: QUẠT HÚT KHO 2 | C18: Cái | D18: 1 | E18: 1 | F18: =E18 -> 1 | G18: TH2/EF-09 | H18: 250 | I18: 20 | J18: Fan wall mounted | K18: 55 | L18: 0.37 | M18: 220/1/50 | N18: ≤ 65 dBA | O18: ≥ 50 % | P18: ≤ 1450 rpm | R18: 1 | S18: Quạt gắn tường | T18: VNS-AV6-15 | U18: TH VINASUN | V18: Việt Nam | W18: 390660 | X18: 42000 | Y18: 630000 | Z18: =ROUND((W18+X18+Y18)*10%,-1) -> 106270 | AA18: =ROUND((W18+X18+Y18+Z18)*7%,-1) -> 81830 | AB18: =W18+X18+Y18+Z18+AA18 -> 1250760 | AC18: =AB18*F18 -> 1250760 | AD18: =AB18*R18 -> 1250760
A19: 8 | B19: QUẠT HÚT KHO 3 | C19: Cái | D19: 1 | E19: 1 | F19: =E19 -> 1 | G19: TH2/EF-10 | H19: 350 | I19: 25 | J19: Fan wall mounted | K19: 55 | L19: 0.37 | M19: 220/1/50 | N19: ≤ 65 dBA | O19: ≥ 50 % | P19: ≤ 1450 rpm | R19: 1 | S19: Quạt gắn tường | T19: VNS-AV6-20 | U19: TH VINASUN | V19: Việt Nam | W19: 441660 | X19: 42000 | Y19: 630000 | Z19: =ROUND((W19+X19+Y19)*10%,-1) -> 111370 | AA19: =ROUND((W19+X19+Y19+Z19)*7%,-1) -> 85750 | AB19: =W19+X19+Y19+Z19+AA19 -> 1310780 | AC19: =AB19*F19 -> 1310780 | AD19: =AB19*R19 -> 1310780
A20: 9 | B20: QUẠT HÚT KHO 4 | C20: Cái | D20: 1 | E20: 1 | F20: =E20 -> 1 | G20: TH2/EF-11 | H20: 150 | I20: 20 | J20: Fan wall mounted | K20: 55 | L20: 0.37 | M20: 220/1/50 | N20: ≤ 65 dBA | O20: ≥ 50 % | R20: 1 | S20: Quạt gắn tường | T20: VNS-AV6-15 | U20: TH VINASUN | V20: Việt Nam | W20: 390660 | X20: 42000 | Y20: 472500 | Z20: =ROUND((W20+X20+Y20)*10%,-1) -> 90520 | AA20: =ROUND((W20+X20+Y20+Z20)*7%,-1) -> 69700 | AB20: =W20+X20+Y20+Z20+AA20 -> 1065380 | AC20: =AB20*F20 -> 1065380 | AD20: =AB20*R20 -> 1065380
A21: 10 | B21: QUẠT CẤP GIÓ TẦNG HẦM ZONE 1 | C21: Cái | D21: 2 | E21: 2 | F21: =E21 -> 2 | G21: TH2/SF-01.1,2 | H21: 20500 | I21: 400 | J21: Axial Fan/In-Line Fan/ Cabinet Fan | K21: 55 | L21: 11 | M21: 380/3/50 | N21: ≤ 65 dBA | O21: ≥ 50 % | R21: 2 | S21: Quạt hướng trục | T21: VNS-AF5-7T Động cơ ATT IE3 | U21: TH VINASUN | V21: Việt Nam | W21: 23890440 | X21: 492000 | Y21: 4053000 | Z21: =ROUND((W21+X21+Y21)*10%,-1) -> 2843540 | AA21: =ROUND((W21+X21+Y21+Z21)*7%,-1) -> 2189530 | AB21: =W21+X21+Y21+Z21+AA21 -> 33468510 | AC21: =AB21*F21 -> 66937020 | AD21: =AB21*R21 -> 66937020
A22: 11 | B22: QUẠT CẤP GIÓ TẦNG HẦM ZONE 2 | C22: Cái | D22: 1 | E22: 1 | F22: =E22 -> 1 | G22: TH2/SF-02 | H22: 39000 | I22: 400 | J22: Axial Fan/In-Line Fan/ Cabinet Fan | K22: 55 | L22: 15 | M22: 380/3/50 | N22: ≤ 65 dBA | O22: ≥ 50 % | R22: 1 | S22: Quạt hướng trục | T22: VNS-AF5-8T Động cơ ATT IE3 | U22: TH VINASUN | V22: Việt Nam | W22: 41326320 | X22: 851000 | Y22: 5040000 | Z22: =ROUND((W22+X22+Y22)*10%,-1) -> 4721730 | AA22: =ROUND((W22+X22+Y22+Z22)*7%,-1) -> 3635730 | AB22: =W22+X22+Y22+Z22+AA22 -> 55574780 | AC22: =AB22*F22 -> 55574780 | AD22: =AB22*R22 -> 55574780
B23: Tầng hầm 1
A24: 12 | B24: QUẠT HÚT PHÒNG QUẠT HÚT 1 | C24: Cái | D24: 1 | E24: 1 | F24: =E24 -> 1 | G24: TH1/EF-03 | H24: 1000 | I24: 50 | J24: Fan wall mounted | K24: 55 | L24: 0.37 | M24: 220/1/50 | N24: ≤ 65 dBA | O24: ≥ 50 % | R24: 1 | S24: Quạt gắn tường | T24: VNS-AV6-25 | U24: TH VINASUN | V24: Việt Nam | W24: 479400 | X24: 42000 | Y24: 714000 | Z24: =ROUND((W24+X24+Y24)*10%,-1) -> 123540 | AA24: =ROUND((W24+X24+Y24+Z24)*7%,-1) -> 95130 | AB24: =W24+X24+Y24+Z24+AA24 -> 1454070 | AC24: =AB24*F24 -> 1454070 | AD24: =AB24*R24 -> 1454070
A25: =A24+1 -> 13 | B25: QUẠT HÚT PHÒNG QUẠT HÚT 2 | C25: Cái | D25: 1 | E25: 1 | F25: =E25 -> 1 | G25: TH1/EF-04 | H25: 650 | I25: 25 | J25: Fan wall mounted | K25: 55 | L25: 0.37 | M25: 220/1/50 | N25: ≤ 65 dBA | O25: ≥ 50 % | R25: 1 | S25: Quạt gắn tường | T25: VNS-AV6-25 | U25: TH VINASUN | V25: Việt Nam | W25: 479400 | X25: 42000 | Y25: 714000 | Z25: =ROUND((W25+X25+Y25)*10%,-1) -> 123540 | AA25: =ROUND((W25+X25+Y25+Z25)*7%,-1) -> 95130 | AB25: =W25+X25+Y25+Z25+AA25 -> 1454070 | AC25: =AB25*F25 -> 1454070 | AD25: =AB25*R25 -> 1454070
A26: =A25+1 -> 14 | B26: QUẠT HÚT PHÒNG QUẠT HÚT 3 | C26: Cái | D26: 1 | E26: 1 | F26: =E26 -> 1 | G26: TH1/EF-05 | H26: 1000 | I26: 50 | J26: Fan wall mounted | K26: 55 | L26: 0.37 | M26: 220/1/50 | N26: ≤ 65 dBA | O26: ≥ 50 % | R26: 1 | S26: Quạt gắn tường | T26: VNS-AV6-25 | U26: TH VINASUN | V26: Việt Nam | W26: 479400 | X26: 42000 | Y26: 714000 | Z26: =ROUND((W26+X26+Y26)*10%,-1) -> 123540 | AA26: =ROUND((W26+X26+Y26+Z26)*7%,-1) -> 95130 | AB26: =W26+X26+Y26+Z26+AA26 -> 1454070 | AC26: =AB26*F26 -> 1454070 | AD26: =AB26*R26 -> 1454070
A27: =A26+1 -> 15 | B27: QUẠT HÚT PHÒNG QUẠT CẤP | C27: Cái | D27: 1 | E27: 1 | F27: =E27 -> 1 | G27: TH1/EF-06 | H27: 650 | I27: 25 | J27: Fan wall mounted | K27: 55 | L27: 0.37 | M27: 220/1/50 | N27: ≤ 65 dBA | O27: ≥ 50 % | R27: 1 | S27: Quạt gắn tường | T27: VNS-AV6-25 | U27: TH VINASUN | V27: Việt Nam | W27: 479400 | X27: 42000 | Y27: 714000 | Z27: =ROUND((W27+X27+Y27)*10%,-1) -> 123540 | AA27: =ROUND((W27+X27+Y27+Z27)*7%,-1) -> 95130 | AB27: =W27+X27+Y27+Z27+AA27 -> 1454070 | AC27: =AB27*F27 -> 1454070 | AD27: =AB27*R27 -> 1454070
A28: =A27+1 -> 16 | B28: QUẠT HÚT PHÒNG BƠM PCCC | C28: Cái | D28: 1 | E28: 1 | F28: =E28 -> 1 | G28: TH1/EF-07 | H28: 1000 | I28: 50 | J28: Fan wall mounted | K28: 55 | L28: 0.37 | M28: 220/1/50 | N28: ≤ 65 dBA | O28: ≥ 50 % | R28: 1 | S28: Quạt gắn tường | T28: VNS-AV6-25 | U28: TH VINASUN | V28: Việt Nam | W28: 479400 | X28: 42000 | Y28: 714000 | Z28: =ROUND((W28+X28+Y28)*10%,-1) -> 123540 | AA28: =ROUND((W28+X28+Y28+Z28)*7%,-1) -> 95130 | AB28: =W28+X28+Y28+Z28+AA28 -> 1454070 | AC28: =AB28*F28 -> 1454070 | AD28: =AB28*R28 -> 1454070
A29: =A28+1 -> 17 | B29: QUẠT HÚT PHÒNG HẠ THẾ | C29: Cái | D29: 1 | E29: 1 | F29: =E29 -> 1 | G29: TH1/EF-08 | H29: 3500 | I29: 50 | J29: Fan wall mounted | K29: 55 | L29: 0.55 | M29: 220/1/50 | N29: ≤ 65 dBA | O29: ≥ 50 % | R29: 1 | S29: Quạt hướng trục vuông, kt 400x400x320mm | T29: VNS-AF9-4T | U29: TH VINASUN | V29: Việt Nam | W29: 3908640 | X29: 105000 | Y29: 892500 | Z29: =ROUND((W29+X29+Y29)*10%,-1) -> 490610 | AA29: =ROUND((W29+X29+Y29+Z29)*7%,-1) -> 377770 | AB29: =W29+X29+Y29+Z29+AA29 -> 5774520 | AC29: =AB29*F29 -> 5774520 | AD29: =AB29*R29 -> 5774520
A30: =A29+1 -> 18 | B30: QUẠT HÚT PHÒNG KĨ THUẬT | C30: Cái | D30: 1 | E30: 1 | F30: =E30 -> 1 | G30: TH1/EF-09 | H30: 450 | I30: 25 | J30: Fan wall mounted | K30: 55 | L30: 0.37 | M30: 220/1/50 | N30: ≤ 65 dBA | O30: ≥ 50 % | R30: 1 | S30: Quạt gắn tường | T30: VNS-AV6-20 | U30: TH VINASUN | V30: Việt Nam | W30: 441660 | X30: 42000 | Y30: 630000 | Z30: =ROUND((W30+X30+Y30)*10%,-1) -> 111370 | AA30: =ROUND((W30+X30+Y30+Z30)*7%,-1) -> 85750 | AB30: =W30+X30+Y30+Z30+AA30 -> 1310780 | AC30: =AB30*F30 -> 1310780 | AD30: =AB30*R30 -> 1310780
A31: =A30+1 -> 19 | B31: QUẠT HÚT NHÀ ĐIỀU HÀNH XLNT | C31: Cái | D31: 1 | E31: 1 | F31: =E31 -> 1 | G31: TH1/EF-10 | H31: 450 | I31: 25 | J31: Fan wall mounted | K31: 55 | L31: 0.37 | M31: 220/1/50 | N31: ≤ 65 dBA | O31: ≥ 50 % | R31: 1 | S31: Quạt gắn tường | T31: VNS-AV6-20 | U31: TH VINASUN | V31: Việt Nam | W31: 441660 | X31: 42000 | Y31: 630000 | Z31: =ROUND((W31+X31+Y31)*10%,-1) -> 111370 | AA31: =ROUND((W31+X31+Y31+Z31)*7%,-1) -> 85750 | AB31: =W31+X31+Y31+Z31+AA31 -> 1310780 | AC31: =AB31*F31 -> 1310780 | AD31: =AB31*R31 -> 1310780
