Workbook
Name Print_Area_Reset: OFFSET(Full_Print,0,0,Last_Row)

Sheet TỔNG HỢP
E1: Mẫu số 03.1
A2: DỰ ÁN: TOÀ NHÀ HỖN HỢP HACOM MALL
A3: GÓI THẦU: CUNG CẤP VTTB VÀ THI CÔNG LẮP ĐẶT HỆ THỐNG CƠ ĐIỆN
A4: NHÀ THẦU: SEAREFICO
A6: BẢNG CHÀO GIÁ TỔNG HỢP
A8: Stt | B8: Mô tả công việc mời thầu | C8: Thành tiền | E8: Ghi chú
C9: Theo KLMT | D9: Nhà thầu chào
A10: A | B10: ĐẦU MỤC CÔNG VIỆC THEO KLMT | C10: =SUBTOTAL(9,C11:C18) -> 1.754e+11 | D10: =SUBTOTAL(9,D11:D18) -> 1.754e+11
A11: I | B11: HẠNG MỤC: ĐIỆN | C11: ='1. HT điện'!Q2731 -> 8.6074206e+10 | D11: ='1. HT điện'!R2731 -> 8.6074206e+10
A12: II | B12: HẠNG MỤC: ĐIỆN NHẸ | C12: ='2. HT điện nhẹ'!Q61 -> 1806831740 | D12: ='2. HT điện nhẹ'!R61 -> 1806831740
A13: III | B13: HẠNG MỤC: CẤP THOÁT NƯỚC | C13: ='3. HT CTN'!Q905 -> 3.4968185e+10 | D13: ='3. HT CTN'!R905 -> 3.4968185e+10
A14: IV | B14: HẠNG MỤC: HVAC | C14: =SUBTOTAL(9,C15:C17) -> 5.0616174e+10 | D14: =SUBTOTAL(9,D15:D17) -> 5.0616174e+10
A15: 4.1 | B15: ĐIỀU HÒA VRV | C15: ='4.1 ĐH VRV'!AF51 -> 1437739800 | D15: ='4.1 ĐH VRV'!AG51 -> 1437739800
A16: 4.2 | B16: QUẠT | C16: ='4.2 Quạt'!AC148 -> 4227522600 | D16: ='4.2 Quạt'!AD148 -> 4227522600
A17: 4.3 | B17: ĐIỀU HÒA KHÔNG KHÍ VÀ THÔNG GIÓ | C17: ='4.3 DHKK & TG'!Q1116 -> 4.4950912e+10 | D17: ='4.3 DHKK & TG'!R1116 -> 4.4950912e+10
A18: V | B18: HẠNG MỤC: NGĂN CHÁY LAN | C18: ='5. Ngăn cháy lan'!Q27 -> 1.9346025e+09 | D18: ='5. Ngăn cháy lan'!R27 -> 1.9346025e+09
A19: B | B19: ĐẦU MỤC CÔNG VIỆC PHÁT SINH NGOÀI KLMT | C19: =SUBTOTAL(9,C20:C20) -> 0 | D19: =SUBTOTAL(9,D20:D20) -> 0
D20: 0
A21: C | B21: TỔNG CỘNG GIÁ CHÀO TRƯỚC THUẾ: (C = A + B) (VNĐ) | C21: =SUBTOTAL(9,C11:C19) -> 1.754e+11 | D21: =SUBTOTAL(9,D11:D19) -> 1.754e+11
B22: Thuế Vat (tạm tính 10%) (VNĐ) | C22: =C21*10% -> 1.754e+10 | D22: =D21*10% -> 1.754e+10
A23: D | B23: TỔNG CỘNG GIÁ CHÀO SAU THUẾ (VNĐ) | C23: =C21+C22 -> 1.9294e+11 | D23: =D21+D22 -> 1.9294e+11
A25: Lưu ý: Đối với các vật tư/ thiết bị CĐT cung cấp nhà thầu lắp đặt. Tỷ lệ phí sẽ được thống nhất theo biểu phí đính kèm hồ sơ dự thầu

Sheet 1. HT điện
A1: Dự án: TOÀ NHÀ HỖN HỢP HACOM MALL
A2: Gói thầu: CUNG CẤP VTTB VÀ THI CÔNG LẮP ĐẶT HỆ THỐNG CƠ ĐIỆN
A3: Hạng mục: HỆ THỐNG ĐIỆN
A5: KHỐI LƯỢNG MỜI THẦU | F5: NHÀ THẦU SEAREFICO
A6: STT | B6: Diễn giải | C6: Đơn vị | D6: KL Mời thầu Lần 2 | E6: Ghi chú | F6: KL Nhà thầu chào | G6: THÔNG TIN VỀ VẬT LIỆU CHÍNH | K6: ĐƠN GIÁ (chưa bao gồm VAT) | Q6: Thành tiền BOQ | S6: Ghi chú
G7: Mô tả/ Quy cách | H7: Mã hiệu | I7: Thương hiệu | J7: Xuất xứ | K7: VL chính | L7: VL phụ | M7: NC&M | N7: CF quản lý | O7: Lợi nhuận | P7: ĐG tổng hợp | Q7: Thành tiền KLMT | R7: Thành tiền Nhà thầu chào
A8: 1 | B8: 2 | C8: 3 | D8: 4 | E8: 5 | F8: 6 | G8: 7 | H8: 8 | I8: 9 | J8: 10 | K8: 11 | L8: 12 | M8: 13 | N8: 14 | O8: 15 | P8: 16=11+12+13+14+15 | Q8: 17=4*16 | R8: 18=6*16 | S8: 19
A9: A | B9: ĐẦU MỤC CÔNG VIỆC THEO KLMT
A10: I | B10: Tủ điện hạ thế
A11: 1 | B11: Tủ điện LV-G.1+LV-G.2+LV-G.3+LV-G.4+LV-G.5+LV-G.6 | C11: Tủ | D11: 1 | F11: 1 | G11: Tủ điện LV-G.1+G.2+G.3+G.4+G.5+G.6 | H11: Form 3B, IP42 | I11: Nhà sản xuất tủ: ACIT - Á Châu Thiết bị đóng cắt: Schneider | J11: Việt Nam Châu Á | K11: 1910614577 | M11: 42500200 | P11: =+K11+L11+M11+N11+O11 -> 1953114777 | Q11: =+P11*D11 -> 1953114777 | R11: =P11*F11 -> 1953114777 | S11: Nhà thầu đính kèm bảng chi tiết tủ điện
B12: Vỏ tủ form 3B | C12: Cái | D12: 1 | G12: 0 | H12: 0 | I12: 0 | J12: 0 | K12: 0 | M12: 0 | P12: =+K12+L12+M12+N12+O12 -> 0 | Q12: =+P12*D12 -> 0 | R12: =P12*F12 -> 0 | S12: 0
B13: Đầu vào: | S13: 0
B14: ACB Fixed 4P 3200AT 3200AF 65kA , bảo vệ quá dòng, chạm đất, quá áp, thấp áp, đo lường class 1, kết nối NFC/ Bluetooth. | C14: Cái | D14: 2 | G14: 0 | H14: 0 | I14: 0 | J14: 0 | K14: 0 | M14: 0 | P14: =+K14+L14+M14+N14+O14 -> 0 | Q14: =+P14*D14 -> 0 | R14: =P14*F14 -> 0 | S14: 0
B15: Motor sạc 220VAC cho ACB Fixed 4P 3200A 65kA | C15: Cái | D15: 2 | G15: 0 | H15: 0 | I15: 0 | J15: 0 | K15: 0 | M15: 0 | P15: =+K15+L15+M15+N15+O15 -> 0 | Q15: =+P15*D15 -> 0 | R15: =P15*F15 -> 0 | S15: 0
B16: Cuộn đóng 220VAC cho ACB Fixed 4P 3200A 65kA | C16: Cái | D16: 2 | G16: 0 | H16: 0 | I16: 0 | J16: 0 | K16: 0 | M16: 0 | P16: =+K16+L16+M16+N16+O16 -> 0 | Q16: =+P16*D16 -> 0 | R16: =P16*F16 -> 0 | S16: 0
B17: Cuộn cắt 220VAC cho ACB Fixed dòng MTZ | C17: Cái | D17: 2 | G17: 0 | H17: 0 | I17: 0 | J17: 0 | K17: 0 | M17: 0 | P17: =+K17+L17+M17+N17+O17 -> 0 | Q17: =+P17*D17 -> 0 | R17: =P17*F17 -> 0 | S17: 0
B18: Cuộn UVT 220VAC cho ACB Fixed dòng MTZ | C18: Cái | D18: 2 | G18: 0 | H18: 0 | I18: 0 | J18: 0 | K18: 0 | M18: 0 | P18: =+K18+L18+M18+N18+O18 -> 0 | Q18: =+P18*D18 -> 0 | R18: =P18*F18 -> 0 | S18: 0
B19: Khóa đóng cắt ACB | C19: Cái | D19: 2 | G19: 0 | H19: 0 | I19: 0 | J19: 0 | K19: 0 | M19: 0 | P19: =+K19+L19+M19+N19+O19 -> 0 | Q19: =+P19*D19 -> 0 | R19: =P19*F19 -> 0 | S19: 0
B20: Bộ hòa đồng bộ 2 máy phát | C20: Bộ | D20: 1 | G20: 0 | H20: 0 | I20: 0 | J20: 0 | K20: 0 | M20: 0 | P20: =+K20+L20+M20+N20+O20 -> 0 | Q20: =+P20*D20 -> 0 | R20: =P20*F20 -> 0 | S20: 0
B21: Đèn báo trạng thái On/OFF/TRIP ACB | C21: Cái | D21: 6 | G21: 0 | H21: 0 | I21: 0 | J21: 0 | K21: 0 | M21: 0 | P21: =+K21+L21+M21+N21+O21 -> 0 | Q21: =+P21*D21 -> 0 | R21: =P21*F21 -> 0 | S21: 0
B22: Biến dòng hạ thế 3200/5A | C22: Quả | D22: 12 | G22: 0 | H22: 0 | I22: 0 | J22: 0 | K22: 0 | M22: 0 | P22: =+K22+L22+M22+N22+O22 -> 0 | Q22: =+P22*D22 -> 0 | R22: =P22*F22 -> 0 | S22: 0
B23: Đồng hồ Volt 0-450VAC | C23: Cái | D23: 2 | G23: 0 | H23: 0 | I23: 0 | J23: 0 | K23: 0 | M23: 0 | P23: =+K23+L23+M23+N23+O23 -> 0 | Q23: =+P23*D23 -> 0 | R23: =P23*F23 -> 0 | S23: 0
B24: Chuyển mạch Volt 7 vị trí | C24: Cái | D24: 2 | G24: 0 | H24: 0 | I24: 0 | J24: 0 | K24: 0 | M24: 0 | P24: =+K24+L24+M24+N24+O24 -> 0 | Q24: =+P24*D24 -> 0 | R24: =P24*F24 -> 0 | S24: 0
B25: Đồng hồ Ampe 0-3200A | C25: Cái | D25: 6 | G25: 0 | H25: 0 | I25: 0 | J25: 0 | K25: 0 | M25: 0 | P25: =+K25+L25+M25+N25+O25 -> 0 | Q25: =+P25*D25 -> 0 | R25: =P25*F25 -> 0 | S25: 0
... B27: Cầu chi 2A | C27: Cái | D27: 18 | G27: 0 | H27: 0 | I27: 0 | J27: 0 | K27: 0 | M27: 0 | P27: =+K27+L27+M27+N27+O27 -> 0 | Q27: =+P27*D27 -> 0 | R27: =P27*F27 -> 0 | S27: 0
B28: Đầu ra: | S28: 0
B29: ACB Fixed 4P 3000AT 3200AF 65kA | C29: Cái | D29: 1 | G29: 0 | H29: 0 | I29: 0 | J29: 0 | K29: 0 | M29: 0 | P29: =+K29+L29+M29+N29+O29 -> 0 | Q29: =+P29*D29 -> 0 | R29: =P29*F29 -> 0 | S29: 0
B30: Motor sạc 220VAC cho ACB Fixed 4P 3000AT 3200AF 65kA | C30: Cái | D30: 1 | G30: 0 | H30: 0 | I30: 0 | J30: 0 | K30: 0 | M30: 0 | P30: =+K30+L30+M30+N30+O30 -> 0 | Q30: =+P30*D30 -> 0 | R30: =P30*F30 -> 0 | S30: 0
B31: Cuộn đóng 220VAC cho ACB Fixed 4P 3000AT 3200AF 65kA | C31: Cái | D31: 1 | G31: 0 | H31: 0 | I31: 0 | J31: 0 | K31: 0 | M31: 0 | P31: =+K31+L31+M31+N31+O31 -> 0 | Q31: =+P31*D31 -> 0 | R31: =P31*F31 -> 0 | S31: 0
B32: Cuộn cắt 220VAC cho ACB Fixed dòng MTZ | C32: Cái | D32: 1 | G32: 0 | H32: 0 | I32: 0 | J32: 0 | K32: 0 | M32: 0 | P32: =+K32+L32+M32+N32+O32 -> 0 | Q32: =+P32*D32 -> 0 | R32: =P32*F32 -> 0 | S32: 0
B33: ACB 4P 1600AT 1600AF 65kA Fixed | C33: Cái | D33: 1 | G33: 0 | H33: 0 | I33: 0 | J33: 0 | K33: 0 | M33: 0 | P33: =+K33+L33+M33+N33+O33 -> 0 | Q33: =+P33*D33 -> 0 | R33: =P33*F33 -> 0 | S33: 0
B34: Motor sạc 220VAC cho ACB 4P 1600AT 1600AF 65kA Fixed | C34: Cái | D34: 1 | G34: 0 | H34: 0 | I34: 0 | J34: 0 | K34: 0 | M34: 0 | P34: =+K34+L34+M34+N34+O34 -> 0 | Q34: =+P34*D34 -> 0 | R34: =P34*F34 -> 0 | S34: 0
B35: Cuộn đóng 220VAC cho ACB 4P 1600AT 1600AF 65kA Fixed | C35: Cái | D35: 1 | G35: 0 | H35: 0 | I35: 0 | J35: 0 | K35: 0 | M35: 0 | P35: =+K35+L35+M35+N35+O35 -> 0 | Q35: =+P35*D35 -> 0 | R35: =P35*F35 -> 0 | S35: 0
B36: Cuộn cắt 220VAC cho ACB 4P 1600AT 1600AF 65kA Fixed | C36: Cái | D36: 2 | G36: 0 | H36: 0 | I36: 0 | J36: 0 | K36: 0 | M36: 0 | P36: =+K36+L36+M36+N36+O36 -> 0 | Q36: =+P36*D36 -> 0 | R36: =P36*F36 -> 0 | S36: 0
B37: Đèn báo trạng thái On/OFF/TRIP ACB | C37: Cái | D37: 6 | G37: 0 | H37: 0 | I37: 0 | J37: 0 | K37: 0 | M37: 0 | P37: =+K37+L37+M37+N37+O37 -> 0 | Q37: =+P37*D37 -> 0 | R37: =P37*F37 -> 0 | S37: 0
B38: Khóa đóng cắt ACB | C38: Cái | D38: 2 | G38: 0 | H38: 0 | I38: 0 | J38: 0 | K38: 0 | M38: 0 | P38: =+K38+L38+M38+N38+O38 -> 0 | Q38: =+P38*D38 -> 0 | R38: =P38*F38 -> 0 | S38: 0
B39: MCCB 4P 1250AT 1250AF 50kA | C39: Cái | D39: 1 | G39: 0 | H39: 0 | I39: 0 | J39: 0 | K39: 0 | M39: 0 | P39: =+K39+L39+M39+N39+O39 -> 0 | Q39: =+P39*D39 -> 0 | R39: =P39*F39 -> 0 | S39: 0
B40: Tiếp điểm báo trạng thái cho MCCB 4P 1250AT 1250AF 50kA | C40: Cái | D40: 2 | G40: 0 | H40: 0 | I40: 0 | J40: 0 | K40: 0 | M40: 0 | P40: =+K40+L40+M40+N40+O40 -> 0 | Q40: =+P40*D40 -> 0 | R40: =P40*F40 -> 0 | S40: 0
... B53: Nhân công + phụ kiện lắp đặt | C53: Tủ | D53: 1 | G53: 0 | H53: 0 | I53: 0 | J53: 0 | K53: 0 | M53: 0 | P53: =+K53+L53+M53+N53+O53 -> 0 | Q53: =+P53*D53 -> 0 | R53: =P53*F53 -> 0 | S53: 0
A54: 2 | B54: Tủ điện MSB1.7+MSB1.8+MSB1.9 | C54: Tủ | D54: 1 | F54: 1 | G54: Tủ điện MSB1.7+MSB1.8+MSB1.9 | H54: Form 3B, IP42 | I54: Nhà sản xuất tủ: ACIT - Á Châu Thiết bị đóng cắt: Schneider | J54: Việt Nam Châu Á | K54: 228249100 | M54: 8060000 | P54: =+K54+L54+M54+N54+O54 -> 236309100 | Q54: =+P54*D54 -> 236309100 | R54: =P54*F54 -> 236309100 | S54: Nhà thầu đính kèm bảng chi tiết tủ điện
...

Sheet 2. HT điện nhẹ
A1: Dự án: TOÀ NHÀ HỖN HỢP HACOM MALL
A2: Gói thầu: CUNG CẤP VTTB VÀ THI CÔNG LẮP ĐẶT HỆ THỐNG CƠ ĐIỆN
A3: Hạng mục: HỆ THỐNG ĐIỆN NHẸ
A5: KHỐI LƯỢNG MỜI THẦU | F5: NHÀ THẦU SEAREFICO
A6: Stt | B6: Diễn giải | C6: Đơn vị | D6: KL Mời thầu Lần 2 | E6: Ghi chú | F6: KL Nhà thầu chào | G6: THÔNG TIN VỀ VẬT LIỆU CHÍNH | K6: ĐƠN GIÁ (chưa bao gồm VAT) | Q6: Thành tiền BOQ | S6: Ghi chú
G7: Mô tả/ Quy cách | H7: Mã hiệu | I7: Thương hiệu | J7: Xuất xứ | K7: VL chính | L7: VL phụ | M7: NC&M | N7: CF quản lý | O7: Lợi nhuận | P7: ĐG tổng hợp | Q7: Thành tiền KLMT | R7: Thành tiền Nhà thầu chào
A8: 1 | B8: 2 | C8: 3 | D8: 4 | E8: 5 | F8: 6 | G8: 7 | H8: 8 | I8: 9 | J8: 10 | K8: 11 | L8: 12 | M8: 13 | N8: 14 | O8: 15 | P8: 16=11+12+13+14+15 | Q8: 17=4*16 | R8: 18=6*16 | S8: 19
A9: A | B9: ĐẦU MỤC CÔNG VIỆC THEO KLMT
A10: I | B10: Vật tư thiết bị đầu tư cho BQL tòa nhà
A11: 1 | B11: Ổ cắm mạng đơn 1xRJ45, bao gồm mặt và hạt | C11: Cái | D11: 10 | E11: NT chỉ cung cấp và lắp đặt đế âm | F11: 10 | G11: 0 | H11: 0 | I11: 0 | J11: 0 | K11: 7600 | M11: 38300 | P11: =+K11+L11+M11+N11+O11 -> 45900 | Q11: =+P11*D11 -> 459000 | R11: =+P11*D11 -> 459000 | S11: NT chỉ cung cấp và lắp đặt đế âm
A12: 2 | B12: Ống PVC D20 | C12: m | D12: 100 | F12: 100 | G12: Ống luồn tròn PVC - Medium duty phi 20mm - ARC20/M | H12: ARC20/M | I12: AC | J12: Việt Nam | K12: 9000 | M12: 23200 | P12: =+K12+L12+M12+N12+O12 -> 32200 | Q12: =+P12*D12 -> 3220000 | R12: =+P12*D12 -> 3220000 | S12: Ống đi nổi. Không bao gồm cắt đục, trám trét và đóng lưới hoàn thiện
A13: II | B13: PHẦN VẬT TƯ THIẾT BỊ ĐẦU TƯ CHO CĂN HỘ | D13: 0
A14: 1 | B14: Ổ cắm mạng đơn 1xRJ45, bao gồm cả mặt và hạt | C14: Cái | D14: 1109 | E14: NT chỉ cung cấp và lắp đặt đế âm | F14: 1109 | G14: 0 | H14: 0 | I14: 0 | J14: 0 | K14: 7600 | M14: 38300 | P14: =+K14+L14+M14+N14+O14 -> 45900 | Q14: =+P14*D14 -> 50903100 | R14: =+P14*D14 -> 50903100 | S14: NT chỉ cung cấp và lắp đặt đế âm
A15: 2 | B15: Ổ cắm truyền hình, bao gồm mặt cả hạt | C15: Cái | D15: 1109 | E15: NT chỉ cung cấp và lắp đặt đế âm | F15: 1109 | G15: 0 | H15: 0 | I15: 0 | J15: 0 | K15: 7600 | M15: 38300 | P15: =+K15+L15+M15+N15+O15 -> 45900 | Q15: =+P15*D15 -> 50903100 | R15: =+P15*D15 -> 50903100 | S15: NT chỉ cung cấp và lắp đặt đế âm
A16: 3 | B16: Ống PVC D20 | C16: m | D16: 15826 | F16: 15826 | G16: Ống luồn tròn PVC - Medium duty phi 20mm - ARC20/M | H16: ARC20/M | I16: AC | J16: Việt Nam | K16: 9000 | M16: 23200 | P16: =+K16+L16+M16+N16+O16 -> 32200 | Q16: =+P16*D16 -> 509597200 | R16: =+P16*D16 -> 509597200 | S16: Ống đi nổi. Không bao gồm cắt đục, trám trét và đóng lưới hoàn thiện
A17: 4 | B17: Vật tư phụ hoàn thiện toàn bộ hệ thống | C17: Lô | D17: 1 | F17: 1 | G17: 0 | H17: 0 | I17: 0 | J17: Việt Nam | K17: 0 | M17: 0 | P17: =+K17+L17+M17+N17+O17 -> 0 | Q17: =+P17*D17 -> 0 | R17: =+P17*D17 -> 0 | S17: Đã bao gồm
A18: III | B18: Thang máng cáp | D18: 0
A19: 1 | B19: Thang cáp kim loại WxH-500x100mm | C19: m | D19: 209.3 | F19: 209.3 | G19: Thang cáp kim loại WxH-500x100mm | H19: Độ dày 2.0mm, Sơn tĩnh điện | I19: BHT | J19: Việt Nam | K19: 271200 | M19: 155200 | P19: =+K19+L19+M19+N19+O19 -> 426400 | Q19: =+P19*D19 -> 89245520 | R19: =+P19*D19 -> 89245520 | S19: 0
B20: Tê nối thang cáp WxH=(500x100)mm | C20: Cái | D20: 2 | F20: 2 | G20: Tê đều thang cáp WxH=(500x100)mm | H20: Sơn tĩnh điện | I20: BHT | J20: Việt Nam | K20: 331200 | M20: 172300 | P20: =+K20+L20+M20+N20+O20 -> 503500 | Q20: =+P20*D20 -> 1007000 | R20: =+P20*D20 -> 1007000 | S20: 0
B21: Chuyển hướng ngang 90 độ thang cáp WxH=(500x100)mm | C21: Cái | D21: 8 | F21: 8 | G21: Chuyển hướng ngang 90 độ thang cáp WxH=(500x100)mm | H21: Sơn tĩnh điện | I21: BHT | J21: Việt Nam | K21: 265000 | M21: 155200 | P21: =+K21+L21+M21+N21+O21 -> 420200 | Q21: =+P21*D21 -> 3361600 | R21: =+P21*D21 -> 3361600 | S21: 0
B22: Chuyển hướng dọc 90 độ thang cáp WxH=(500x100)mm | C22: Cái | D22: 4 | F22: 4 | G22: Chuyển hướng ngang 90 độ thang cáp WxH=(500x100)mm | H22: Sơn tĩnh điện | I22: BHT | J22: Việt Nam | K22: 265000 | M22: 155200 | P22: =+K22+L22+M22+N22+O22 -> 420200 | Q22: =+P22*D22 -> 1680800 | R22: =+P22*D22 -> 1680800 | S22: 0
A23: 2 | B23: Thang cáp kim loại WxH-400x100mm | C23: m | D23: 48.8 | F23: 48.8 | G23: Thang cáp kim loại WxH-400x100mm | H23: Độ dày 2.0mm, Sơn tĩnh điện | I23: BHT | J23: Việt Nam | K23: 257300 | M23: 124000 | P23: =+K23+L23+M23+N23+O23 -> 381300 | Q23: =+P23*D23 -> 18607440 | R23: =+P23*D23 -> 18607440 | S23: 0
B24: Tê nối máng cáp WxH=(400x100)mm | C24: Cái | D24: 0 | F24: 0 | G24: Tê giảm thang cáp WxH=(400x100)mm | H24: Sơn tĩnh điện | I24: BHT | J24: Việt Nam | K24: 330000 | M24: 155200 | P24: =+K24+L24+M24+N24+O24 -> 485200 | Q24: =+P24*D24 -> 0 | R24: =+P24*D24 -> 0 | S24: 0
B25: Chuyển hướng ngang 90 độ máng cáp WxH=(400x100)mm | C25: Cái | D25: 0 | F25: 0 | G25: Chuyển hướng ngang 90 độ máng cáp WxH=(400x100)mm | H25: Sơn tĩnh điện | I25: BHT | J25: Việt Nam | K25: 762500 | M25: 158200 | P25: =+K25+L25+M25+N25+O25 -> 920700 | Q25: =+P25*D25 -> 0 | R25: =+P25*D25 -> 0 | S25: 0
B26: Chữ thập nối thang cáp WxH=(400x100)mm | C26: Cái | D26: 1 | F26: 1 | G26: Thập thang cáp WxH=(400x100)mm | H26: Sơn tĩnh điện | I26: BHT | J26: Việt Nam | K26: 395800 | M26: 193500 | P26: =+K26+L26+M26+N26+O26 -> 589300 | Q26: =+P26*D26 -> 589300 | R26: =+P26*D26 -> 589300 | S26: 0
B27: Chuyển hướng ngang 90 độ thang cáp WxH=(400x100)mm | C27: Cái | D27: 5 | F27: 5 | G27: Co lơi thang cáp WxH=(400x100)mm | H27: Sơn tĩnh điện | I27: BHT | J27: Việt Nam | K27: 194500 | M27: 124000 | P27: =+K27+L27+M27+N27+O27 -> 318500 | Q27: =+P27*D27 -> 1592500 | R27: =+P27*D27 -> 1592500 | S27: 0
B28: Chuyển hướng dọc 90 độ thang cáp WxH=(400x100)mm | C28: Cái | D28: 1 | F28: 1 | G28: Co lơi thang cáp WxH=(400x100)mm | H28: Sơn tĩnh điện | I28: BHT | J28: Việt Nam | K28: 194500 | M28: 124000 | P28: =+K28+L28+M28+N28+O28 -> 318500 | Q28: =+P28*D28 -> 318500 | R28: =+P28*D28 -> 318500 | S28: 0
A29: 3 | B29: Máng cáp kim loại WxH-200x100mm | C29: m | D29: 0 | F29: 0 | G29: Máng cáp WxH=(200x100)mm | H29: Độ dày 1.2mm, Loại đục lỗ, Sơn tĩnh điện | I29: BHT | J29: Việt Nam | K29: 344200 | M29: 120900 | P29: =+K29+L29+M29+N29+O29 -> 465100 | Q29: =+P29*D29 -> 0 | R29: =+P29*D29 -> 0 | S29: 0
B30: Chuyển hướng ngang 90 độ máng cáp WxH=(200x100)mm | C30: Cái | D30: 0 | F30: 0 | G30: Chuyển hướng ngang 90 độ máng cáp WxH=(200x100)mm | H30: Sơn tĩnh điện | I30: BHT | J30: Việt Nam | K30: 336300 | M30: 120900 | P30: =+K30+L30+M30+N30+O30 -> 457200 | Q30: =+P30*D30 -> 0 | R30: =+P30*D30 -> 0 | S30: 0
B31: Tê nối máng cáp WxH=(200x100)mm | C31: Cái | D31: 0 | F31: 0 | G31: Tê nối máng cáp WxH=(200x100)mm | H31: Sơn tĩnh điện | I31: BHT | J31: Việt Nam | K31: 420200 | M31: 130000 | P31: =+K31+L31+M31+N31+O31 -> 550200 | Q31: =+P31*D31 -> 0 | R31: =+P31*D31 -> 0 | S31: 0
A32: 4 | B32: Máng cáp kim loại WxH-200x50mm | C32: m | D32: 871.99 | F32: 871.99 | G32: Máng cáp WxH=(200x50)mm | H32: Độ dày 1.2mm, Loại đục lỗ | I32: BHT | J32: Việt Nam | K32: 290500 | M32: 120900 | P32: =+K32+L32+M32+N32+O32 -> 411400 | Q32: =+P32*D32 -> 3.5873669e+08 | R32: =+P32*D32 -> 3.5873669e+08 | S32: 0
B33: Chuyển hướng ngang 90 độ máng cáp WxH=(200x50)mm | C33: Cái | D33: 40 | F33: 40 | G33: Chuyển hướng ngang 90 độ máng cáp WxH=(200x50)mm | H33: Sơn tĩnh điện | I33: BHT | J33: Việt Nam | K33: 283800 | M33: 120900 | P33: =+K33+L33+M33+N33+O33 -> 404700 | Q33: =+P33*D33 -> 16188000 | R33: =+P33*D33 -> 16188000 | S33: 0
B34: Chuyển hướng dọc 90 độ máng cáp WxH=(200x50)mm | C34: Cái | D34: 5 | F34: 5 | G34: Chuyển hướng ngang 90 độ máng cáp WxH=(200x50)mm | H34: Sơn tĩnh điện | I34: BHT | J34: Việt Nam | K34: 283800 | M34: 120900 | P34: =+K34+L34+M34+N34+O34 -> 404700 | Q34: =+P34*D34 -> 2023500 | R34: =+P34*D34 -> 2023500 | S34: 0
B35: Tê nối máng cáp WxH=(200x50)mm | C35: Cái | D35: 26 | F35: 26 | G35: Tê nối máng cáp WxH=(200x50)mm | H35: Sơn tĩnh điện | I35: BHT | J35: Việt Nam | K35: 363300 | M35: 130000 | P35: =+K35+L35+M35+N35+O35 -> 493300 | Q35: =+P35*D35 -> 12825800 | R35: =+P35*D35 -> 12825800 | S35: 0
A36: 5 | B36: Máng cáp kim loại WxH-150x50mm | C36: m | D36: 1724.49 | F36: 1724.49 | G36: Máng cáp kim loại WxH-150x50mm | H36: Độ dày 1.0mm, Loại đục lỗ, Sơn tĩnh điện | I36: BHT | J36: Việt Nam | K36: 218700 | M36: 111900 | P36: =+K36+L36+M36+N36+O36 -> 330600 | Q36: =+P36*D36 -> 5.7011639e+08 | R36: =+P36*D36 -> 5.7011639e+08 | S36: 0
B37: Tê nối máng cáp WxH=(150x50)mm | C37: Cái | D37: 20 | F37: 20 | G37: Tê nối máng cáp WxH=(150x50)mm | H37: Sơn tĩnh điện | I37: BHT | J37: Việt Nam | K37: 267000 | M37: 120900 | P37: =+K37+L37+M37+N37+O37 -> 387900 | Q37: =+P37*D37 -> 7758000 | R37: =+P37*D37 -> 7758000 | S37: 0
B38: Chuyển hướng ngang 90 độ máng cáp WxH=(150x50)mm | C38: Cái | D38: 89 | F38: 89 | G38: Chuyển hướng ngang 90 độ máng cáp WxH=(150x50)mm | H38: Sơn tĩnh điện | I38: BHT | J38: Việt Nam | K38: 213600 | M38: 111900 | P38: =+K38+L38+M38+N38+O38 -> 325500 | Q38: =+P38*D38 -> 28969500 | R38: =+P38*D38 -> 28969500 | S38: 0
B39: Chuyển hướng dọc 90 độ máng cáp WxH=(150x50)mm | C39: Cái | D39: 19 | F39: 19 | G39: Chuyển hướng ngang 90 độ máng cáp WxH=(150x50)mm | H39: Sơn tĩnh điện | I39: BHT | J39: Việt Nam | K39: 213600 | M39: 111900 | P39: =+K39+L39+M39+N39+O39 -> 325500 | Q39: =+P39*D39 -> 6184500 | R39: =+P39*D39 -> 6184500 | S39: 0
B40: Thang cáp WxH=(400x50)mm | C40: m | D40: 66 | F40: 66 | G40: Thang cáp kim loại WxH-400x50mm | H40: 2mm, Sơn tĩnh điện | I40: BHT | J40: Việt Nam | K40: 181000 | M40: 124000 | P40: =+K40+L40+M40+N40+O40 -> 305000 | Q40: =+P40*D40 -> 20130000 | R40: =+P40*D40 -> 20130000 | S40: 0
B41: Chuyển hướng ngang 90 độ thang cáp WxH=(400x50)mm | C41: Cái | D41: 4 | F41: 4 | G41: Chuyển hướng ngang 90 độ thang cáp WxH=(400x50)mm | H41: Sơn tĩnh điện | I41: BHT | J41: Việt Nam | K41: 176800 | M41: 124000 | P41: =+K41+L41+M41+N41+O41 -> 300800 | Q41: =+P41*D41 -> 1203200 | R41: =+P41*D41 -> 1203200 | S41: 0
...

Sheet 3. HT CTN
A1: Dự án: TOÀ NHÀ HỖN HỢP HACOM MALL
A2: Gói thầu: CUNG CẤP VTTB VÀ THI CÔNG LẮP ĐẶT HỆ THỐNG CƠ ĐIỆN
A3: Hạng mục: HỆ THỐNG CẤP THOÁT NƯỚC
A5: KHỐI LƯỢNG MỜI THẦU | F5: NHÀ THẦU SEAREFICO
A6: STT | B6: Diễn giải | C6: Đơn vị | D6: KL Mời thầu Lần 2 | E6: Ghi chú | F6: KL Nhà thầu chào | G6: THÔNG TIN VỀ VẬT LIỆU CHÍNH | K6: ĐƠN GIÁ (chưa bao gồm VAT) | Q6: Thành tiền BOQ | S6: Ghi chú
G7: Mô tả/ Quy cách | H7: Mã hiệu | I7: Thương hiệu | J7: Xuất xứ | K7: VL chính | L7: VL phụ | M7: NC&M | N7: CF quản lý | O7: Lợi nhuận | P7: ĐG tổng hợp | Q7: Thành tiền KLMT | R7: Thành tiền Nhà thầu chào
A8: 1 | B8: 2 | C8: 3 | D8: 4 | F8: 6 | G8: 7 | H8: 8 | I8: 9 | J8: 10 | K8: 11 | L8: 12 | M8: 13 | N8: 14 | O8: 15 | P8: 16=11+12+13+14+15 | Q8: 17=4*16 | R8: 18=6*16 | S8: 19
A9: A | B9: ĐẦU MỤC CÔNG VIỆC THEO KLMT
A10: I | B10: Phần thiết bị + phụ kiện chính
A11: 1 | B11: Bơm thoát nước sàn hầm ( thông số 1 bơm Q=12m3/h. H=15m, N=2,5KW), ( bao gồm phụ kiện : khớp nối nhanh, xích kéo, thanh dẫn hướng…) | C11: Cụm | D11: 3 | E11: Bơm thả chìm, nguyên cụm (bao gồm 02 bơm) | F11: 3 | G11: Đơn giá 2 bơm kèm khớp nối nhanh, chưa bao gồm van và tủ điện | H11: FAG 50C 20.30/15 | I11: Wilo | J11: Trung Quốc | K11: 72682000 | M11: 4030000 | P11: =K11+L11+M11+N11+O11 -> 76712000 | Q11: =$P11*D11 -> 230136000 | R11: =$P11*F11 -> 230136000 | S11: Đơn giá 2 bơm kèm khớp nối nhanh, chưa bao gồm van và tủ điện
A12: 2 | B12: Bơm hố pít thang máy ( thông số 1 bơm Q=10m3/h. H=15m, N=1,5KW), ( bao gồm phụ kiện : khớp nối nhanh, xích kéo, thanh dẫn hướng…) | C12: Cụm | D12: 2 | E12: Bơm thả chìm, nguyên cụm (bao gồm 02 bơm) | F12: 2 | G12: Đơn giá 2 bơm kèm khớp nối nhanh, chưa bao gồm van và tủ điện | H12: FAG 50C 20.30/15 | I12: Wilo | J12: Trung Quốc | K12: 72682000 | M12: 4030000 | P12: =K12+L12+M12+N12+O12 -> 76712000 | Q12: =$P12*D12 -> 153424000 | R12: =$P12*F12 -> 153424000 | S12: Đơn giá 2 bơm kèm khớp nối nhanh, chưa bao gồm van và tủ điện
A13: 3 | B13: Bơm bể bơm trung chuyển ( thông số bơm Q=6m3/h. H=6m), ( bao gồm phụ kiện : khớp nối nhanh, xích kéo, thanh dẫn hướng…) | C13: Cụm | D13: 2 | E13: Bơm thả chìm, nguyên cụm (bao gồm 02 bơm) | F13: 2 | G13: Đơn giá 2 bơm kèm khớp nối nhanh, chưa bao gồm van và tủ điện | H13: FAG 50Z 11.14/4.5 | I13: Wilo | J13: Trung Quốc | K13: 49834000 | M13: 4030000 | P13: =K13+L13+M13+N13+O13 -> 53864000 | Q13: =$P13*D13 -> 107728000 | R13: =$P13*F13 -> 107728000 | S13: Đơn giá 2 bơm kèm khớp nối nhanh, chưa bao gồm van và tủ điện
A14: 4 | B14: Bơm cấp nước lên mái khối A ( thông số 1 bơm Q=40m3/h. H=130m, N=22KW), ( bao gồm phụ kiện ) | C14: Cụm | D14: 1 | E14: Bơm trục đứng, đa tầng cánh, nguyên cụm (bao gồm 02 bơm) | F14: 1 | G14: Đơn giá 2 bơm, chưa bao gồm cụm van và tủ điện | H14: Helix FIRST V 3608-5/25/E/KS/400-50 | I14: Wilo | J14: Trung Quốc | K14: 333200000 | M14: 8886200 | P14: =K14+L14+M14+N14+O14 -> 342086200 | Q14: =$P14*D14 -> 342086200 | R14: =$P14*F14 -> 342086200 | S14: Đơn giá 2 bơm, chưa bao gồm cụm van và tủ điện
A15: 5 | B15: Bơm cấp nước lên mái khối B ( thông số 1 bơm Q=40m3/h. H=120m, N=22KW), ( bao gồm phụ kiện ) | C15: Cụm | D15: 1 | E15: Bơm trục đứng, đa tầng cánh, nguyên cụm (bao gồm 02 bơm) | F15: 1 | G15: Đơn giá 2 bơm, chưa bao gồm cụm van và tủ điện | H15: Helix FIRST V 3607-5/25/E/KS/400-50 | I15: Wilo | J15: Trung Quốc | K15: 311780000 | M15: 8886200 | P15: =K15+L15+M15+N15+O15 -> 320666200 | Q15: =$P15*D15 -> 320666200 | R15: =$P15*F15 -> 320666200 | S15: Đơn giá 2 bơm, chưa bao gồm cụm van và tủ điện
A16: 6 | B16: Bơm biến tần tăng áp khối đế (thông số 1 bơm Q=40m3/h. H=56m,N=11KW), ( bao gồm phụ kiện ) | C16: Cụm | D16: 1 | E16: Bơm trục đứng, đa tầng cánh, nguyên cụm (bao gồm 02 bơm) | F16: 1 | G16: Bơm trục đứng đa tầng cánh bao gồm bệ, ống gom phía hút-xả bằng Inox, van đồng Miha, đồng hồ đo áp…..và các thiết bị liên quan. Thân gang Lắp ráp tại Việt Nam | H16: FIRST V 3604/2-5/16/E/S/400-50 | I16: Wilo, lắp ráp cụm cơ khí Việt Nam | J16: Trung Quốc, Việt Nam | K16: 351407000 | M16: 8886200 | P16: =K16+L16+M16+N16+O16 -> 360293200 | Q16: =$P16*D16 -> 360293200 | R16: =$P16*F16 -> 360293200 | S16: Bơm trục đứng đa tầng cánh bao gồm bệ, ống gom phía hút-xả bằng Inox, van đồng Miha, đồng hồ đo áp…..và các thiết bị liên quan. Thân gang Lắp ráp tại Việt Nam
A17: 7 | B17: Bơm biến tần tăng áp mái khối A (thông số 1 bơm Q=27m3/h. H=25m,N=3.7KW), ( bao gồm phụ kiện ) | C17: Cụm | D17: 1 | E17: Bơm trục đứng, đa tầng cánh, nguyên cụm (bao gồm 02 bơm) | F17: 1 | G17: Bơm trục ngang đơn tầng cánh bao gồm bệ, ống gom phía hút-xả bằng Inox, van đồng Miha, đồng hồ đo áp…..và các thiết bị liên quan. Lắp ráp tại Việt Nam | H17: Atmos BST 40/125-3/2-V1 | I17: Wilo, lắp ráp cụm cơ khí Việt Nam | J17: Trung Quốc, Việt Nam | K17: 132923000 | M17: 8886200 | P17: =K17+L17+M17+N17+O17 -> 141809200 | Q17: =$P17*D17 -> 141809200 | R17: =$P17*F17 -> 141809200 | S17: Bơm trục ngang đơn tầng cánh bao gồm bệ, ống gom phía hút-xả bằng Inox, van đồng Miha, đồng hồ đo áp…..và các thiết bị liên quan. Lắp ráp tại Việt Nam
A18: 8 | B18: Bơm biến tần tăng áp mái khối B (thông số 1 bơm Q=30m3/h. H=25m,N=3.7KW), ( bao gồm phụ kiện ) | C18: Cụm | D18: 1 | E18: Bơm trục đứng, đa tầng cánh, nguyên cụm (bao gồm 02 bơm) | F18: 1 | G18: Bơm trục ngang đơn tầng cánh bao gồm bệ, ống gom phía hút-xả bằng Inox, van đồng Miha, đồng hồ đo áp…..và các thiết bị liên quan. Lắp ráp tại Việt Nam | H18: Atmos BST 50/160-4/2-V2 | I18: Wilo, lắp ráp cụm cơ khí Việt Nam | J18: Trung Quốc, Việt Nam | K18: 150773000 | M18: 8886200 | P18: =K18+L18+M18+N18+O18 -> 159659200 | Q18: =$P18*D18 -> 159659200 | R18: =$P18*F18 -> 159659200 | S18: Bơm trục ngang đơn tầng cánh bao gồm bệ, ống gom phía hút-xả bằng Inox, van đồng Miha, đồng hồ đo áp…..và các thiết bị liên quan. Lắp ráp tại Việt Nam
A19: 9 | B19: Bình tích áp 500L (bao gồm đồng hồ đo áp, công tắc áp lực liên động bơm tăng áp), ( bao gồm phụ kiện) | C19: Cụm | D19: 3 | F19: 3 | G19: 0 | H19: US500461CS000000 | I19: Varem | J19: Ý | K19: 31037600 | M19: 1612000 | P19: =K19+L19+M19+N19+O19 -> 32649600 | Q19: =$P19*D19 -> 97948800 | R19: =$P19*F19 -> 97948800 | S19: 0
A20: 10 | B20: Cụm đồng hồ nước DN100 (gồm 01 đồng hồ, 02 van bướm, 01 mối nối mềm) | C20: Cụm | D20: 1 | F20: 1 | G20: 1 cụm bao gồm 1 đồng hồ 2 bướm, 1 Y lọc Vật liệu gang Loại cơ, không kết nối BMS, Lắp ngang - PN10,Van bướm DN100 PN16 ,Nối mềm DN110 PN16, SS304 | H20: WTM - 100,FSNG.16,FSSEF.16 | I20: KVS,Flowsure,Flowsure | J20: Trung Quốc, Châu Á | K20: 19055500 | M20: 1608000 | P20: =K20+L20+M20+N20+O20 -> 20663500 | Q20: =$P20*D20 -> 20663500 | R20: =$P20*F20 -> 20663500 | S20: 1 cụm bao gồm 1 đồng hồ 2 bướm, 1 Y lọc Vật liệu gang Loại cơ, không kết nối BMS, Lắp ngang - PN10,Van bướm DN100 PN16 ,Nối mềm DN110 PN16, SS304
A21: 11 | B21: Cụm đồng hồ nước DN80 (gồm 01 đồng hồ, 02 van khóa, kèm phụ kiện) | C21: Cụm | D21: 1 | F21: 1 | G21: 1 cụm bao gồm 1 đồng hồ 2 van cổng Vật liệu gang Loại cơ, không kết nối BMS, Lắp ngang,Van DN80 PN16 | H21: WTM - 80,FSNG.16 | I21: KVS,Flowsure | J21: Trung Quốc, Châu Á | K21: 12591200 | M21: 915900 | P21: =K21+L21+M21+N21+O21 -> 13507100 | Q21: =$P21*D21 -> 13507100 | R21: =$P21*F21 -> 13507100 | S21: 1 cụm bao gồm 1 đồng hồ 2 van cổng Vật liệu gang Loại cơ, không kết nối BMS, Lắp ngang,Van DN80 PN16
A22: 12 | B22: Cụm đồng hồ nước DN50 (gồm 01 đồng hồ, 02 van khóa, kèm phụ kiện) | C22: Cụm | D22: 2 | F22: 2 | G22: 1 cụm bao gồm 1 đồng hồ 2 van cổng Vật liệu gang Loại cơ, không kết nối BMS, Lắp ngang,Van DN50 PN16 | H22: MTF - 55,FSGT.16, đồng thau | I22: KVS,Flowsure | J22: Trung Quốc, Châu Á | K22: 3906700 | M22: 752700 | P22: =K22+L22+M22+N22+O22 -> 4659400 | Q22: =$P22*D22 -> 9318800 | R22: =$P22*F22 -> 9318800 | S22: 1 cụm bao gồm 1 đồng hồ 2 van cổng Vật liệu gang Loại cơ, không kết nối BMS, Lắp ngang,Van DN50 PN16
A23: 13 | B23: Cụm đồng hồ nước DN40 (gồm 01 đồng hồ, 02 van khóa, kèm phụ kiện) | C23: Cụm | D23: 5 | F23: 5 | G23: 1 cụm bao gồm 1 đồng hồ 2 van cổng Vật liệu gang Loại cơ, không kết nối BMS, Lắp ngang,Van DN40 PN16 | H23: MTM - 55,FSGT.16, đồng thau | I23: KVS,Flowsure | J23: Trung Quốc, Châu Á | K23: 2575000 | M23: 680100 | P23: =K23+L23+M23+N23+O23 -> 3255100 | Q23: =$P23*D23 -> 16275500 | R23: =$P23*F23 -> 16275500 | S23: 1 cụm bao gồm 1 đồng hồ 2 van cổng Vật liệu gang Loại cơ, không kết nối BMS, Lắp ngang,Van DN40 PN16
A24: 14 | B24: Cụm đồng hồ nước DN32 (gồm 01 đồng hồ, 02 van khóa, kèm phụ kiện) | C24: Cụm | D24: 2 | F24: 2 | G24: 1 cụm bao gồm 1 đồng hồ 2 van cổng Vật liệu gang Loại cơ, không kết nối BMS, Lắp ngang,Van DN32 PN16 | H24: MTM - 55,FSGT.16, đồng thau | I24: KVS,Flowsure | J24: Trung Quốc, Châu Á | K24: 1814000 | M24: 616600 | P24: =K24+L24+M24+N24+O24 -> 2430600 | Q24: =$P24*D24 -> 4861200 | R24: =$P24*F24 -> 4861200 | S24: 1 cụm bao gồm 1 đồng hồ 2 van cổng Vật liệu gang Loại cơ, không kết nối BMS, Lắp ngang,Van DN32 PN16
A25: 15 | B25: Cụm đồng hồ nước DN25 (gồm 01 đồng hồ, 02 van khóa, kèm phụ kiện) | C25: Cụm | D25: 6 | F25: 6 | G25: 1 cụm bao gồm 1 đồng hồ 2 van cổng Vật liệu gang Loại cơ, không kết nối BMS, Lắp ngang,Van DN25 PN16 | H25: MTM - 55,FSGT.16, đồng thau | I25: KVS,Flowsure | J25: Trung Quốc, Châu Á | K25: 1499700 | M25: 544100 | P25: =K25+L25+M25+N25+O25 -> 2043800 | Q25: =$P25*D25 -> 12262800 | R25: =$P25*F25 -> 12262800 | S25: 1 cụm bao gồm 1 đồng hồ 2 van cổng Vật liệu gang Loại cơ, không kết nối BMS, Lắp ngang,Van DN25 PN16
A26: 16 | B26: Cụm đồng hồ nước DN20 (gồm 01 đồng hồ, 02 van khóa, kèm phụ kiện) | C26: Cụm | D26: 432 | F26: 432 | G26: 1 cụm bao gồm 1 đồng hồ 2 van cổng Vật liệu gang Loại cơ, không kết nối BMS, Lắp ngang,Van cổng DN25 PN16 | H26: MTM - 55,FSGT.16, đồng thau | I26: KVS,Flowsure | J26: Trung Quốc, Châu Á | K26: 1224800 | M26: 471600 | P26: =K26+L26+M26+N26+O26 -> 1696400 | Q26: =$P26*D26 -> 732844800 | R26: =$P26*F26 -> 732844800 | S26: 1 cụm bao gồm 1 đồng hồ 2 van cổng Vật liệu gang Loại cơ, không kết nối BMS, Lắp ngang,Van cổng DN25 PN16
A27: 17 | B27: Cụm đồng hồ nước DN15 (gồm 01 đồng hồ, 02 van khóa, kèm phụ kiện) | C27: Cụm | D27: 84 | F27: 84 | G27: 1 cụm bao gồm 1 đồng hồ 2 van cổng Vật liệu gang Loại cơ, không kết nối BMS, Lắp ngang,Van cổng DN20 PN16 | H27: KVS - 402,FSGT.16, đồng thau | I27: KVS,Flowsure | J27: Trung Quốc, Châu Á | K27: 882200 | M27: 471600 | P27: =K27+L27+M27+N27+O27 -> 1353800 | Q27: =$P27*D27 -> 113719200 | R27: =$P27*F27 -> 113719200 | S27: 1 cụm bao gồm 1 đồng hồ 2 van cổng Vật liệu gang Loại cơ, không kết nối BMS, Lắp ngang,Van cổng DN20 PN16
A28: 18 | B28: Cảm biến mực nước | C28: Cái | D28: 6 | F28: 6 | G28: 0 | H28: 61F-GAP | I28: Omron | J28: Nhật/Trung Quốc | K28: 6975200 | M28: 302300 | P28: =K28+L28+M28+N28+O28 -> 7277500 | Q28: =$P28*D28 -> 43665000 | R28: =$P28*F28 -> 43665000 | S28: 0
A29: 19 | B29: Van búa nước DN80 | C29: Cái | D29: 2 | E29: PN25 | F29: 2 | G29: PN20 | H29: FSWH.20 | I29: Flowsure | J29: Trung Quốc | K29: 9923200 | M29: 244500 | P29: =K29+L29+M29+N29+O29 -> 10167700 | Q29: =$P29*D29 -> 20335400 | R29: =$P29*F29 -> 20335400 | S29: PN20
A30: 20 | B30: Van chống va xả áp lực dư DN80 | C30: Cái | D30: 2 | E30: PN25 | F30: 2 | G30: 0 | H30: FSQR.25 | I30: Flowsure | J30: Trung Quốc | K30: 23338000 | M30: 244500 | P30: =K30+L30+M30+N30+O30 -> 23582500 | Q30: =$P30*D30 -> 47165000 | R30: =$P30*F30 -> 47165000 | S30: 0
A31: 21 | B31: Van phao cơ DN100 | C31: Cái | D31: 2 | E31: PN16 | F31: 2 | G31: PN16 | H31: FSFL.16 | I31: Flowsure | J31: Trung Quốc | K31: 11397200 | M31: 310000 | P31: =K31+L31+M31+N31+O31 -> 11707200 | Q31: =$P31*D31 -> 23414400 | R31: =$P31*F31 -> 23414400 | S31: PN16
A32: 22 | B32: Van xả khí tự động DN25 | C32: Cái | D32: 9 | F32: 9 | G32: 25 Bar | H32: KVS - 870 | I32: KVS | J32: Trung Quốc | K32: 2347700 | M32: 85800 | P32: =K32+L32+M32+N32+O32 -> 2433500 | Q32: =$P32*D32 -> 21901500 | R32: =$P32*F32 -> 21901500 | S32: 25 Bar
A33: 23 | B33: Cụm van giảm áp DN100 (gồm 4 van khóa, 02 van giảm áp) | C33: Cụm | D33: 1 | E33: PN16 | F33: 1 | G33: PN16 | H33: FSNG.16,FSPR.16 | I33: Flowsure | J33: Trung Quốc | K33: 30601600 | M33: 1860000 | P33: =K33+L33+M33+N33+O33 -> 32461600 | Q33: =$P33*D33 -> 32461600 | R33: =$P33*F33 -> 32461600 | S33: PN16
A34: 24 | B34: Cụm van giảm áp DN80 (gồm 4 van khóa, 02 van giảm áp) | C34: Cụm | D34: 5 | E34: PN16 | F34: 5 | G34: 0 | H34: FSNG.16,FSPR.16 | I34: Flowsure | J34: Trung Quốc | K34: 27383100 | M34: 1466700 | P34: =K34+L34+M34+N34+O34 -> 28849800 | Q34: =$P34*D34 -> 144249000 | R34: =$P34*F34 -> 144249000 | S34: 0
A35: 25 | B35: Cảm biến áp suất | C35: Cái | D35: 2 | F35: 2 | G35: SS304+Bras | H35: 8080 +3029 | I35: Genebre | J35: Tây Ban Nha | K35: 5318200 | M35: 302300 | P35: =K35+L35+M35+N35+O35 -> 5620500 | Q35: =$P35*D35 -> 11241000 | R35: =$P35*F35 -> 11241000 | S35: SS304+Bras
A36: 26 | B36: Cửa thăm | C36: Cái | D36: 1 | F36: 1 | G36: Không thuộc phạm vi công việc của nhà thầu MEP theo RFI 02.01 | H36: 0 | I36: 0 | J36: 0 | K36: 0 | M36: 0 | P36: =K36+L36+M36+N36+O36 -> 0 | Q36: =$P36*D36 -> 0 | R36: =$P36*F36 -> 0 | S36: Không thuộc phạm vi công việc của nhà thầu MEP theo RFI 02.01
A37: 27 | B37: Cửa thăm vuông có bản lề hapulico hoặc tương đương | C37: Cái | D37: 6 | F37: 6 | G37: Không thuộc phạm vi công việc của nhà thầu MEP theo RFI 02.01 | H37: 0 | I37: 0 | J37: 0 | K37: 0 | M37: 0 | P37: =K37+L37+M37+N37+O37 -> 0 | Q37: =$P37*D37 -> 0 | R37: =$P37*F37 -> 0 | S37: Không thuộc phạm vi công việc của nhà thầu MEP theo RFI 02.01
A38: 28 | B38: Tấm ghi đậy rãnh B300, KN12,5 | C38: m | D38: 16 | F38: 16 | G38: Không thuộc phạm vi công việc của nhà thầu MEP theo RFI 02.01 | H38: 0 | I38: 0 | J38: 0 | K38: 0 | M38: 0 | P38: =K38+L38+M38+N38+O38 -> 0 | Q38: =$P38*D38 -> 0 | R38: =$P38*F38 -> 0 | S38: Không thuộc phạm vi công việc của nhà thầu MEP theo RFI 02.01
A39: 29 | B39: Bể Inox lắp ghép mái tháp B 32m3 (AxBxH=4x4x2.5) | C39: Cái | D39: 1 | F39: 1 | G39: - Dung tích bể: 32m3; - Chia ngăn: Chia 02 ngăn; - Trọng lượng: Khoảng 2.0 Tấn - Vật liệu: Inox 304; Tấm panel đáy bể dày 3.0mm dập chỏm cầu tăng cứng tại nhà máy, quy cách giống tấm thành và nóc, tấm panel thành 1(1000x500) dày 2.5mm; tấm thành 2 dày 2.0mm; tấm thàn 3 dày 1.5mm; tấm nóc bể dày 1.2mm; Sản xuất theo tiêu chuẩn Jis G4305:2012/ASTM-A240; Hệ giằng, chống trong bể V30x2.0-2.5mm. Hệ U100x45x4.0 chấn mạ kẽm nhúng nóng, lắp đặt bằng bulong mạ kẽm. - Phương pháp lắp đặt: Hàn Tig tại hiện trường.AA1033 | H39: 0 | I39: Sơn Hà | J39: Việt Nam | K39: 492148300 | M39: 12400000 | P39: =K39+L39+M39+N39+O39 -> 504548300 | Q39: =$P39*D39 -> 504548300 | R39: =$P39*F39 -> 504548300 | S39: - Dung tích bể: 32m3; - Chia ngăn: Chia 02 ngăn; - Trọng lượng: Khoảng 2.0 Tấn - Vật liệu: Inox 304; Tấm panel đáy bể dày 3.0mm dập chỏm cầu tăng cứng tại nhà máy, quy cách giống tấm thành và nóc, tấm panel thành 1(1000x500) dày 2.5mm; tấm thành 2 dày 2.0mm; tấm thàn 3 dày 1.5mm; tấm nóc bể dày 1.2mm; Sản xuất theo tiêu chuẩn Jis G4305:2012/ASTM-A240; Hệ giằng, chống trong bể V30x2.0-2.5mm. Hệ U100x45x4.0 chấn mạ kẽm nhúng nóng, lắp đặt bằng bulong mạ kẽm. - Phương pháp lắp đặt: Hàn Tig tại hiện trường.AA1033
A40: 30 | B40: Bể Inox lắp ghép mái tháp A 36m3 (AxBxH=6x3x2.5) | C40: Cái | D40: 1 | F40: 1 | G40: - Kích thước: D6,0(3,0+3,0) x R3,0 x C3 (m); - Dung tích bể: 36m3; - Chia ngăn: Chia 02 ngăn; - Trọng lượng: Khoảng 2.2 Tấn '- Vật liệu: Inox 304; Tấm panel đáy bể dày 3.0mm dập chỏm cầu tăng cứng tại nhà máy, quy cách giống tấm thành và nóc, tấm panel thành 1(1000x500) dày 2.5mm; tấm thành 2 dày 2.0mm; tấm thành 3 dày 1.5mm; tấm nóc bể dày 1.2mm; Sản xuất theo tiêu chuẩn Jis G4305:2012/ASTM-A240; Hệ giằng, chống trong bể V30x2.0-2.5mm. Hệ U100x45x4.0 chấn mạ kẽm nhúng nóng, lắp đặt bằng bulong mạ kẽm. - Phương pháp lắp đặt: Hàn Tig tại hiện trường. | H40: 0 | I40: Sơn Hà | J40: Việt Nam | K40: 520383700 | M40: 12400000 | P40: =K40+L40+M40+N40+O40 -> 532783700 | Q40: =$P40*D40 -> 532783700 | R40: =$P40*F40 -> 532783700 | S40: - Kích thước: D6,0(3,0+3,0) x R3,0 x C3 (m); - Dung tích bể: 36m3; - Chia ngăn: Chia 02 ngăn; - Trọng lượng: Khoảng 2.2 Tấn '- Vật liệu: Inox 304; Tấm panel đáy bể dày 3.0mm dập chỏm cầu tăng cứng tại nhà máy, quy cách giống tấm thành và nóc, tấm panel thành 1(1000x500) dày 2.5mm; tấm thành 2 dày 2.0mm; tấm thành 3 dày 1.5mm; tấm nóc bể dày 1.2mm; Sản xuất theo tiêu chuẩn Jis G4305:2012/ASTM-A240; Hệ giằng, chống trong bể V30x2.0-2.5mm. Hệ U100x45x4.0 chấn mạ kẽm nhúng nóng, lắp đặt bằng bulong mạ kẽm. - Phương pháp lắp đặt: Hàn Tig tại hiện trường.
A41: 31 | B41: Nắp ghi gang ga thu sàn 400x600 | C41: Cái | D41: 10 | F41: 10 | G41: Không thuộc phạm vi công việc của nhà thầu MEP theo RFI 02.01 | H41: 0 | I41: 0 | J41: 0 | K41: 0 | M41: 0 | P41: =K41+L41+M41+N41+O41 -> 0 | Q41: =$P41*D41 -> 0 | R41: =$P41*F41 -> 0 | S41: Không thuộc phạm vi công việc của nhà thầu MEP theo RFI 02.01
...

Sheet 4.1 ĐH VRV
A1: Dự án: TOÀ NHÀ HỖN HỢP HACOM MALL
A2: Gói thầu: CUNG CẤP VTTB VÀ THI CÔNG LẮP ĐẶT HỆ THỐNG CƠ ĐIỆN
A3: Hạng mục: HỆ THỐNG HVAC
A5: KHỐI LƯỢNG MỜI THẦU | U5: NHÀ THẦU SEAREFICO
A6: STT | B6: Diễn giải | C6: TẦNGH2 | D6: TẦNGH1 | E6: TẦNG1 | F6: TẦNG2 | G6: TẦNG3 | H6: TẦNG4 | I6: TẦNG5 | J6: TẦNG23 | K6: Đơn vị | L6: KL Mời thầu Lần 2 | M6: Công suất lạnh Kw | N6: Lưu lượng gió (m3/min) | O6: Cột áp (Pa) | P6: Công suất điện (W) | Q6: Điên áp (P/V/Hz) | R6: Môi chất lạnh | S6: Quy cách | T6: Ghi chú | U6: KL Nhà thầu chào | V6: THÔNG TIN VỀ VẬT LIỆU CHÍNH | Z6: ĐƠN GIÁ (chưa bao gồm VAT) | AF6: Thành tiền BOQ | AH6: Ghi chú
V7: Mô tả/ Quy cách | W7: Mã hiệu | X7: Thương hiệu | Y7: Xuất xứ | Z7: VL chính | AA7: VL phụ | AB7: NC&M | AC7: CF quản lý | AD7: Lợi nhuận | AE7: ĐG tổng hợp | AF7: Thành tiền KLMT | AG7: Thành tiền Nhà thầu chào
A8: 1 | B8: 2 | K8: 3 | L8: 4 | T8: 5 | U8: 6 | V8: 7 | W8: 8 | X8: 9 | Y8: 10 | Z8: 11 | AA8: 12 | AB8: 13 | AC8: 14 | AD8: 15 | AE8: 16=11+12+13+14+15 | AF8: 17=4*16 | AG8: 18=6*16 | AH8: 19
A9: A | B9: ĐẦU MỤC CÔNG VIỆC THEO KLMT
B10: THIẾT BỊ ĐIỀU HOÀ KHÔNG KHÍ
A11: I. THIẾT BỊ ĐIỀU HÒA VRV (VRF)
A12: 1. DÀN LẠNH ĐIỀU HÒA VRV, VRF | K12: Wilo
A13: 1 | B13: Dàn lạnh 1 chiều lạnh loại âm trần nối ống gió | I13: 1 | K13: cái | L13: 1 | M13: 4.5 | N13: 16/13/11 | O13: 50-200 | P13: 151 | Q13: 1P/220/50 | R13: R410A | S13: Đồng bộ với dàn nóng kèm điều khiển từ xa loại có dây | T13: Nhà thầu lắp đặt, CĐT cấp thiết bị | U13: 1 | V13: 0 | W13: 0 | X13: 0 | Y13: 0 | Z13: 1358900 | AB13: 1162700 | AE13: =Z13+AA13+AB13+AC13+AD13 -> 2521600 | AF13: =$AE13*L13 -> 2521600 | AG13: =$AE13*U13 -> 2521600 | AH13: Nhà thầu lắp đặt, CĐT cấp thiết bị Bao gồm giá vật tư phụ lắp đặt
A14: 2 | B14: Dàn lạnh 1 chiều lạnh loại âm trần nối ống gió | E14: 1 | F14: 4 | G14: 2 | H14: 8 | I14: 3 | K14: cái | L14: 18 | M14: 5.6 | N14: 18/16,5/15 | O14: 50-200 | P14: 128 | Q14: 1P/220/50 | R14: R410A | S14: Đồng bộ với dàn nóng kèm điều khiển từ xa loại có dây | U14: 18 | V14: 0 | W14: 0 | X14: 0 | Y14: 0 | Z14: 1358900 | AB14: 1162700 | AE14: =Z14+AA14+AB14+AC14+AD14 -> 2521600 | AF14: =$AE14*L14 -> 45388800 | AG14: =$AE14*U14 -> 45388800 | AH14: Nhà thầu lắp đặt, CĐT cấp thiết bị Bao gồm giá vật tư phụ lắp đặt
A15: 3 | B15: Dàn lạnh 1 chiều lạnh loại âm trần nối ống gió | E15: 6 | F15: 7 | G15: 2 | I15: 6 | K15: cái | L15: 20 | M15: 7.1 | N15: 19.5/17.5/16 | O15: 50-200 | P15: 138 | Q15: 1P/220/50 | R15: R410A | S15: Đồng bộ với dàn nóng kèm điều khiển từ xa loại có dây | U15: 20 | V15: 0 | W15: 0 | X15: 0 | Y15: 0 | Z15: 1358900 | AB15: 1162700 | AE15: =Z15+AA15+AB15+AC15+AD15 -> 2521600 | AF15: =$AE15*L15 -> 50432000 | AG15: =$AE15*U15 -> 50432000 | AH15: Nhà thầu lắp đặt, CĐT cấp thiết bị Bao gồm giá vật tư phụ lắp đặt
A16: 4 | B16: Dàn lạnh 1 chiều lạnh loại âm trần nối ống gió | E16: 2 | F16: 11 | G16: 7 | H16: 8 | I16: 8 | K16: cái | L16: 34 | M16: 9 | N16: 25/22,2/20 | O16: 50-200 | P16: 185 | Q16: 1P/220/50 | R16: R410A | S16: Đồng bộ với dàn nóng kèm điều khiển từ xa loại có dây | U16: 34 | V16: 0 | W16: 0 | X16: 0 | Y16: 0 | Z16: 1358900 | AB16: 1348100 | AE16: =Z16+AA16+AB16+AC16+AD16 -> 2707000 | AF16: =$AE16*L16 -> 92038000 | AG16: =$AE16*U16 -> 92038000 | AH16: Nhà thầu lắp đặt, CĐT cấp thiết bị Bao gồm giá vật tư phụ lắp đặt
A17: 5 | B17: Dàn lạnh 1 chiều lạnh loại âm trần nối ống gió | E17: 8 | F17: 10 | G17: 16 | H17: 13 | I17: 3 | K17: cái | L17: 51 | M17: 11.2 | N17: 32/27/23 | O17: 50-200 | P17: 215 | Q17: 1P/220/50 | R17: R410A | S17: Đồng bộ với dàn nóng kèm điều khiển từ xa loại có dây | U17: 51 | V17: 0 | W17: 0 | X17: 0 | Y17: 0 | Z17: 1358900 | AB17: 1348100 | AE17: =Z17+AA17+AB17+AC17+AD17 -> 2707000 | AF17: =$AE17*L17 -> 138057000 | AG17: =$AE17*U17 -> 138057000 | AH17: Nhà thầu lắp đặt, CĐT cấp thiết bị Bao gồm giá vật tư phụ lắp đặt
A18: 6 | B18: Dàn lạnh 1 chiều lạnh loại âm trần nối ống gió | E18: 1 | F18: 4 | G18: 4 | H18: 4 | I18: 2 | K18: cái | L18: 16 | M18: 14 | N18: 39/33/28 | O18: 50-200 | P18: 284 | Q18: 1P/220/50 | R18: R410A | S18: Đồng bộ với dàn nóng kèm điều khiển từ xa loại có dây | U18: 16 | V18: 0 | W18: 0 | X18: 0 | Y18: 0 | Z18: 1358900 | AB18: 1348100 | AE18: =Z18+AA18+AB18+AC18+AD18 -> 2707000 | AF18: =$AE18*L18 -> 43312000 | AG18: =$AE18*U18 -> 43312000 | AH18: Nhà thầu lắp đặt, CĐT cấp thiết bị Bao gồm giá vật tư phụ lắp đặt
A19: 7 | B19: Dàn lạnh 1 chiều lạnh loại âm trần nối ống gió | E19: 1 | F19: 21 | G19: 28 | H19: 19 | I19: 17 | K19: cái | L19: 85 | M19: 16 | N19: 16/39/32 | O19: 50-200 | P19: 405 | Q19: 1P/220/50 | R19: R410A | S19: Đồng bộ với dàn nóng kèm điều khiển từ xa loại có dây | U19: 85 | V19: 0 | W19: 0 | X19: 0 | Y19: 0 | Z19: 1358900 | AB19: 1983800 | AE19: =Z19+AA19+AB19+AC19+AD19 -> 3342700 | AF19: =$AE19*L19 -> 284129500 | AG19: =$AE19*U19 -> 284129500 | AH19: Nhà thầu lắp đặt, CĐT cấp thiết bị Bao gồm giá vật tư phụ lắp đặt
A20: 8 | B20: Dàn lạnh 1 chiều lạnh loại âm trần nối ống gió | E20: 8 | I20: 6 | K20: cái | L20: 14 | M20: 22.4 | N20: 16/39/32 | O20: 50-200 | P20: 405 | Q20: 1P/220/50 | R20: R410A | S20: Đồng bộ với dàn nóng kèm điều khiển từ xa loại có dây | U20: 14 | V20: 0 | W20: 0 | X20: 0 | Y20: 0 | Z20: 1358900 | AB20: 1983800 | AE20: =Z20+AA20+AB20+AC20+AD20 -> 3342700 | AF20: =$AE20*L20 -> 46797800 | AG20: =$AE20*U20 -> 46797800 | AH20: Nhà thầu lắp đặt, CĐT cấp thiết bị Bao gồm giá vật tư phụ lắp đặt
A21: 9 | B21: Dàn lạnh 1 chiều lạnh loại treo tường | I21: 1 | K21: cái | L21: 1 | M21: 2.2 | N21: 16/39/32 | O21: 50-200 | P21: 405 | Q21: 1P/220/50 | R21: R410A | S21: Đồng bộ với dàn nóng kèm điều khiển từ xa loại có dây | U21: 1 | V21: 0 | W21: 0 | X21: 0 | Y21: 0 | Z21: 76000 | AB21: 1004500 | AE21: =Z21+AA21+AB21+AC21+AD21 -> 1080500 | AF21: =$AE21*L21 -> 1080500 | AG21: =$AE21*U21 -> 1080500 | AH21: Nhà thầu lắp đặt, CĐT cấp thiết bị Bao gồm giá vật tư phụ lắp đặt
A22: 10 | B22: Dàn lạnh 1 chiều lạnh loại cassette âm trần | I22: 1 | K22: cái | L22: 1 | M22: 2.2 | N22: 9,5/8/7 | O22: 50-200 | P22: 60 | Q22: 1P/220/50 | R22: R410A | S22: Đồng bộ với dàn nóng kèm điều khiển từ xa loại có dây | U22: 1 | V22: 0 | W22: 0 | X22: 0 | Y22: 0 | Z22: 288800 | AB22: 1004500 | AE22: =Z22+AA22+AB22+AC22+AD22 -> 1293300 | AF22: =$AE22*L22 -> 1293300 | AG22: =$AE22*U22 -> 1293300 | AH22: Nhà thầu lắp đặt, CĐT cấp thiết bị Bao gồm giá vật tư phụ lắp đặt
A23: 11 | B23: Dàn lạnh 1 chiều lạnh loại cassette âm trần | I23: 1 | K23: cái | L23: 1 | M23: 7.1 | N23: 16/39/32 | O23: 50-200 | P23: 405 | Q23: 1P/220/50 | R23: R410A | S23: Đồng bộ với dàn nóng kèm điều khiển từ xa loại có dây | U23: 1 | V23: 0 | W23: 0 | X23: 0 | Y23: 0 | Z23: 288800 | AB23: 1162700 | AE23: =Z23+AA23+AB23+AC23+AD23 -> 1451500 | AF23: =$AE23*L23 -> 1451500 | AG23: =$AE23*U23 -> 1451500 | AH23: Nhà thầu lắp đặt, CĐT cấp thiết bị Bao gồm giá vật tư phụ lắp đặt
A24: 12 | B24: Dàn lạnh 1 chiều lạnh loại cassette âm trần | I24: 2 | K24: cái | L24: 2 | M24: 14 | N24: 16/39/32 | O24: 50-200 | P24: 405 | Q24: 1P/220/50 | R24: R410A | S24: Đồng bộ với dàn nóng kèm điều khiển từ xa loại có dây | U24: 2 | V24: 0 | W24: 0 | X24: 0 | Y24: 0 | Z24: 288800 | AB24: 1348100 | AE24: =Z24+AA24+AB24+AC24+AD24 -> 1636900 | AF24: =$AE24*L24 -> 3273800 | AG24: =$AE24*U24 -> 3273800 | AH24: Nhà thầu lắp đặt, CĐT cấp thiết bị Bao gồm giá vật tư phụ lắp đặt
A25: 2. DÀN NÓNG ĐIỀU HÒA VRV, VRF | U25: 0 | V25: 0 | W25: 0 | X25: 0 | Y25: 0 | Z25: 0 | AB25: 0 | AE25: =Z25+AA25+AB25+AC25+AD25 -> 0 | AF25: =$AE25*L25 -> 0 | AG25: =$AE25*U25 -> 0 | AH25: Nhà thầu lắp đặt, CĐT cấp thiết bị Bao gồm giá vật tư phụ lắp đặt
A26: 1 | B26: Dàn nóng 1 chiều lạnh (22HP). | E26: 1 | K26: cái | L26: 1 | M26: 61.5 | N26: -- | O26: -- | P26: 16100 | Q26: 3P/380/50 | R26: R410A | S26: Trọn bộ | T26: Nhà thầu lắp đặt, CĐT cấp thiết bị | U26: 1 | V26: 0 | W26: 0 | X26: 0 | Y26: 0 | Z26: 608000 | AB26: 14438500 | AE26: =Z26+AA26+AB26+AC26+AD26 -> 15046500 | AF26: =$AE26*L26 -> 15046500 | AG26: =$AE26*U26 -> 15046500 | AH26: Nhà thầu lắp đặt, CĐT cấp thiết bị Bao gồm giá vật tư phụ lắp đặt
A27: 2 | B27: Dàn nóng 1 chiều lạnh (24HP). | E27: 1 | K27: cái | L27: 1 | M27: 67 | N27: -- | O27: -- | P27: 17800 | Q27: 3P/380/50 | R27: R410A | S27: Trọn bộ | U27: 1 | V27: 0 | W27: 0 | X27: 0 | Y27: 0 | Z27: 608000 | AB27: 17538600 | AE27: =Z27+AA27+AB27+AC27+AD27 -> 18146600 | AF27: =$AE27*L27 -> 18146600 | AG27: =$AE27*U27 -> 18146600 | AH27: Nhà thầu lắp đặt, CĐT cấp thiết bị Bao gồm giá vật tư phụ lắp đặt
A28: 3 | B28: Dàn nóng 1 chiều lạnh (26HP). | E28: 1 | K28: cái | L28: 1 | M28: 73.5 | N28: -- | O28: -- | P28: 19900 | Q28: 3P/380/50 | R28: R410A | S28: Trọn bộ | U28: 1 | V28: 0 | W28: 0 | X28: 0 | Y28: 0 | Z28: 608000 | AB28: 18995500 | AE28: =Z28+AA28+AB28+AC28+AD28 -> 19603500 | AF28: =$AE28*L28 -> 19603500 | AG28: =$AE28*U28 -> 19603500 | AH28: Nhà thầu lắp đặt, CĐT cấp thiết bị Bao gồm giá vật tư phụ lắp đặt
A29: 4 | B29: Dàn nóng 1 chiều lạnh (32HP). | H29: 1 | K29: cái | L29: 1 | M29: 90 | N29: -- | O29: -- | P29: 25800 | Q29: 3P/380/50 | R29: R410A | S29: Trọn bộ | U29: 1 | V29: 0 | W29: 0 | X29: 0 | Y29: 0 | Z29: 608000 | AB29: 20115400 | AE29: =Z29+AA29+AB29+AC29+AD29 -> 20723400 | AF29: =$AE29*L29 -> 20723400 | AG29: =$AE29*U29 -> 20723400 | AH29: Nhà thầu lắp đặt, CĐT cấp thiết bị Bao gồm giá vật tư phụ lắp đặt
A30: 5 | B30: Dàn nóng 1 chiều lạnh (34HP). | I30: 1 | K30: cái | L30: 1 | M30: 95 | N30: -- | O30: -- | P30: 28200 | Q30: 3P/380/50 | R30: R410A | S30: Trọn bộ | U30: 1 | V30: 0 | W30: 0 | X30: 0 | Y30: 0 | Z30: 608000 | AB30: 21638200 | AE30: =Z30+AA30+AB30+AC30+AD30 -> 22246200 | AF30: =$AE30*L30 -> 22246200 | AG30: =$AE30*U30 -> 22246200 | AH30: Nhà thầu lắp đặt, CĐT cấp thiết bị Bao gồm giá vật tư phụ lắp đặt
A31: 6 | B31: Dàn nóng 1 chiều lạnh (36HP). | H31: 2 | K31: cái | L31: 2 | M31: 101 | N31: -- | O31: -- | P31: 30600 | Q31: 3P/380/50 | R31: R410A | S31: Trọn bộ | U31: 2 | V31: 0 | W31: 0 | X31: 0 | Y31: 0 | Z31: 608000 | AB31: 21638200 | AE31: =Z31+AA31+AB31+AC31+AD31 -> 22246200 | AF31: =$AE31*L31 -> 44492400 | AG31: =$AE31*U31 -> 44492400 | AH31: Nhà thầu lắp đặt, CĐT cấp thiết bị Bao gồm giá vật tư phụ lắp đặt
A32: 7 | B32: Dàn nóng 1 chiều lạnh (38HP). | H32: 1 | I32: 1 | K32: cái | L32: 2 | M32: 106 | N32: -- | O32: -- | P32: 33000 | Q32: 3P/380/50 | R32: R410A | S32: Trọn bộ | U32: 2 | V32: 0 | W32: 0 | X32: 0 | Y32: 0 | Z32: 608000 | AB32: 22033500 | AE32: =Z32+AA32+AB32+AC32+AD32 -> 22641500 | AF32: =$AE32*L32 -> 45283000 | AG32: =$AE32*U32 -> 45283000 | AH32: Nhà thầu lắp đặt, CĐT cấp thiết bị Bao gồm giá vật tư phụ lắp đặt
A33: 8 | B33: Dàn nóng 1 chiều lạnh (40HP). | F33: 1 | G33: 1 | K33: cái | L33: 2 | M33: 112 | N33: -- | O33: -- | P33: 35400 | Q33: 3P/380/50 | R33: R410A | S33: Trọn bộ | U33: 2 | V33: 0 | W33: 0 | X33: 0 | Y33: 0 | Z33: 608000 | AB33: 22428700 | AE33: =Z33+AA33+AB33+AC33+AD33 -> 23036700 | AF33: =$AE33*L33 -> 46073400 | AG33: =$AE33*U33 -> 46073400 | AH33: Nhà thầu lắp đặt, CĐT cấp thiết bị Bao gồm giá vật tư phụ lắp đặt
A34: 9 | B34: Dàn nóng 1 chiều lạnh (42HP). | F34: 1 | H34: 1 | K34: cái | L34: 2 | M34: 117 | N34: -- | O34: -- | P34: 32700 | Q34: 3P/380/50 | R34: R410A | S34: Trọn bộ | U34: 2 | V34: 0 | W34: 0 | X34: 0 | Y34: 0 | Z34: 912000 | AB34: 28357700 | AE34: =Z34+AA34+AB34+AC34+AD34 -> 29269700 | AF34: =$AE34*L34 -> 58539400 | AG34: =$AE34*U34 -> 58539400 | AH34: Nhà thầu lắp đặt, CĐT cấp thiết bị Bao gồm giá vật tư phụ lắp đặt
A35: 10 | B35: Dàn nóng 1 chiều lạnh (44HP). | F35: 1 | K35: cái | L35: 1 | M35: 123 | N35: -- | O35: -- | P35: 35100 | Q35: 3P/380/50 | R35: R410A | S35: Trọn bộ | U35: 1 | V35: 0 | W35: 0 | X35: 0 | Y35: 0 | Z35: 912000 | AB35: 28752900 | AE35: =Z35+AA35+AB35+AC35+AD35 -> 29664900 | AF35: =$AE35*L35 -> 29664900 | AG35: =$AE35*U35 -> 29664900 | AH35: Nhà thầu lắp đặt, CĐT cấp thiết bị Bao gồm giá vật tư phụ lắp đặt
A36: 11 | B36: Dàn nóng 1 chiều lạnh (46HP). | H36: 1 | K36: cái | L36: 1 | M36: 145 | N36: -- | O36: -- | P36: 36500 | Q36: 3P/380/50 | R36: R410A | S36: Trọn bộ | U36: 1 | V36: 0 | W36: 0 | X36: 0 | Y36: 0 | Z36: 912000 | AB36: 30341600 | AE36: =Z36+AA36+AB36+AC36+AD36 -> 31253600 | AF36: =$AE36*L36 -> 31253600 | AG36: =$AE36*U36 -> 31253600 | AH36: Nhà thầu lắp đặt, CĐT cấp thiết bị Bao gồm giá vật tư phụ lắp đặt
A37: 12 | B37: Dàn nóng 1 chiều lạnh (50HP). | I37: 2 | K37: cái | L37: 2 | M37: 140 | N37: -- | O37: -- | P37: 41100 | Q37: 3P/380/50 | R37: R410A | S37: Trọn bộ | U37: 2 | V37: 0 | W37: 0 | X37: 0 | Y37: 0 | Z37: 912000 | AB37: 30934500 | AE37: =Z37+AA37+AB37+AC37+AD37 -> 31846500 | AF37: =$AE37*L37 -> 63693000 | AG37: =$AE37*U37 -> 63693000 | AH37: Nhà thầu lắp đặt, CĐT cấp thiết bị Bao gồm giá vật tư phụ lắp đặt
A38: 13 | B38: Dàn nóng 1 chiều lạnh (58HP). | E38: 1 | K38: cái | L38: 1 | M38: 162 | N38: -- | O38: -- | P38: 50700 | Q38: 3P/380/50 | R38: R410A | S38: Trọn bộ | U38: 1 | V38: 0 | W38: 0 | X38: 0 | Y38: 0 | Z38: 912000 | AB38: 33247800 | AE38: =Z38+AA38+AB38+AC38+AD38 -> 34159800 | AF38: =$AE38*L38 -> 34159800 | AG38: =$AE38*U38 -> 34159800 | AH38: Nhà thầu lắp đặt, CĐT cấp thiết bị Bao gồm giá vật tư phụ lắp đặt
A39: 14 | B39: Dàn nóng 1 chiều lạnh (60HP). | F39: 2 | G39: 4 | I39: 1 | K39: cái | L39: 7 | M39: 158 | N39: -- | O39: -- | P39: 53100 | Q39: 3P/380/50 | R39: R410A | S39: Trọn bộ | U39: 7 | V39: 0 | W39: 0 | X39: 0 | Y39: 0 | Z39: 912000 | AB39: 33643000 | AE39: =Z39+AA39+AB39+AC39+AD39 -> 34555000 | AF39: =$AE39*L39 -> 241885000 | AG39: =$AE39*U39 -> 241885000 | AH39: Nhà thầu lắp đặt, CĐT cấp thiết bị Bao gồm giá vật tư phụ lắp đặt
A40: II. THIẾT BỊ ĐIỀU HÒA CỤC BỘ | U40: 0 | V40: 0 | W40: 0 | X40: 0 | Y40: 0 | Z40: 0 | AB40: 0 | AE40: =Z40+AA40+AB40+AC40+AD40 -> 0 | AF40: =$AE40*L40 -> 0 | AG40: =$AE40*U40 -> 0 | AH40: Nhà thầu lắp đặt, CĐT cấp thiết bị Bao gồm giá vật tư phụ lắp đặt
A41: 1. HỆ THỐNG ĐIỀU HÒA CỤC BỘ | U41: 0 | V41: 0 | W41: 0 | X41: 0 | Y41: 0 | Z41: 0 | AB41: 0 | AE41: =Z41+AA41+AB41+AC41+AD41 -> 0 | AF41: =$AE41*L41 -> 0 | AG41: =$AE41*U41 -> 0 | AH41: Nhà thầu lắp đặt, CĐT cấp thiết bị Bao gồm giá vật tư phụ lắp đặt
...

Sheet 4.2 Quạt
A1: Dự án: TOÀ NHÀ HỖN HỢP HACOM MALL
A2: Gói thầu: CUNG CẤP VTTB VÀ THI CÔNG LẮP ĐẶT HỆ THỐNG CƠ ĐIỆN
A3: Hạng mục: HỆ THỐNG HVAC
A5: KHỐI LƯỢNG MỜI THẦU | R5: NHÀ THẦU SEAREFICO
A6: STT | B6: DANH MỤC QUẠT THÔNG GIÓ | C6: Đơn vị | D6: KL Mời thầu Lần 1 | E6: KL BIM | F6: KL Mời thầu Lần 2 | G6: KÍ HIỆU | H6: LƯU LƯỢNG | I6: CỘP ÁP | J6: QUY CÁCH | K6: NHIỆT ĐỘ LÀM VIỆC | L6: CÔNG SUẤT ĐIỆN | M6: NGUỒN ĐIỆN | N6: ĐỘ ỒN | O6: HIỆU SUẤT | P6: Tốc độ vòng quay | Q6: GHI CHÚ | R6: KL Nhà thầu chào | S6: THÔNG TIN VỀ VẬT LIỆU CHÍNH | W6: ĐƠN GIÁ (chưa bao gồm VAT) | AC6: Thành tiền BOQ | AE6: Ghi chú
I7: Pa | K7: oC | L7: kW | M7: V/Ph/Hz | N7: dBA @ 3M | S7: Mô tả/ Quy cách | T7: Mã hiệu | U7: Thương hiệu | V7: Xuất xứ | W7: VL chính | X7: VL phụ | Y7: NC&M | Z7: CF quản lý | AA7: Lợi nhuận | AB7: ĐG tổng hợp | AC7: Thành tiền KLMT | AD7: Thành tiền Nhà thầu chào
A8: 1 | B8: 2 | C8: 3 | F8: 4 | Q8: 5 | R8: 6 | S8: 7 | T8: 8 | U8: 9 | V8: 10 | W8: 11 | X8: 12 | Y8: 13 | Z8: 14 | AA8: 15 | AB8: 16=11+12+13+14+15 | AC8: 17=4*16 | AD8: 18=6*16 | AE8: 19
A9: A | B9: ĐẦU MỤC CÔNG VIỆC THEO KLMT
A10: I | B10: QUẠT THÔNG GIÓ CẤP, HÚT
B11: QUẠT THÔNG GIÓ CẤP, HÚT TẦNG HẦM - TUM
B12: Tầng hầm 2
A13: 1 | B13: QUẠT HÚT PHÒNG QUẠT HÚT 1 | C13: Cái | D13: 1 | E13: 1 | F13: =E13 -> 1 | G13: TH2/EF-03 | H13: 650 | I13: 25 | J13: Fan wall mounted | K13: 55 | L13: 0.37 | M13: 220/1/50 | N13: ≤ 65 dBA | O13: ≥ 50 % | P13: ≤ 2900 rpm | R13: 1 | S13: VNS-AV6-25 | T13: Quạt gắn tường | U13: TH Vinasun | V13: Việt Nam | W13: 591600 | Y13: 852400 | AB13: =+W13+X13+Y13+Z13+AA13 -> 1444000 | AC13: =+AB13*F13 -> 1444000 | AD13: =+AB13*R13 -> 1444000 | AE13: Lưu lượng: 650m3/h, Cột áp: 25Pa
A14: 2 | B14: QUẠT HÚT PHÒNG QUẠT HÚT 2 | C14: Cái | D14: 1 | E14: 1 | F14: =E14 -> 1 | G14: TH2/EF-04 | H14: 650 | I14: 25 | J14: Fan wall mounted | K14: 55 | L14: 0.37 | M14: 220/1/50 | N14: ≤ 65 dBA | O14: ≥ 50 % | P14: ≤ 2900 rpm | R14: 1 | S14: VNS-AV6-25 | T14: Quạt gắn tường | U14: TH Vinasun | V14: Việt Nam | W14: 591600 | Y14: 852400 | AB14: =+W14+X14+Y14+Z14+AA14 -> 1444000 | AC14: =+AB14*F14 -> 1444000 | AD14: =+AB14*R14 -> 1444000 | AE14: Lưu lượng: 650m3/h, Cột áp: 25Pa
A15: 3 | B15: QUẠT HÚT PHÒNG QUẠT HÚT 3 | C15: Cái | D15: 1 | E15: 1 | F15: =E15 -> 1 | G15: TH2/EF-05 | H15: 1000 | I15: 50 | J15: Fan wall mounted | K15: 55 | L15: 0.37 | M15: 220/1/50 | N15: ≤ 65 dBA | O15: ≥ 50 % | P15: ≤ 2900 rpm | R15: 1 | S15: VNS-AV6-25 | T15: Quạt gắn tường | U15: TH Vinasun | V15: Việt Nam | W15: 591600 | Y15: 1317900 | AB15: =+W15+X15+Y15+Z15+AA15 -> 1909500 | AC15: =+AB15*F15 -> 1909500 | AD15: =+AB15*R15 -> 1909500 | AE15: Lưu lượng: 1000m3/h, Cột áp: 50Pa
A16: 4 | B16: QUẠT HÚT PHÒNG QUẠT CẤP | C16: Cái | D16: 1 | E16: 1 | F16: =E16 -> 1 | G16: TH2/EF-06 | H16: 650 | I16: 25 | J16: Fan wall mounted | K16: 55 | L16: 0.37 | M16: 220/1/50 | N16: ≤ 65 dBA | O16: ≥ 50 % | P16: ≤ 2900 rpm | R16: 1 | S16: VNS-AV6-25 | T16: Quạt gắn tường | U16: TH Vinasun | V16: Việt Nam | W16: 591600 | Y16: 852400 | AB16: =+W16+X16+Y16+Z16+AA16 -> 1444000 | AC16: =+AB16*F16 -> 1444000 | AD16: =+AB16*R16 -> 1444000 | AE16: Lưu lượng: 650m3/h, Cột áp: 25Pa
A17: 6 | B17: QUẠT HÚT KHO 1 | C17: Cái | D17: 1 | E17: 1 | F17: =E17 -> 1 | G17: TH2/EF-08 | H17: 650 | I17: 25 | J17: Fan wall mounted | K17: 55 | L17: 0.37 | M17: 220/1/50 | N17: ≤ 65 dBA | O17: ≥ 50 % | P17: ≤ 2900 rpm | R17: 1 | S17: VNS-AV6-25 | T17: Quạt gắn tường | U17: TH Vinasun | V17: Việt Nam | W17: 591600 | Y17: 852400 | AB17: =+W17+X17+Y17+Z17+AA17 -> 1444000 | AC17: =+AB17*F17 -> 1444000 | AD17: =+AB17*R17 -> 1444000 | AE17: Lưu lượng: 650m3/h, Cột áp: 25Pa
A18: 7 | B18: QUẠT HÚT KHO 2 | C18: Cái | D18: 1 | E18: 1 | F18: =E18 -> 1 | G18: TH2/EF-09 | H18: 250 | I18: 20 | J18: Fan wall mounted | K18: 55 | L18: 0.37 | M18: 220/1/50 | N18: ≤ 65 dBA | O18: ≥ 50 % | P18: ≤ 1450 rpm | R18: 1 | S18: VNS-AV6-15 | T18: Quạt gắn tường | U18: TH Vinasun | V18: Việt Nam | W18: 496600 | Y18: 852400 | AB18: =+W18+X18+Y18+Z18+AA18 -> 1349000 | AC18: =+AB18*F18 -> 1349000 | AD18: =+AB18*R18 -> 1349000 | AE18: Lưu lượng: 250m3/h, Cột áp: 20Pa
A19: 8 | B19: QUẠT HÚT KHO 3 | C19: Cái | D19: 1 | E19: 1 | F19: =E19 -> 1 | G19: TH2/EF-10 | H19: 350 | I19: 25 | J19: Fan wall mounted | K19: 55 | L19: 0.37 | M19: 220/1/50 | N19: ≤ 65 dBA | O19: ≥ 50 % | P19: ≤ 1450 rpm | R19: 1 | S19: VNS-AV6-20 | T19: Quạt gắn tường | U19: TH Vinasun | V19: Việt Nam | W19: 550900 | Y19: 852400 | AB19: =+W19+X19+Y19+Z19+AA19 -> 1403300 | AC19: =+AB19*F19 -> 1403300 | AD19: =+AB19*R19 -> 1403300 | AE19: Lưu lượng: 350m3/h, Cột áp: 25Pa
A20: 9 | B20: QUẠT HÚT KHO 4 | C20: Cái | D20: 1 | E20: 1 | F20: =E20 -> 1 | G20: TH2/EF-11 | H20: 150 | I20: 20 | J20: Fan wall mounted | K20: 55 | L20: 0.37 | M20: 220/1/50 | N20: ≤ 65 dBA | O20: ≥ 50 % | R20: 1 | S20: VNS-AV6-15 | T20: Quạt gắn tường | U20: TH Vinasun | V20: Việt Nam | W20: 496600 | Y20: 676100 | AB20: =+W20+X20+Y20+Z20+AA20 -> 1172700 | AC20: =+AB20*F20 -> 1172700 | AD20: =+AB20*R20 -> 1172700 | AE20: Lưu lượng: 150m3/h, Cột áp: 20Pa
A21: 10 | B21: QUẠT CẤP GIÓ TẦNG HẦM ZONE 1 | C21: Cái | D21: 2 | E21: 2 | F21: =E21 -> 2 | G21: TH2/SF-01.1,2 | H21: 20500 | I21: 400 | J21: Axial Fan/In-Line Fan/ Cabinet Fan | K21: 55 | L21: 11 | M21: 380/3/50 | N21: ≤ 65 dBA | O21: ≥ 50 % | R21: 2 | S21: VNS-AF5-7T Động cơ ATT IE3 | T21: Quạt hướng trục | U21: TH Vinasun | V21: Việt Nam | W21: 26908400 | Y21: 3719700 | AB21: =+W21+X21+Y21+Z21+AA21 -> 30628100 | AC21: =+AB21*F21 -> 61256200 | AD21: =+AB21*R21 -> 61256200 | AE21: Lưu lượng: 20500m3/h, Cột áp: 400Pa
A22: 11 | B22: QUẠT CẤP GIÓ TẦNG HẦM ZONE 2 | C22: Cái | D22: 1 | E22: 1 | F22: =E22 -> 1 | G22: TH2/SF-02 | H22: 39000 | I22: 400 | J22: Axial Fan/In-Line Fan/ Cabinet Fan | K22: 55 | L22: 15 | M22: 380/3/50 | N22: ≤ 65 dBA | O22: ≥ 50 % | R22: 1 | S22: VNS-AF5-8T Động cơ ATT IE3 | T22: Quạt hướng trục | U22: TH Vinasun | V22: Việt Nam | W22: 45457400 | Y22: 5207800 | AB22: =+W22+X22+Y22+Z22+AA22 -> 50665200 | AC22: =+AB22*F22 -> 50665200 | AD22: =+AB22*R22 -> 50665200 | AE22: Lưu lượng: 39000m3/h, Cột áp: 400Pa
B23: Tầng hầm 1 | F23: =E23 -> 0 | R23: 0 | S23: 0 | T23: 0 | U23: 0 | V23: 0 | W23: 0 | Y23: 0 | AB23: =+W23+X23+Y23+Z23+AA23 -> 0 | AC23: =+AB23*F23 -> 0 | AD23: =+AB23*R23 -> 0 | AE23: 0
A24: 12 | B24: QUẠT HÚT PHÒNG QUẠT HÚT 1 | C24: Cái | D24: 1 | E24: 1 | F24: =E24 -> 1 | G24: TH1/EF-03 | H24: 1000 | I24: 50 | J24: Fan wall mounted | K24: 55 | L24: 0.37 | M24: 220/1/50 | N24: ≤ 65 dBA | O24: ≥ 50 % | R24: 1 | S24: VNS-AV6-25 | T24: Quạt gắn tường | U24: TH Vinasun | V24: Việt Nam | W24: 591600 | Y24: 1317900 | AB24: =+W24+X24+Y24+Z24+AA24 -> 1909500 | AC24: =+AB24*F24 -> 1909500 | AD24: =+AB24*R24 -> 1909500 | AE24: Lưu lượng: 1000m3/h, Cột áp: 50Pa
A25: =A24+1 -> 13 | B25: QUẠT HÚT PHÒNG QUẠT HÚT 2 | C25: Cái | D25: 1 | E25: 1 | F25: =E25 -> 1 | G25: TH1/EF-04 | H25: 650 | I25: 25 | J25: Fan wall mounted | K25: 55 | L25: 0.37 | M25: 220/1/50 | N25: ≤ 65 dBA | O25: ≥ 50 % | R25: 1 | S25: VNS-AV6-25 | T25: Quạt gắn tường | U25: TH Vinasun | V25: Việt Nam | W25: 591600 | Y25: 852400 | AB25: =+W25+X25+Y25+Z25+AA25 -> 1444000 | AC25: =+AB25*F25 -> 1444000 | AD25: =+AB25*R25 -> 1444000 | AE25: Lưu lượng: 650m3/h, Cột áp: 25Pa
A26: =A25+1 -> 14 | B26: QUẠT HÚT PHÒNG QUẠT HÚT 3 | C26: Cái | D26: 1 | E26: 1 | F26: =E26 -> 1 | G26: TH1/EF-05 | H26: 1000 | I26: 50 | J26: Fan wall mounted | K26: 55 | L26: 0.37 | M26: 220/1/50 | N26: ≤ 65 dBA | O26: ≥ 50 % | R26: 1 | S26: VNS-AV6-25 | T26: Quạt gắn tường | U26: TH Vinasun | V26: Việt Nam | W26: 591600 | Y26: 1317900 | AB26: =+W26+X26+Y26+Z26+AA26 -> 1909500 | AC26: =+AB26*F26 -> 1909500 | AD26: =+AB26*R26 -> 1909500 | AE26: Lưu lượng: 1000m3/h, Cột áp: 50Pa
A27: =A26+1 -> 15 | B27: QUẠT HÚT PHÒNG QUẠT CẤP | C27: Cái | D27: 1 | E27: 1 | F27: =E27 -> 1 | G27: TH1/EF-06 | H27: 650 | I27: 25 | J27: Fan wall mounted | K27: 55 | L27: 0.37 | M27: 220/1/50 | N27: ≤ 65 dBA | O27: ≥ 50 % | R27: 1 | S27: VNS-AV6-25 | T27: Quạt gắn tường | U27: TH Vinasun | V27: Việt Nam | W27: 591600 | Y27: 852400 | AB27: =+W27+X27+Y27+Z27+AA27 -> 1444000 | AC27: =+AB27*F27 -> 1444000 | AD27: =+AB27*R27 -> 1444000 | AE27: Lưu lượng: 650m3/h, Cột áp: 25Pa
A28: =A27+1 -> 16 | B28: QUẠT HÚT PHÒNG BƠM PCCC | C28: Cái | D28: 1 | E28: 1 | F28: =E28 -> 1 | G28: TH1/EF-07 | H28: 1000 | I28: 50 | J28: Fan wall mounted | K28: 55 | L28: 0.37 | M28: 220/1/50 | N28: ≤ 65 dBA | O28: ≥ 50 % | R28: 1 | S28: VNS-AV6-25 | T28: Quạt gắn tường | U28: TH Vinasun | V28: Việt Nam | W28: 591600 | Y28: 1317900 | AB28: =+W28+X28+Y28+Z28+AA28 -> 1909500 | AC28: =+AB28*F28 -> 1909500 | AD28: =+AB28*R28 -> 1909500 | AE28: Lưu lượng: 1000m3/h, Cột áp: 50Pa
A29: =A28+1 -> 17 | B29: QUẠT HÚT PHÒNG HẠ THẾ | C29: Cái | D29: 1 | E29: 1 | F29: =E29 -> 1 | G29: TH1/EF-08 | H29: 3500 | I29: 50 | J29: Fan wall mounted | K29: 55 | L29: 0.55 | M29: 220/1/50 | N29: ≤ 65 dBA | O29: ≥ 50 % | R29: 1 | S29: VNS-AF9-4T | T29: Quạt hướng trục vuông, kt 400x400x320mm | U29: TH Vinasun | V29: Việt Nam | W29: 4281500 | Y29: 1595900 | AB29: =+W29+X29+Y29+Z29+AA29 -> 5877400 | AC29: =+AB29*F29 -> 5877400 | AD29: =+AB29*R29 -> 5877400 | AE29: Lưu lượng: 3500m3/h, Cột áp: 50Pa
