Workbook
Name HESOLNNE: #REF!
Name HESORENHANH: #REF!
Name LOGO: INDEX(#REF!,MATCH(#REF!,#REF!,0),2)
Name TaxTV: 10%
Name TaxXL: 5%
Name TIEUCHUAN: #REF!

Sheet TONG
E1: Mẫu số 03.1
A2: BẢNG GIÁ CHÀO TỔNG HỢP
A4: Stt | B4: Mô tả công việc mời thầu | C4: Thành tiền | E4: Ghi chú
C5: Theo KLMT | D5: Nhà thầu chào
A6: A | B6: ĐẦU MỤC CÔNG VIỆC THEO KLMT | C6: =SUBTOTAL(9,C7:C11) -> 1.7635408e+11
A7: I | B7: HẠNG MỤC: ĐIỆN | C7: ='BoQ chi tiet'!Q10 -> 85852544382
A8: II | B8: HẠNG MỤC: ĐIỆN NHẸ | C8: ='BoQ chi tiet'!Q2684 -> 1893615371
A9: III | B9: HẠNG MỤC: CẤP THOÁT NƯỚC | C9: ='BoQ chi tiet'!Q2727 -> 3.0727291e+10
A10: IV | B10: HẠNG MỤC: HVAC | C10: ='BoQ chi tiet'!Q3534 -> 5.6272312e+10
A11: V | B11: HẠNG MỤC: NGĂN CHÁY LAN | C11: ='BoQ chi tiet'!Q4808 -> 1.6083143e+09
A12: B | B12: ĐẦU MỤC CÔNG VIỆC PHÁT SINH NGOÀI KLMT | C12: =SUBTOTAL(9,C13:C17) -> 3926674400
A13: I | B13: HẠNG MỤC: ĐIỆN | C13: ='BoQ chi tiet'!Q4826 -> 395709700
A14: II | B14: HẠNG MỤC: ĐIỆN NHẸ
A15: III | B15: HẠNG MỤC: CẤP THOÁT NƯỚC | C15: ='BoQ chi tiet'!Q4837 -> 2264013000
A16: IV | B16: HẠNG MỤC: HVAC | C16: ='BoQ chi tiet'!Q4855 -> 1266951700
A17: V | B17: HẠNG MỤC: NGĂN CHÁY LAN
A18: BS | B18: CHI PHÍ CHUNG | C18: ='Tong VK'!I31 -> 8351925000
A19: C | B19: TỔNG CỘNG GIÁ CHÀO TRƯỚC THUẾ: (C = A + B) | C19: =C12+C6+C18 -> 1.8863268e+11
B20: Thuế Vat | C20: =C19*8% -> 1.5090614e+10 | E20: 0.08
A21: D | B21: TỔNG CỘNG GIÁ CHÀO SAU THUẾ | C21: =C20+C19 -> 2.0372329e+11
C23: ĐẠI DIỆN HỢP PHÁP CỦA NHÀ THẦU
C24: (Ghi tên, chức danh, ký tên và đóng dấu)

Sheet Bia
C4: BẢNG BÁO GIÁ
C8: DỰ ÁN | D8: : | E8: {=UPPER('Tong VK'!D9:E9)} -> TÒA NHÀ HỖN HỢP HACOM MALL
C10: HẠNG MỤC | D10: : | E10: {=UPPER('Tong VK'!D10:E10)} -> CUNG CẤP VTTB VÀ THI CÔNG LẮP ĐẶT HỆ THỐNG CƠ ĐIỆN
C12: ĐỊA CHỈ | D12: : | E12: {=UPPER('Tong VK'!D11:E11)} -> PHƯỜNG ĐÔNG HẢI, TỈNH KHÁNH HÒA
C25: HO CHI MINH CITY - 12/2025

Sheet Tong VK
B4: BẢNG BÁO GIÁ
B6: Từ | C6: : | D6: Công Ty Cổ Phần Tập Đoàn Đầu Tư – Thương Mại Và Xây Dựng Vân Khánh | F6: Kính gửi | G6: : | H6: Công ty Cổ phần đầu tư Hacom Holdings
B7: Người gửi | C7: : | D7: Le Van Hao / Email : hao.levan@vankhanhgroup.com | F7: Người nhận | G7: : | H7: Mr Thái
B8: Tel | C8: : | D8: M : 096.448.2608 / +84.274 399 0303 : Ext 308 | F8: Tel | G8: :
B9: Công trình | C9: : | D9: Tòa nhà hỗn hợp Hacom Mall | F9: Email | G9: : | H9: thaipv@hacomholdings.vn
B10: Hạng mục | C10: : | D10: Cung cấp VTTB và thi công lắp đặt hệ thống Cơ điện | F10: Hiệu lực | G10: : | H10: 10 Ngày kể từ ngày phát hành / Hiệu chỉnh
B11: Địa chỉ | C11: : | D11: Phường Đông Hải, tỉnh Khánh Hòa | F11: Phát hành | G11: : | H11: Ngày 10 tháng 10 năm 2025
B12: Số báo giá | C12: : | D12: VKG-Hacom Holdings/ Hacom mall/ Rev01 | F12: Hiệu chỉnh | G12: : | H12: Ngày 08 tháng 12 năm 2025
B14: Chúng tôi gửi tới Quý Công ty bảng báo giá theo yêu cầu như sau:
B16: STT | D16: Diễn Giải | E16: Đơn Vị | F16: Số Lượng | H16: Đơn Giá ( VND ) | I16: Thành Tiền ( VND )
B19: A | D19: ĐẦU MỤC CÔNG VIỆC THEO KLMT
B20: 1 | D20: HỆ THỐNG ĐIỆN | E20: Lô | F20: 1 | H20: ='BoQ chi tiet'!Q10 -> 85852544382 | I20: =H20*F20 -> 85852544382
B21: =B20+1 -> 2 | D21: HỆ THỐNG ĐIỆN NHẸ | E21: Lô | F21: 1 | H21: ='BoQ chi tiet'!Q2684 -> 1893615371 | I21: =H21*F21 -> 1893615371
B22: =B21+1 -> 3 | D22: HỆ THỐNG CẤP THOÁT NƯỚC | E22: Lô | F22: 1 | H22: ='BoQ chi tiet'!Q2727 -> 3.0727291e+10 | I22: =H22*F22 -> 3.0727291e+10
B23: =B22+1 -> 4 | D23: HỆ THỐNG ĐIỀU HÒA KHÔNG KHÍ | E23: Lô | F23: 1 | H23: ='BoQ chi tiet'!Q3534 -> 5.6272312e+10 | I23: =H23*F23 -> 5.6272312e+10
B24: =B23+1 -> 5 | D24: HỆ THỐNG NGĂN CHÁY LAN | E24: Lô | F24: 1 | H24: ='BoQ chi tiet'!Q4808 -> 1.6083143e+09 | I24: =H24*F24 -> 1.6083143e+09
B25: B | D25: ĐẦU MỤC CÔNG VIỆC PHÁT SINH NGOÀI KLMT
B26: 1 | D26: HỆ THỐNG ĐIỆN | E26: Lô | F26: 1 | H26: ='BoQ chi tiet'!Q4826 -> 395709700 | I26: =H26*F26 -> 395709700
B27: =B26+1 -> 2 | D27: HỆ THỐNG ĐIỆN NHẸ | E27: Lô | F27: 1 | I27: =H27*F27 -> 0
B28: =B27+1 -> 3 | D28: HỆ THỐNG CẤP THOÁT NƯỚC | E28: Lô | F28: 1 | H28: ='BoQ chi tiet'!Q4837 -> 2264013000 | I28: =H28*F28 -> 2264013000
B29: =B28+1 -> 4 | D29: HỆ THỐNG ĐIỀU HÒA KHÔNG KHÍ | E29: Lô | F29: 1 | H29: ='BoQ chi tiet'!Q4855 -> 1266951700 | I29: =H29*F29 -> 1266951700
B30: =B29+1 -> 5 | D30: HỆ THỐNG NGĂN CHÁY LAN | E30: Lô | F30: 1
B31: C | D31: CHI PHÍ CHUNG | E31: Lô | F31: 1 | H31: 8351925000 | I31: =H31*F31 -> 8351925000
D33: TỔNG : | I33: =SUM(I18:I32) -> 1.8863268e+11
D34: THUẾ VAT (8%): | I34: =I33*8% -> 1.5090614e+10
D35: TỔNG CỘNG ( Bao gồm VAT) : | I35: =SUM(I33:I34) -> 2.0372329e+11
B37: Ghi chú :
D39: Khách hàng phê duyệt | I39: Công Ty Cổ Phần Tập Đoàn Đầu Tư – Thương Mại Và Xây Dựng Vân Khánh

Sheet BoQ chi tiet
A1: Dự án: TOÀ NHÀ HỖN HỢP HACOM MALL
A2: Gói thầu: CUNG CẤP VTTB VÀ THI CÔNG LẮP ĐẶT HỆ THỐNG CƠ ĐIỆN
A3: Hạng mục: Cung cấp VTTB và thi công lắp đặt hệ thống Cơ điện
A5: KHỐI LƯỢNG MỜI THẦU | F5: VÂN KHÁNH GROUP
A6: STT | B6: Diễn giải | C6: Đơn vị | D6: KL Mời thầu Lần 2 | E6: Ghi chú | F6: KL Nhà thầu chào | G6: THÔNG TIN VỀ VẬT LIỆU CHÍNH | K6: ĐƠN GIÁ (chưa bao gồm VAT) | Q6: Thành tiền BOQ | S6: Ghi chú
G7: Mô tả/ Quy cách | H7: Mã hiệu | I7: Thương hiệu | J7: Xuất xứ | K7: VL chính | L7: VL phụ | M7: NC&M | N7: CF quản lý | O7: Lợi nhuận | P7: ĐG tổng hợp | Q7: Thành tiền KLMT | R7: Thành tiền Nhà thầu chào
A8: 1 | B8: 2 | C8: 3 | D8: 4 | F8: 6 | G8: 7 | H8: 8 | I8: 9 | J8: 10 | K8: 11 | L8: 12 | M8: 13 | N8: 14 | O8: 15 | P8: 16=11+12+13+14+15 | Q8: 17=4*16 | R8: 18=6*16 | S8: 19
A9: A | B9: ĐẦU MỤC CÔNG VIỆC THEO KLMT | Q9: =SUBTOTAL(9,Q10:Q4824) -> 1.7635408e+11
B10: HẠNG MỤC: ĐIỆN | Q10: =SUBTOTAL(9,Q11:Q2683) -> 85852544382
A11: I | B11: Tủ điện hạ thế
A12: =COUNT($A$11:$A11)+1 -> 1 | B12: Tủ điện LV-G.1+LV-G.2+LV-G.3+LV-G.4+LV-G.5+LV-G.6 | C12: Tủ | D12: 1 | G12: Thiết bị đóng cắt: Schneider/ ABB | I12: Á Châu (ACIT)/ Đạt Vĩnh Tiến (ĐVT)/ Bích Hạnh (BHT) | J12: Việt Nam | K12: 2461261500 | M12: 39137500 | P12: =SUM(K12:O12) -> 2500399000 | Q12: =P12*$D12 -> 2500399000 | R12: =P12*$F12 -> 0 | S12: Báo giá theo bản vẽ SĐNL Chi tiết xem sheet "Chi tiet tu dien"
B13: Vỏ tủ form 3B | C13: Cái | D13: 1
B14: Đầu vào:
B15: ACB Fixed 4P 3200AT 3200AF 65kA , bảo vệ quá dòng, chạm đất, quá áp, thấp áp, đo lường class 1, kết nối NFC/ Bluetooth. | C15: Cái | D15: 2
B16: Motor sạc 220VAC cho ACB Fixed 4P 3200A 65kA | C16: Cái | D16: 2
B17: Cuộn đóng 220VAC cho ACB Fixed 4P 3200A 65kA | C17: Cái | D17: 2
B18: Cuộn cắt 220VAC cho ACB Fixed dòng MTZ | C18: Cái | D18: 2
B19: Cuộn UVT 220VAC cho ACB Fixed dòng MTZ | C19: Cái | D19: 2
B20: Khóa đóng cắt ACB | C20: Cái | D20: 2
B21: Bộ hòa đồng bộ 2 máy phát | C21: Bộ | D21: 1
B22: Đèn báo trạng thái On/OFF/TRIP ACB | C22: Cái | D22: 6
B23: Biến dòng hạ thế 3200/5A | C23: Quả | D23: 12
B24: Đồng hồ Volt 0-450VAC | C24: Cái | D24: 2
B25: Chuyển mạch Volt 7 vị trí | C25: Cái | D25: 2
B26: Đồng hồ Ampe 0-3200A | C26: Cái | D26: 6
... B28: Cầu chi 2A | C28: Cái | D28: 18
B29: Đầu ra:
B30: ACB Fixed 4P 3000AT 3200AF 65kA | C30: Cái | D30: 1
B31: Motor sạc 220VAC cho ACB Fixed 4P 3000AT 3200AF 65kA | C31: Cái | D31: 1
B32: Cuộn đóng 220VAC cho ACB Fixed 4P 3000AT 3200AF 65kA | C32: Cái | D32: 1
B33: Cuộn cắt 220VAC cho ACB Fixed dòng MTZ | C33: Cái | D33: 1
B34: ACB 4P 1600AT 1600AF 65kA Fixed | C34: Cái | D34: 1
B35: Motor sạc 220VAC cho ACB 4P 1600AT 1600AF 65kA Fixed | C35: Cái | D35: 1
B36: Cuộn đóng 220VAC cho ACB 4P 1600AT 1600AF 65kA Fixed | C36: Cái | D36: 1
B37: Cuộn cắt 220VAC cho ACB 4P 1600AT 1600AF 65kA Fixed | C37: Cái | D37: 2
B38: Đèn báo trạng thái On/OFF/TRIP ACB | C38: Cái | D38: 6
B39: Khóa đóng cắt ACB | C39: Cái | D39: 2
B40: MCCB 4P 1250AT 1250AF 50kA | C40: Cái | D40: 1
B41: Tiếp điểm báo trạng thái cho MCCB 4P 1250AT 1250AF 50kA | C41: Cái | D41: 2
... B54: Nhân công + phụ kiện lắp đặt | C54: Tủ | D54: 1
...

Sheet Phạm vi tính toán
A1: Dự án: TOÀ NHÀ HỖN HỢP HACOM MALL
A2: Gói thầu: CUNG CẤP VTTB VÀ THI CÔNG LẮP ĐẶT HỆ THỐNG CƠ ĐIỆN
A3: Hạng mục: Ngăn cháy lan
C4: NHÀ THẦU THỰC HIỆN NGĂN CHÁY LAN
A5: STT | B5: Phạm vi công việc | C5: Có | D5: Không | E5: Ghi chú | F5: XÁC NHẬN CĐT
A6: I - HỆ CẤP THOÁT NƯỚC
A7: 1 | B7: Tính toán ngăn cháy xuyên sàn cho lỗ mở phòng kĩ thuật hở - trục đứng (có cửa chống cháy) | C7: X
A8: 2 | B8: Tính toán ngăn cháy đường ống CTN xuyên tường phòng kĩ thuật hở (có cửa chống cháy) - phòng kỹ thuật cấp nước | C8: X
A9: 3 | B9: Tính toán ngăn cháy đường ống CTN xuyên tường từ hành lang đi vào mỗi căn hộ. | C9: X
A10: 4 | B10: Tính toán ngăn cháy xuyên sàn cho các trục kỹ thuật kín tại tầng gom (trục căn hộ tại tầng gom / chuyển trục). | C10: X | E10: Chỉ có tại tầng gom chuyển trục (sàn tầng 6) (các tầng khác không thực hiện)
A11: 5 | B11: Tính toán ngăn cháy đường ống CTN xuyên tường đi vào phòng rác, phòng bơm, phòng máy khối tháp | C11: X
A12: 6 | B12: Tính toán ngăn cháy đường ống CTN xuyên tường phân chia khoang cháy khu vực hầm, các tường ngăn cháy khác, tường phòng máy khu hầm. | C12: X
A13: 7 | B13: Đường ống xuyên tường ngăn cháy giữa hai căn hộ, giữa 2 căn shop house (nếu có) | D13: X | E13: Chỉ làm kín bằng VLXD thông thường
A14: 8 | B14: Đường ống xuyên tường từ khu WC / không gian căn hộ đi vào trục thoát cô lập kín trong mỗi căn hộ | D14: X | E14: Chỉ làm kín bằng VLXD thông thường
A15: 9 | B15: Đường ống xuyên sàn cho các WC căn hộ, WC công cộng | D15: X | E15: Chỉ làm kín bằng VLXD thông thường
A16: 10 | B16: Các vị trí xuyên sàn trục xây cô lập kín (trục thoát căn hộ) không có vị trí chuyển trục. | D16: X | E16: Không thực hiện
A17: 11 | B17: Các phạm vi khác không liệt kê ở đây | D17: X | E17: Chỉ làm kín bằng VLXD thông thường
A18: II - HỆ ĐIỆN - ĐIỆN NHẸ
A19: 1 | B19: Tính toán ngăn cháy xuyên sàn cho lỗ mở phòng kĩ thuật điện - điện nhẹ (có cửa chống cháy) | C19: X
A20: 2 | B20: Tính toán ngăn cháy xuyên tường (thang máng cáp, busway) từ trong phòng kĩ thuật điện - điện nhẹ đi ra hành lang (có cửa chống cháy) | C20: X
A21: 3 | B21: Tính toán ngăn cháy xuyên tường (thang máng cáp, busway) tại các phòng máy, P. trung thế, hạ thế, máy phát, bơm, MEP, AHU ... (có cửa chống cháy) | C21: X
A22: 4 | B22: Tính toán ngăn cháy xuyên tường (thang máng cáp, busway), xuyên tường ngăn khoang cháy khu hầm, và các tường ngăn cháy khác dọc hành lang… | C22: X
A23: 5 | B23: Các phạm vi khác không liệt kê ở đây | D23: X | E23: Chỉ làm kín bằng VLXD thông thường
A24: III - HỆ DUCT HVAC - TAHK
A25: 1 | B25: Tính toán ngăn cháy các vị trí lỗ mở ống Duct xuyên sàn tại các phòng kỹ thuật hở (có cửa ngăn cháy) - Nếu có | C25: X
A26: 2 | B26: Tính toán ngăn cháy các vị trí ống Duct xuyên tường tại các phòng kỹ thuật hở (có cửa ngăn cháy). | C26: X
A27: 3 | B27: Tính toán ngăn cháy các vị trí ống Duct hút khói đi xuyên tường hành lang vào trục đứng. | C27: X
A28: 4 | B28: Tính toán ngăn cháy các vị trí lỗ mở ống Duct xuyên sàn trục cô lập kín (chỉ thực hiện tại vị trí chuyển trục). | C28: X | E28: Chỉ có tại tầng gom chuyển trục (các tầng khác không thực hiện)
A29: 5 | B29: Tính toán vị trí đường ống Duct (HVAC-TAHK) xuyên tường ngăn cháy/rèm ngăn chia khoang cháy khu vực các tầng hầm (nếu có) | C29: X
A30: 6 | B30: Tính toán vị trí đường ống Duct HVAC-TAHK xuyên tường từ ngoài hành lang đi vào buồng đệm / buồng thang bộ. | C30: X
A31: 7 | B31: Vị trí đường ống Duct TAHK, van xuyên tường trong nội bộ buồng đệm thang, buồng thang bộ (khu vực bảo vệ tăng áp, không được phép có cháy, không có nguy cơ) | D31: X | E31: Chỉ làm kín bằng VLXD thông thường
A32: 8 | B32: Các vị trí xuyên sàn trục xây cô lập kín không có vị trí chuyển trục. | D32: X | E32: Không thực hiện
A33: 9 | B33: Các phạm vi khác không liệt kê ở đây | D33: X | E33: Chỉ làm kín bằng VLXD thông thường
A34: IV - HỆ PCCC
A35: 1 | B35: Tính toán ngăn cháy xuyên sàn cho lỗ mở phòng kĩ thuật hở (có cửa ngăn cháy) - đi chung hoặc đi riêng với hệ CTN | C35: X
A36: 2 | B36: Tính toán ngăn cháy đường ống PCCC xuyên tường phòng kĩ thuật hở (có cửa ngăn cháy) - đi chung hoặc đi riêng với hệ CTN | C36: X
A37: 3 | B37: Tính toán ngăn cháy đường ống PCCC xuyên tường hành lang vào căn hộ. | C37: X
A38: 4 | B38: Tính toán ngăn cháy đường ống PCCC xuyên tường hành lang vào buồng đệm, vào phòng rác, vào phòng kỹ thuật điện, vào phòng máy khối tháp. | C38: X
A39: 5 | B39: Tính toán ngăn cháy đường ống PCCC xuyên tường tường ngăn chia khoang cháy khu vực các tầng hầm, vào các phòng máy khu vực hầm. | C39: X
A40: 6 | B40: Đường ống xuyên tường ngăn cháy giữa hai căn hộ, giữa 2 căn shop house (nếu có) | C40: X
...

Sheet DMVT
B1: PHỤ LỤC 02: BẢNG DANH MỤC VẬT TƯ THIẾT BỊ Dự án: TOÀ NHÀ HỖN HỢP HACOM MALL Gói thầu: CUNG CẤP VTTB VÀ THI CÔNG LẮP ĐẶT HỆ THỐNG CƠ ĐIỆN
A2: STT | B2: VẬT TƯ THIẾT BỊ | C2: THƯƠNG HIỆU - XUẤT XỨ | D2: GHI CHÚ | E2: Nhà thầu đề xuất
E3: Nhãn hiệu | F3: Xuất xứ | G3: GHI CHÚ
A4: I | B4: HỆ THỐNG ĐIỆN
A5: 1 | B5: Tủ điện hạ thế (Đơn vị sản xuất, lắp ráp) | C5: Á Châu (ACIT)/ Đạt Vĩnh Tiến (ĐVT)/ Bích Hạnh (BHT) - VN | D5: Theo PL02.1 đính kèm | E5: Á Châu (ACIT)/ Đạt Vĩnh Tiến (ĐVT)/ Bích Hạnh (BHT) | F5: Việt Nam | G5: Theo PL02.1 đính kèm
A6: 2 | B6: Thiết bị đóng cắt Tủ điện hạ thế | C6: Schneider/ ABB - Asia | E6: Schneider/ ABB | F6: Asia
A7: 3 | B7: Thiết bị đóng cắt Tủ điện căn hộ | C7: Schneider/ Legrand/ ABB - Asia | E7: Legrand | F7: Asia
A8: 4 | B8: Hệ thống dây cáp hạ thế | C8: Cadivi/ Taisin - Asia | E8: Cadivi | F8: Việt Nam
A9: 5 | B9: Busway và phụ kiện | C9: Schneider/ ABB - Asia | E9: Schneider/ ABB | F9: China
A10: 6 | B10: Đèn chiếu sáng | C10: Phillips/ Simon - Asia | E10: Simon | F10: Việt Nam
A11: 7 | B11: Công tắc, ổ cắm | C11: Lergrand/ Simon/ Siemens - Asia | D11: Công tắc: Obria/ S6/ Peleus Ổ cắm: Obria/ S5/ Relfa | E11: Legrand | F11: China | G11: Obria Series
A12: 8 | B12: Ống luồn dây điện PVC và phụ kiện | C12: Sam Phú/ AC - VN | E12: Sam Phú/ AC | F12: Việt Nam
A13: 9 | B13: Thang, máng cáp và phụ kiện | C13: Eusteel/ Đại Phúc - VN | D13: Trong nhà sử dụng sơn tĩnh điện Ngoài nhà sử dụng mạ kẽm nhúng nóng | E13: Á Châu (ACIT)/ Đạt Vĩnh Tiến (ĐVT)/ Bích Hạnh (BHT) | F13: Việt Nam
A14: 10 | B14: Kim thu sét tia tiên đạo | C14: Kalre/ Ingesco - Turkey/ Spain | E14: Liva | F14: Turkey
A15: 11 | B15: Cọc tiếp địa | C15: Kumwell/ CVL - Asia | E15: CVL | F15: Việt Nam
A16: II | B16: HỆ THỐNG ĐIỆN NHẸ
A17: 1 | B17: Ống luồn dây PVC và phụ kiện | C17: Sam Phú/ AC - VN | E17: Sam Phú/ AC | F17: Việt Nam
A18: 2 | B18: Thang, máng cáp và phụ kiện | C18: Eusteel/ Đại Phúc - VN | D18: Trong nhà sử dụng sơn tĩnh điện Ngoài nhà sử dụng mạ kẽm nhũng nóng | E18: Á Châu (ACIT)/ Đạt Vĩnh Tiến (ĐVT)/ Bích Hạnh (BHT) | F18: Việt Nam
A19: III | B19: HỆ THỐNG CẤP THOÁT NƯỚC
A20: 1 | B20: Bơm cấp nước | C20: Grundfos/ Wilo/ Gould - Asia | D20: Bơm, động cơ nhập khẩu từ nhà máy và được tổ hợp, lắp ráp với cụm van, cụm cơ khí, tủ điều khiển được … tại Việt Nam | E20: Grundfos/ Wilo | F20: Asia
A21: 2 | B21: Ống thoát nước uPVC và phụ kiện | C21: Đệ Nhất/ Tiền Phong - VN | E21: Tiền Phong | F21: Việt Nam
A22: 3 | B22: Ống cấp nước PPR và phụ kiện | C22: Đệ Nhất/ Tiền Phong - VN | E22: Tiền Phong | F22: Việt Nam
A23: 4 | B23: Ống inox | C23: Sơn Hà/ Tương đương - VN | E23: Sơn Hà | F23: Việt Nam
A24: 5 | B24: Van và phụ kiện | C24: KVS/ Flowsure - Asia | E24: Flowsure | F24: Asia
A25: 6 | B25: Bình nóng lạnh | C25: Ariston/ Ferroli - Asia | D25: Slim3 + Pro R/ Rapido + HBO | E25: Ariston | F25: Asia
A26: 7 | B26: Đồng hồ nước | C26: KVS/ tương đương - Asia | E26: Hydroconta | F26: Spain
A27: 8 | B27: Bể nước mái | C27: Sơn Hà/ Tân Á Đại Thành - VN | E27: Sơn Hà | F27: Việt Nam
A28: 9 | B28: Thiết bị vệ sinh | C28: Nhà thầu lắp đặt, CĐT cấp thiết bị | E28: Nhà thầu lắp đặt, CĐT cấp thiết bị | F28: Nhà thầu lắp đặt, CĐT cấp thiết bị
A29: 10 | B29: Phễu thu nước mưa, cầu thu mưa, cầu chắn rác… | C29: Thủy Sanh/ Hiwin/ Ngọc Thảo - Asia | E29: PTS | F29: Việt Nam
A30: 11 | B30: Phụ kiện ống inox | C30: Suzhou/ Cangzhou/ Tương đương - China | E30: Vinpro | F30: Việt Nam
A31: IV | B31: HỆ THỐNG ĐHKK
A32: 1 | B32: Thiết bị điều hoà VRV | C32: Nhà thầu lắp đặt, CĐT cấp thiết bị | E32: Nhà thầu lắp đặt, CĐT cấp thiết bị | F32: Nhà thầu lắp đặt, CĐT cấp thiết bị
A33: 2 | B33: Thiết bị điều hoà cục bộ, Multi | C33: Nhà thầu lắp đặt, CĐT cấp thiết bị | E33: Nhà thầu lắp đặt, CĐT cấp thiết bị | F33: Nhà thầu lắp đặt, CĐT cấp thiết bị
A34: 3 | B34: Ống đồng điều hoà | C34: Taisei/ TPcooper/ Toàn Phát - Asia | E34: TAISEI | F34: Việt Nam
A35: 4 | B35: Ống nước ngưng điều hoà và phụ kiện | C35: Đệ Nhất/ Tiền Phong - VN | E35: Đệ Nhất | F35: Việt Nam
A36: 5 | B36: Quạt thông gió | C36: TH Vinasun/ Tomeco - VN | E36: Wolter | F36: Thailand
A37: 6 | B37: Quạt hút mùi trong căn hộ | C37: Wolter/ Kruger - Thailand | E37: Wolter | F37: Thailand
A38: 6 | B38: Quạt thông gió TAHK | C38: TH Vinasun/ Tomeco - VN | E38: Wolter | F38: Thailand
A39: 7 | B39: Ống gió mạ kẽm TAHK (EI) | C39: Eusteel/ Đại Phúc - VN | E39: Eusteel | F39: Việt Nam
A40: 8 | B40: Miệng gió, van gió TAHK (EI) | C40: Eusteel/ Đại Phúc - VN | E40: Eusteel | F40: Việt Nam
...
